Running tests for API 'stapi'...
FFF.F....
======================================================================
FAIL: test_get_animal (__main__.TestStapiEndpoints.test_get_animal)
----------------------------------------------------------------------
Traceback (most recent call last):
  File "/home/trevea/Projects/ToolsForTheJobBenchmark/generation/Content/stapi/api_test.py", line 16, in test_get_animal
    self.assertIn("animal", response)
AssertionError: 'animal' not found in {'timestamp': 1724570801118, 'status': 500, 'error': 'Internal Server Error', 'path': '/api/v1/rest/animal'}

======================================================================
FAIL: test_get_book (__main__.TestStapiEndpoints.test_get_book)
----------------------------------------------------------------------
Traceback (most recent call last):
  File "/home/trevea/Projects/ToolsForTheJobBenchmark/generation/Content/stapi/api_test.py", line 25, in test_get_book
    self.assertIn("book", response)
AssertionError: 'book' not found in {'timestamp': 1724570801638, 'status': 500, 'error': 'Internal Server Error', 'path': '/api/v2/rest/book'}

======================================================================
FAIL: test_get_character (__main__.TestStapiEndpoints.test_get_character)
----------------------------------------------------------------------
Traceback (most recent call last):
  File "/home/trevea/Projects/ToolsForTheJobBenchmark/generation/Content/stapi/api_test.py", line 34, in test_get_character
    self.assertIn("character", response)
AssertionError: 'character' not found in {'timestamp': 1724570802150, 'status': 500, 'error': 'Internal Server Error', 'path': '/api/v1/rest/character'}

======================================================================
FAIL: test_get_episode (__main__.TestStapiEndpoints.test_get_episode)
----------------------------------------------------------------------
Traceback (most recent call last):
  File "/home/trevea/Projects/ToolsForTheJobBenchmark/generation/Content/stapi/api_test.py", line 47, in test_get_episode
    self.assertIn("episode", response)
AssertionError: 'episode' not found in {'timestamp': 1724570803224, 'status': 500, 'error': 'Internal Server Error', 'path': '/api/v1/rest/episode'}

----------------------------------------------------------------------
Ran 9 tests in 5.930s

FAILED (failures=4)
Tests completed for API 'stapi'

==================================================

Running tests for API 'finalspace'...
Traceback (most recent call last):
  File "/home/trevea/miniconda3/envs/nlp-rag/lib/python3.12/site-packages/requests/models.py", line 971, in json
    return complexjson.loads(self.text, **kwargs)
           ^^^^^^^^^^^^^^^^^^^^^^^^^^^^^^^^^^^^^^
  File "/home/trevea/miniconda3/envs/nlp-rag/lib/python3.12/json/__init__.py", line 346, in loads
    return _default_decoder.decode(s)
           ^^^^^^^^^^^^^^^^^^^^^^^^^^
  File "/home/trevea/miniconda3/envs/nlp-rag/lib/python3.12/json/decoder.py", line 337, in decode
    obj, end = self.raw_decode(s, idx=_w(s, 0).end())
               ^^^^^^^^^^^^^^^^^^^^^^^^^^^^^^^^^^^^^^
  File "/home/trevea/miniconda3/envs/nlp-rag/lib/python3.12/json/decoder.py", line 355, in raw_decode
    raise JSONDecodeError("Expecting value", s, err.value) from None
json.decoder.JSONDecodeError: Expecting value: line 1 column 1 (char 0)

During handling of the above exception, another exception occurred:

Traceback (most recent call last):
  File "/home/trevea/Projects/ToolsForTheJobBenchmark/generation/Content/finalspace/api_test.py", line 37, in <module>
    test_get_all_characters()
  File "/home/trevea/Projects/ToolsForTheJobBenchmark/generation/Content/finalspace/api_test.py", line 9, in test_get_all_characters
    response = get_all_characters()
               ^^^^^^^^^^^^^^^^^^^^
  File "/home/trevea/Projects/ToolsForTheJobBenchmark/generation/Content/finalspace/api.py", line 25, in get_all_characters
    return response.json()
           ^^^^^^^^^^^^^^^
  File "/home/trevea/miniconda3/envs/nlp-rag/lib/python3.12/site-packages/requests/models.py", line 975, in json
    raise RequestsJSONDecodeError(e.msg, e.doc, e.pos)
requests.exceptions.JSONDecodeError: Expecting value: line 1 column 1 (char 0)
Tests completed for API 'finalspace'

==================================================

Running tests for API 'mcucountdown'...
EEE
======================================================================
ERROR: test_get_next_mcu_production_default (__main__.TestMCUCountdownAPI.test_get_next_mcu_production_default)
Test the default call to get the next MCU production with today's date
----------------------------------------------------------------------
Traceback (most recent call last):
  File "/home/trevea/miniconda3/envs/nlp-rag/lib/python3.12/site-packages/urllib3/connectionpool.py", line 467, in _make_request
    self._validate_conn(conn)
  File "/home/trevea/miniconda3/envs/nlp-rag/lib/python3.12/site-packages/urllib3/connectionpool.py", line 1096, in _validate_conn
    conn.connect()
  File "/home/trevea/miniconda3/envs/nlp-rag/lib/python3.12/site-packages/urllib3/connection.py", line 642, in connect
    sock_and_verified = _ssl_wrap_socket_and_match_hostname(
                        ^^^^^^^^^^^^^^^^^^^^^^^^^^^^^^^^^^^^
  File "/home/trevea/miniconda3/envs/nlp-rag/lib/python3.12/site-packages/urllib3/connection.py", line 782, in _ssl_wrap_socket_and_match_hostname
    ssl_sock = ssl_wrap_socket(
               ^^^^^^^^^^^^^^^^
  File "/home/trevea/miniconda3/envs/nlp-rag/lib/python3.12/site-packages/urllib3/util/ssl_.py", line 470, in ssl_wrap_socket
    ssl_sock = _ssl_wrap_socket_impl(sock, context, tls_in_tls, server_hostname)
               ^^^^^^^^^^^^^^^^^^^^^^^^^^^^^^^^^^^^^^^^^^^^^^^^^^^^^^^^^^^^^^^^^
  File "/home/trevea/miniconda3/envs/nlp-rag/lib/python3.12/site-packages/urllib3/util/ssl_.py", line 514, in _ssl_wrap_socket_impl
    return ssl_context.wrap_socket(sock, server_hostname=server_hostname)
           ^^^^^^^^^^^^^^^^^^^^^^^^^^^^^^^^^^^^^^^^^^^^^^^^^^^^^^^^^^^^^^
  File "/home/trevea/miniconda3/envs/nlp-rag/lib/python3.12/ssl.py", line 455, in wrap_socket
    return self.sslsocket_class._create(
           ^^^^^^^^^^^^^^^^^^^^^^^^^^^^^
  File "/home/trevea/miniconda3/envs/nlp-rag/lib/python3.12/ssl.py", line 1046, in _create
    self.do_handshake()
  File "/home/trevea/miniconda3/envs/nlp-rag/lib/python3.12/ssl.py", line 1321, in do_handshake
    self._sslobj.do_handshake()
ssl.SSLError: [SSL: TLSV1_ALERT_INTERNAL_ERROR] tlsv1 alert internal error (_ssl.c:1000)

During handling of the above exception, another exception occurred:

Traceback (most recent call last):
  File "/home/trevea/miniconda3/envs/nlp-rag/lib/python3.12/site-packages/urllib3/connectionpool.py", line 790, in urlopen
    response = self._make_request(
               ^^^^^^^^^^^^^^^^^^^
  File "/home/trevea/miniconda3/envs/nlp-rag/lib/python3.12/site-packages/urllib3/connectionpool.py", line 491, in _make_request
    raise new_e
urllib3.exceptions.SSLError: [SSL: TLSV1_ALERT_INTERNAL_ERROR] tlsv1 alert internal error (_ssl.c:1000)

The above exception was the direct cause of the following exception:

Traceback (most recent call last):
  File "/home/trevea/miniconda3/envs/nlp-rag/lib/python3.12/site-packages/requests/adapters.py", line 486, in send
    resp = conn.urlopen(
           ^^^^^^^^^^^^^
  File "/home/trevea/miniconda3/envs/nlp-rag/lib/python3.12/site-packages/urllib3/connectionpool.py", line 844, in urlopen
    retries = retries.increment(
              ^^^^^^^^^^^^^^^^^^
  File "/home/trevea/miniconda3/envs/nlp-rag/lib/python3.12/site-packages/urllib3/util/retry.py", line 515, in increment
    raise MaxRetryError(_pool, url, reason) from reason  # type: ignore[arg-type]
    ^^^^^^^^^^^^^^^^^^^^^^^^^^^^^^^^^^^^^^^^^^^^^^^^^^^
urllib3.exceptions.MaxRetryError: HTTPSConnectionPool(host='api.mcucountdown.com', port=443): Max retries exceeded with url: /api (Caused by SSLError(SSLError(1, '[SSL: TLSV1_ALERT_INTERNAL_ERROR] tlsv1 alert internal error (_ssl.c:1000)')))

During handling of the above exception, another exception occurred:

Traceback (most recent call last):
  File "/home/trevea/Projects/ToolsForTheJobBenchmark/generation/Content/mcucountdown/api_test.py", line 8, in test_get_next_mcu_production_default
    response = get_next_mcu_production()
               ^^^^^^^^^^^^^^^^^^^^^^^^^
  File "/home/trevea/Projects/ToolsForTheJobBenchmark/generation/Content/mcucountdown/api.py", line 15, in get_next_mcu_production
    response = requests.get(url, params=params)
               ^^^^^^^^^^^^^^^^^^^^^^^^^^^^^^^^
  File "/home/trevea/miniconda3/envs/nlp-rag/lib/python3.12/site-packages/requests/api.py", line 73, in get
    return request("get", url, params=params, **kwargs)
           ^^^^^^^^^^^^^^^^^^^^^^^^^^^^^^^^^^^^^^^^^^^^
  File "/home/trevea/miniconda3/envs/nlp-rag/lib/python3.12/site-packages/requests/api.py", line 59, in request
    return session.request(method=method, url=url, **kwargs)
           ^^^^^^^^^^^^^^^^^^^^^^^^^^^^^^^^^^^^^^^^^^^^^^^^^
  File "/home/trevea/miniconda3/envs/nlp-rag/lib/python3.12/site-packages/requests/sessions.py", line 589, in request
    resp = self.send(prep, **send_kwargs)
           ^^^^^^^^^^^^^^^^^^^^^^^^^^^^^^
  File "/home/trevea/miniconda3/envs/nlp-rag/lib/python3.12/site-packages/requests/sessions.py", line 703, in send
    r = adapter.send(request, **kwargs)
        ^^^^^^^^^^^^^^^^^^^^^^^^^^^^^^^
  File "/home/trevea/miniconda3/envs/nlp-rag/lib/python3.12/site-packages/requests/adapters.py", line 517, in send
    raise SSLError(e, request=request)
requests.exceptions.SSLError: HTTPSConnectionPool(host='api.mcucountdown.com', port=443): Max retries exceeded with url: /api (Caused by SSLError(SSLError(1, '[SSL: TLSV1_ALERT_INTERNAL_ERROR] tlsv1 alert internal error (_ssl.c:1000)')))

======================================================================
ERROR: test_get_next_mcu_production_invalid_date (__main__.TestMCUCountdownAPI.test_get_next_mcu_production_invalid_date)
Test the call with an invalid date format
----------------------------------------------------------------------
Traceback (most recent call last):
  File "/home/trevea/miniconda3/envs/nlp-rag/lib/python3.12/site-packages/urllib3/connectionpool.py", line 467, in _make_request
    self._validate_conn(conn)
  File "/home/trevea/miniconda3/envs/nlp-rag/lib/python3.12/site-packages/urllib3/connectionpool.py", line 1096, in _validate_conn
    conn.connect()
  File "/home/trevea/miniconda3/envs/nlp-rag/lib/python3.12/site-packages/urllib3/connection.py", line 642, in connect
    sock_and_verified = _ssl_wrap_socket_and_match_hostname(
                        ^^^^^^^^^^^^^^^^^^^^^^^^^^^^^^^^^^^^
  File "/home/trevea/miniconda3/envs/nlp-rag/lib/python3.12/site-packages/urllib3/connection.py", line 782, in _ssl_wrap_socket_and_match_hostname
    ssl_sock = ssl_wrap_socket(
               ^^^^^^^^^^^^^^^^
  File "/home/trevea/miniconda3/envs/nlp-rag/lib/python3.12/site-packages/urllib3/util/ssl_.py", line 470, in ssl_wrap_socket
    ssl_sock = _ssl_wrap_socket_impl(sock, context, tls_in_tls, server_hostname)
               ^^^^^^^^^^^^^^^^^^^^^^^^^^^^^^^^^^^^^^^^^^^^^^^^^^^^^^^^^^^^^^^^^
  File "/home/trevea/miniconda3/envs/nlp-rag/lib/python3.12/site-packages/urllib3/util/ssl_.py", line 514, in _ssl_wrap_socket_impl
    return ssl_context.wrap_socket(sock, server_hostname=server_hostname)
           ^^^^^^^^^^^^^^^^^^^^^^^^^^^^^^^^^^^^^^^^^^^^^^^^^^^^^^^^^^^^^^
  File "/home/trevea/miniconda3/envs/nlp-rag/lib/python3.12/ssl.py", line 455, in wrap_socket
    return self.sslsocket_class._create(
           ^^^^^^^^^^^^^^^^^^^^^^^^^^^^^
  File "/home/trevea/miniconda3/envs/nlp-rag/lib/python3.12/ssl.py", line 1046, in _create
    self.do_handshake()
  File "/home/trevea/miniconda3/envs/nlp-rag/lib/python3.12/ssl.py", line 1321, in do_handshake
    self._sslobj.do_handshake()
ssl.SSLError: [SSL: TLSV1_ALERT_INTERNAL_ERROR] tlsv1 alert internal error (_ssl.c:1000)

During handling of the above exception, another exception occurred:

Traceback (most recent call last):
  File "/home/trevea/miniconda3/envs/nlp-rag/lib/python3.12/site-packages/urllib3/connectionpool.py", line 790, in urlopen
    response = self._make_request(
               ^^^^^^^^^^^^^^^^^^^
  File "/home/trevea/miniconda3/envs/nlp-rag/lib/python3.12/site-packages/urllib3/connectionpool.py", line 491, in _make_request
    raise new_e
urllib3.exceptions.SSLError: [SSL: TLSV1_ALERT_INTERNAL_ERROR] tlsv1 alert internal error (_ssl.c:1000)

The above exception was the direct cause of the following exception:

Traceback (most recent call last):
  File "/home/trevea/miniconda3/envs/nlp-rag/lib/python3.12/site-packages/requests/adapters.py", line 486, in send
    resp = conn.urlopen(
           ^^^^^^^^^^^^^
  File "/home/trevea/miniconda3/envs/nlp-rag/lib/python3.12/site-packages/urllib3/connectionpool.py", line 844, in urlopen
    retries = retries.increment(
              ^^^^^^^^^^^^^^^^^^
  File "/home/trevea/miniconda3/envs/nlp-rag/lib/python3.12/site-packages/urllib3/util/retry.py", line 515, in increment
    raise MaxRetryError(_pool, url, reason) from reason  # type: ignore[arg-type]
    ^^^^^^^^^^^^^^^^^^^^^^^^^^^^^^^^^^^^^^^^^^^^^^^^^^^
urllib3.exceptions.MaxRetryError: HTTPSConnectionPool(host='api.mcucountdown.com', port=443): Max retries exceeded with url: /api?date=invalid-date (Caused by SSLError(SSLError(1, '[SSL: TLSV1_ALERT_INTERNAL_ERROR] tlsv1 alert internal error (_ssl.c:1000)')))

During handling of the above exception, another exception occurred:

Traceback (most recent call last):
  File "/home/trevea/Projects/ToolsForTheJobBenchmark/generation/Content/mcucountdown/api_test.py", line 20, in test_get_next_mcu_production_invalid_date
    response = get_next_mcu_production(date="invalid-date")
               ^^^^^^^^^^^^^^^^^^^^^^^^^^^^^^^^^^^^^^^^^^^^
  File "/home/trevea/Projects/ToolsForTheJobBenchmark/generation/Content/mcucountdown/api.py", line 15, in get_next_mcu_production
    response = requests.get(url, params=params)
               ^^^^^^^^^^^^^^^^^^^^^^^^^^^^^^^^
  File "/home/trevea/miniconda3/envs/nlp-rag/lib/python3.12/site-packages/requests/api.py", line 73, in get
    return request("get", url, params=params, **kwargs)
           ^^^^^^^^^^^^^^^^^^^^^^^^^^^^^^^^^^^^^^^^^^^^
  File "/home/trevea/miniconda3/envs/nlp-rag/lib/python3.12/site-packages/requests/api.py", line 59, in request
    return session.request(method=method, url=url, **kwargs)
           ^^^^^^^^^^^^^^^^^^^^^^^^^^^^^^^^^^^^^^^^^^^^^^^^^
  File "/home/trevea/miniconda3/envs/nlp-rag/lib/python3.12/site-packages/requests/sessions.py", line 589, in request
    resp = self.send(prep, **send_kwargs)
           ^^^^^^^^^^^^^^^^^^^^^^^^^^^^^^
  File "/home/trevea/miniconda3/envs/nlp-rag/lib/python3.12/site-packages/requests/sessions.py", line 703, in send
    r = adapter.send(request, **kwargs)
        ^^^^^^^^^^^^^^^^^^^^^^^^^^^^^^^
  File "/home/trevea/miniconda3/envs/nlp-rag/lib/python3.12/site-packages/requests/adapters.py", line 517, in send
    raise SSLError(e, request=request)
requests.exceptions.SSLError: HTTPSConnectionPool(host='api.mcucountdown.com', port=443): Max retries exceeded with url: /api?date=invalid-date (Caused by SSLError(SSLError(1, '[SSL: TLSV1_ALERT_INTERNAL_ERROR] tlsv1 alert internal error (_ssl.c:1000)')))

======================================================================
ERROR: test_get_next_mcu_production_with_date (__main__.TestMCUCountdownAPI.test_get_next_mcu_production_with_date)
Test the call to get the next MCU production starting from a specific date
----------------------------------------------------------------------
Traceback (most recent call last):
  File "/home/trevea/miniconda3/envs/nlp-rag/lib/python3.12/site-packages/urllib3/connectionpool.py", line 467, in _make_request
    self._validate_conn(conn)
  File "/home/trevea/miniconda3/envs/nlp-rag/lib/python3.12/site-packages/urllib3/connectionpool.py", line 1096, in _validate_conn
    conn.connect()
  File "/home/trevea/miniconda3/envs/nlp-rag/lib/python3.12/site-packages/urllib3/connection.py", line 642, in connect
    sock_and_verified = _ssl_wrap_socket_and_match_hostname(
                        ^^^^^^^^^^^^^^^^^^^^^^^^^^^^^^^^^^^^
  File "/home/trevea/miniconda3/envs/nlp-rag/lib/python3.12/site-packages/urllib3/connection.py", line 782, in _ssl_wrap_socket_and_match_hostname
    ssl_sock = ssl_wrap_socket(
               ^^^^^^^^^^^^^^^^
  File "/home/trevea/miniconda3/envs/nlp-rag/lib/python3.12/site-packages/urllib3/util/ssl_.py", line 470, in ssl_wrap_socket
    ssl_sock = _ssl_wrap_socket_impl(sock, context, tls_in_tls, server_hostname)
               ^^^^^^^^^^^^^^^^^^^^^^^^^^^^^^^^^^^^^^^^^^^^^^^^^^^^^^^^^^^^^^^^^
  File "/home/trevea/miniconda3/envs/nlp-rag/lib/python3.12/site-packages/urllib3/util/ssl_.py", line 514, in _ssl_wrap_socket_impl
    return ssl_context.wrap_socket(sock, server_hostname=server_hostname)
           ^^^^^^^^^^^^^^^^^^^^^^^^^^^^^^^^^^^^^^^^^^^^^^^^^^^^^^^^^^^^^^
  File "/home/trevea/miniconda3/envs/nlp-rag/lib/python3.12/ssl.py", line 455, in wrap_socket
    return self.sslsocket_class._create(
           ^^^^^^^^^^^^^^^^^^^^^^^^^^^^^
  File "/home/trevea/miniconda3/envs/nlp-rag/lib/python3.12/ssl.py", line 1046, in _create
    self.do_handshake()
  File "/home/trevea/miniconda3/envs/nlp-rag/lib/python3.12/ssl.py", line 1321, in do_handshake
    self._sslobj.do_handshake()
ssl.SSLError: [SSL: TLSV1_ALERT_INTERNAL_ERROR] tlsv1 alert internal error (_ssl.c:1000)

During handling of the above exception, another exception occurred:

Traceback (most recent call last):
  File "/home/trevea/miniconda3/envs/nlp-rag/lib/python3.12/site-packages/urllib3/connectionpool.py", line 790, in urlopen
    response = self._make_request(
               ^^^^^^^^^^^^^^^^^^^
  File "/home/trevea/miniconda3/envs/nlp-rag/lib/python3.12/site-packages/urllib3/connectionpool.py", line 491, in _make_request
    raise new_e
urllib3.exceptions.SSLError: [SSL: TLSV1_ALERT_INTERNAL_ERROR] tlsv1 alert internal error (_ssl.c:1000)

The above exception was the direct cause of the following exception:

Traceback (most recent call last):
  File "/home/trevea/miniconda3/envs/nlp-rag/lib/python3.12/site-packages/requests/adapters.py", line 486, in send
    resp = conn.urlopen(
           ^^^^^^^^^^^^^
  File "/home/trevea/miniconda3/envs/nlp-rag/lib/python3.12/site-packages/urllib3/connectionpool.py", line 844, in urlopen
    retries = retries.increment(
              ^^^^^^^^^^^^^^^^^^
  File "/home/trevea/miniconda3/envs/nlp-rag/lib/python3.12/site-packages/urllib3/util/retry.py", line 515, in increment
    raise MaxRetryError(_pool, url, reason) from reason  # type: ignore[arg-type]
    ^^^^^^^^^^^^^^^^^^^^^^^^^^^^^^^^^^^^^^^^^^^^^^^^^^^
urllib3.exceptions.MaxRetryError: HTTPSConnectionPool(host='api.mcucountdown.com', port=443): Max retries exceeded with url: /api?date=2020-11-01 (Caused by SSLError(SSLError(1, '[SSL: TLSV1_ALERT_INTERNAL_ERROR] tlsv1 alert internal error (_ssl.c:1000)')))

During handling of the above exception, another exception occurred:

Traceback (most recent call last):
  File "/home/trevea/Projects/ToolsForTheJobBenchmark/generation/Content/mcucountdown/api_test.py", line 14, in test_get_next_mcu_production_with_date
    response = get_next_mcu_production(date="2020-11-01")
               ^^^^^^^^^^^^^^^^^^^^^^^^^^^^^^^^^^^^^^^^^^
  File "/home/trevea/Projects/ToolsForTheJobBenchmark/generation/Content/mcucountdown/api.py", line 15, in get_next_mcu_production
    response = requests.get(url, params=params)
               ^^^^^^^^^^^^^^^^^^^^^^^^^^^^^^^^
  File "/home/trevea/miniconda3/envs/nlp-rag/lib/python3.12/site-packages/requests/api.py", line 73, in get
    return request("get", url, params=params, **kwargs)
           ^^^^^^^^^^^^^^^^^^^^^^^^^^^^^^^^^^^^^^^^^^^^
  File "/home/trevea/miniconda3/envs/nlp-rag/lib/python3.12/site-packages/requests/api.py", line 59, in request
    return session.request(method=method, url=url, **kwargs)
           ^^^^^^^^^^^^^^^^^^^^^^^^^^^^^^^^^^^^^^^^^^^^^^^^^
  File "/home/trevea/miniconda3/envs/nlp-rag/lib/python3.12/site-packages/requests/sessions.py", line 589, in request
    resp = self.send(prep, **send_kwargs)
           ^^^^^^^^^^^^^^^^^^^^^^^^^^^^^^
  File "/home/trevea/miniconda3/envs/nlp-rag/lib/python3.12/site-packages/requests/sessions.py", line 703, in send
    r = adapter.send(request, **kwargs)
        ^^^^^^^^^^^^^^^^^^^^^^^^^^^^^^^
  File "/home/trevea/miniconda3/envs/nlp-rag/lib/python3.12/site-packages/requests/adapters.py", line 517, in send
    raise SSLError(e, request=request)
requests.exceptions.SSLError: HTTPSConnectionPool(host='api.mcucountdown.com', port=443): Max retries exceeded with url: /api?date=2020-11-01 (Caused by SSLError(SSLError(1, '[SSL: TLSV1_ALERT_INTERNAL_ERROR] tlsv1 alert internal error (_ssl.c:1000)')))

----------------------------------------------------------------------
Ran 3 tests in 10.871s

FAILED (errors=3)
Tests completed for API 'mcucountdown'

==================================================

Running tests for API 'chroniclingamerica'...
....FFF.
======================================================================
FAIL: test_get_specific_batch_json (__main__.TestChroniclingAmericaAPI.test_get_specific_batch_json)
----------------------------------------------------------------------
Traceback (most recent call last):
  File "/home/trevea/Projects/ToolsForTheJobBenchmark/generation/Content/chroniclingamerica/api_test.py", line 36, in test_get_specific_batch_json
    assert 'name' in response and 'pages' in response
AssertionError

======================================================================
FAIL: test_search_pages (__main__.TestChroniclingAmericaAPI.test_search_pages)
----------------------------------------------------------------------
Traceback (most recent call last):
  File "/home/trevea/Projects/ToolsForTheJobBenchmark/generation/Content/chroniclingamerica/api_test.py", line 20, in test_search_pages
    assert 'results' in response
AssertionError

======================================================================
FAIL: test_search_titles (__main__.TestChroniclingAmericaAPI.test_search_titles)
----------------------------------------------------------------------
Traceback (most recent call last):
  File "/home/trevea/Projects/ToolsForTheJobBenchmark/generation/Content/chroniclingamerica/api_test.py", line 16, in test_search_titles
    assert 'results' in response
AssertionError

----------------------------------------------------------------------
Ran 8 tests in 12.074s

FAILED (failures=3)
Tests completed for API 'chroniclingamerica'

==================================================

Running tests for API 'therosary'...
Tests completed for API 'therosary'

==================================================

python3: can't open file '/home/trevea/Projects/ToolsForTheJobBenchmark/generation/Content/therosary/api_test.py': [Errno 2] No such file or directory
Running tests for API 'swapi'...
.............
----------------------------------------------------------------------
Ran 13 tests in 11.591s

OK
Tests completed for API 'swapi'

==================================================

Running tests for API '4chan'...
EEEEEE
======================================================================
ERROR: test_get_archive (__main__.Test4ChanAPI.test_get_archive)
----------------------------------------------------------------------
Traceback (most recent call last):
  File "/home/trevea/miniconda3/envs/nlp-rag/lib/python3.12/site-packages/urllib3/connectionpool.py", line 790, in urlopen
    response = self._make_request(
               ^^^^^^^^^^^^^^^^^^^
  File "/home/trevea/miniconda3/envs/nlp-rag/lib/python3.12/site-packages/urllib3/connectionpool.py", line 491, in _make_request
    raise new_e
  File "/home/trevea/miniconda3/envs/nlp-rag/lib/python3.12/site-packages/urllib3/connectionpool.py", line 467, in _make_request
    self._validate_conn(conn)
  File "/home/trevea/miniconda3/envs/nlp-rag/lib/python3.12/site-packages/urllib3/connectionpool.py", line 1096, in _validate_conn
    conn.connect()
  File "/home/trevea/miniconda3/envs/nlp-rag/lib/python3.12/site-packages/urllib3/connection.py", line 642, in connect
    sock_and_verified = _ssl_wrap_socket_and_match_hostname(
                        ^^^^^^^^^^^^^^^^^^^^^^^^^^^^^^^^^^^^
  File "/home/trevea/miniconda3/envs/nlp-rag/lib/python3.12/site-packages/urllib3/connection.py", line 782, in _ssl_wrap_socket_and_match_hostname
    ssl_sock = ssl_wrap_socket(
               ^^^^^^^^^^^^^^^^
  File "/home/trevea/miniconda3/envs/nlp-rag/lib/python3.12/site-packages/urllib3/util/ssl_.py", line 470, in ssl_wrap_socket
    ssl_sock = _ssl_wrap_socket_impl(sock, context, tls_in_tls, server_hostname)
               ^^^^^^^^^^^^^^^^^^^^^^^^^^^^^^^^^^^^^^^^^^^^^^^^^^^^^^^^^^^^^^^^^
  File "/home/trevea/miniconda3/envs/nlp-rag/lib/python3.12/site-packages/urllib3/util/ssl_.py", line 514, in _ssl_wrap_socket_impl
    return ssl_context.wrap_socket(sock, server_hostname=server_hostname)
           ^^^^^^^^^^^^^^^^^^^^^^^^^^^^^^^^^^^^^^^^^^^^^^^^^^^^^^^^^^^^^^
  File "/home/trevea/miniconda3/envs/nlp-rag/lib/python3.12/ssl.py", line 455, in wrap_socket
    return self.sslsocket_class._create(
           ^^^^^^^^^^^^^^^^^^^^^^^^^^^^^
  File "/home/trevea/miniconda3/envs/nlp-rag/lib/python3.12/ssl.py", line 1046, in _create
    self.do_handshake()
  File "/home/trevea/miniconda3/envs/nlp-rag/lib/python3.12/ssl.py", line 1321, in do_handshake
    self._sslobj.do_handshake()
ConnectionResetError: [Errno 104] Connection reset by peer

During handling of the above exception, another exception occurred:

Traceback (most recent call last):
  File "/home/trevea/miniconda3/envs/nlp-rag/lib/python3.12/site-packages/requests/adapters.py", line 486, in send
    resp = conn.urlopen(
           ^^^^^^^^^^^^^
  File "/home/trevea/miniconda3/envs/nlp-rag/lib/python3.12/site-packages/urllib3/connectionpool.py", line 844, in urlopen
    retries = retries.increment(
              ^^^^^^^^^^^^^^^^^^
  File "/home/trevea/miniconda3/envs/nlp-rag/lib/python3.12/site-packages/urllib3/util/retry.py", line 470, in increment
    raise reraise(type(error), error, _stacktrace)
          ^^^^^^^^^^^^^^^^^^^^^^^^^^^^^^^^^^^^^^^^
  File "/home/trevea/miniconda3/envs/nlp-rag/lib/python3.12/site-packages/urllib3/util/util.py", line 38, in reraise
    raise value.with_traceback(tb)
  File "/home/trevea/miniconda3/envs/nlp-rag/lib/python3.12/site-packages/urllib3/connectionpool.py", line 790, in urlopen
    response = self._make_request(
               ^^^^^^^^^^^^^^^^^^^
  File "/home/trevea/miniconda3/envs/nlp-rag/lib/python3.12/site-packages/urllib3/connectionpool.py", line 491, in _make_request
    raise new_e
  File "/home/trevea/miniconda3/envs/nlp-rag/lib/python3.12/site-packages/urllib3/connectionpool.py", line 467, in _make_request
    self._validate_conn(conn)
  File "/home/trevea/miniconda3/envs/nlp-rag/lib/python3.12/site-packages/urllib3/connectionpool.py", line 1096, in _validate_conn
    conn.connect()
  File "/home/trevea/miniconda3/envs/nlp-rag/lib/python3.12/site-packages/urllib3/connection.py", line 642, in connect
    sock_and_verified = _ssl_wrap_socket_and_match_hostname(
                        ^^^^^^^^^^^^^^^^^^^^^^^^^^^^^^^^^^^^
  File "/home/trevea/miniconda3/envs/nlp-rag/lib/python3.12/site-packages/urllib3/connection.py", line 782, in _ssl_wrap_socket_and_match_hostname
    ssl_sock = ssl_wrap_socket(
               ^^^^^^^^^^^^^^^^
  File "/home/trevea/miniconda3/envs/nlp-rag/lib/python3.12/site-packages/urllib3/util/ssl_.py", line 470, in ssl_wrap_socket
    ssl_sock = _ssl_wrap_socket_impl(sock, context, tls_in_tls, server_hostname)
               ^^^^^^^^^^^^^^^^^^^^^^^^^^^^^^^^^^^^^^^^^^^^^^^^^^^^^^^^^^^^^^^^^
  File "/home/trevea/miniconda3/envs/nlp-rag/lib/python3.12/site-packages/urllib3/util/ssl_.py", line 514, in _ssl_wrap_socket_impl
    return ssl_context.wrap_socket(sock, server_hostname=server_hostname)
           ^^^^^^^^^^^^^^^^^^^^^^^^^^^^^^^^^^^^^^^^^^^^^^^^^^^^^^^^^^^^^^
  File "/home/trevea/miniconda3/envs/nlp-rag/lib/python3.12/ssl.py", line 455, in wrap_socket
    return self.sslsocket_class._create(
           ^^^^^^^^^^^^^^^^^^^^^^^^^^^^^
  File "/home/trevea/miniconda3/envs/nlp-rag/lib/python3.12/ssl.py", line 1046, in _create
    self.do_handshake()
  File "/home/trevea/miniconda3/envs/nlp-rag/lib/python3.12/ssl.py", line 1321, in do_handshake
    self._sslobj.do_handshake()
urllib3.exceptions.ProtocolError: ('Connection aborted.', ConnectionResetError(104, 'Connection reset by peer'))

During handling of the above exception, another exception occurred:

Traceback (most recent call last):
  File "/home/trevea/Projects/ToolsForTheJobBenchmark/generation/Content/4chan/api_test.py", line 19, in test_get_archive
    response = get_archive('po')
               ^^^^^^^^^^^^^^^^^
  File "/home/trevea/Projects/ToolsForTheJobBenchmark/generation/Content/4chan/api.py", line 51, in get_archive
    response = requests.get(url)
               ^^^^^^^^^^^^^^^^^
  File "/home/trevea/miniconda3/envs/nlp-rag/lib/python3.12/site-packages/requests/api.py", line 73, in get
    return request("get", url, params=params, **kwargs)
           ^^^^^^^^^^^^^^^^^^^^^^^^^^^^^^^^^^^^^^^^^^^^
  File "/home/trevea/miniconda3/envs/nlp-rag/lib/python3.12/site-packages/requests/api.py", line 59, in request
    return session.request(method=method, url=url, **kwargs)
           ^^^^^^^^^^^^^^^^^^^^^^^^^^^^^^^^^^^^^^^^^^^^^^^^^
  File "/home/trevea/miniconda3/envs/nlp-rag/lib/python3.12/site-packages/requests/sessions.py", line 589, in request
    resp = self.send(prep, **send_kwargs)
           ^^^^^^^^^^^^^^^^^^^^^^^^^^^^^^
  File "/home/trevea/miniconda3/envs/nlp-rag/lib/python3.12/site-packages/requests/sessions.py", line 703, in send
    r = adapter.send(request, **kwargs)
        ^^^^^^^^^^^^^^^^^^^^^^^^^^^^^^^
  File "/home/trevea/miniconda3/envs/nlp-rag/lib/python3.12/site-packages/requests/adapters.py", line 501, in send
    raise ConnectionError(err, request=request)
requests.exceptions.ConnectionError: ('Connection aborted.', ConnectionResetError(104, 'Connection reset by peer'))

======================================================================
ERROR: test_get_boards (__main__.Test4ChanAPI.test_get_boards)
----------------------------------------------------------------------
Traceback (most recent call last):
  File "/home/trevea/miniconda3/envs/nlp-rag/lib/python3.12/site-packages/urllib3/connectionpool.py", line 790, in urlopen
    response = self._make_request(
               ^^^^^^^^^^^^^^^^^^^
  File "/home/trevea/miniconda3/envs/nlp-rag/lib/python3.12/site-packages/urllib3/connectionpool.py", line 491, in _make_request
    raise new_e
  File "/home/trevea/miniconda3/envs/nlp-rag/lib/python3.12/site-packages/urllib3/connectionpool.py", line 467, in _make_request
    self._validate_conn(conn)
  File "/home/trevea/miniconda3/envs/nlp-rag/lib/python3.12/site-packages/urllib3/connectionpool.py", line 1096, in _validate_conn
    conn.connect()
  File "/home/trevea/miniconda3/envs/nlp-rag/lib/python3.12/site-packages/urllib3/connection.py", line 642, in connect
    sock_and_verified = _ssl_wrap_socket_and_match_hostname(
                        ^^^^^^^^^^^^^^^^^^^^^^^^^^^^^^^^^^^^
  File "/home/trevea/miniconda3/envs/nlp-rag/lib/python3.12/site-packages/urllib3/connection.py", line 782, in _ssl_wrap_socket_and_match_hostname
    ssl_sock = ssl_wrap_socket(
               ^^^^^^^^^^^^^^^^
  File "/home/trevea/miniconda3/envs/nlp-rag/lib/python3.12/site-packages/urllib3/util/ssl_.py", line 470, in ssl_wrap_socket
    ssl_sock = _ssl_wrap_socket_impl(sock, context, tls_in_tls, server_hostname)
               ^^^^^^^^^^^^^^^^^^^^^^^^^^^^^^^^^^^^^^^^^^^^^^^^^^^^^^^^^^^^^^^^^
  File "/home/trevea/miniconda3/envs/nlp-rag/lib/python3.12/site-packages/urllib3/util/ssl_.py", line 514, in _ssl_wrap_socket_impl
    return ssl_context.wrap_socket(sock, server_hostname=server_hostname)
           ^^^^^^^^^^^^^^^^^^^^^^^^^^^^^^^^^^^^^^^^^^^^^^^^^^^^^^^^^^^^^^
  File "/home/trevea/miniconda3/envs/nlp-rag/lib/python3.12/ssl.py", line 455, in wrap_socket
    return self.sslsocket_class._create(
           ^^^^^^^^^^^^^^^^^^^^^^^^^^^^^
  File "/home/trevea/miniconda3/envs/nlp-rag/lib/python3.12/ssl.py", line 1046, in _create
    self.do_handshake()
  File "/home/trevea/miniconda3/envs/nlp-rag/lib/python3.12/ssl.py", line 1321, in do_handshake
    self._sslobj.do_handshake()
ConnectionResetError: [Errno 104] Connection reset by peer

During handling of the above exception, another exception occurred:

Traceback (most recent call last):
  File "/home/trevea/miniconda3/envs/nlp-rag/lib/python3.12/site-packages/requests/adapters.py", line 486, in send
    resp = conn.urlopen(
           ^^^^^^^^^^^^^
  File "/home/trevea/miniconda3/envs/nlp-rag/lib/python3.12/site-packages/urllib3/connectionpool.py", line 844, in urlopen
    retries = retries.increment(
              ^^^^^^^^^^^^^^^^^^
  File "/home/trevea/miniconda3/envs/nlp-rag/lib/python3.12/site-packages/urllib3/util/retry.py", line 470, in increment
    raise reraise(type(error), error, _stacktrace)
          ^^^^^^^^^^^^^^^^^^^^^^^^^^^^^^^^^^^^^^^^
  File "/home/trevea/miniconda3/envs/nlp-rag/lib/python3.12/site-packages/urllib3/util/util.py", line 38, in reraise
    raise value.with_traceback(tb)
  File "/home/trevea/miniconda3/envs/nlp-rag/lib/python3.12/site-packages/urllib3/connectionpool.py", line 790, in urlopen
    response = self._make_request(
               ^^^^^^^^^^^^^^^^^^^
  File "/home/trevea/miniconda3/envs/nlp-rag/lib/python3.12/site-packages/urllib3/connectionpool.py", line 491, in _make_request
    raise new_e
  File "/home/trevea/miniconda3/envs/nlp-rag/lib/python3.12/site-packages/urllib3/connectionpool.py", line 467, in _make_request
    self._validate_conn(conn)
  File "/home/trevea/miniconda3/envs/nlp-rag/lib/python3.12/site-packages/urllib3/connectionpool.py", line 1096, in _validate_conn
    conn.connect()
  File "/home/trevea/miniconda3/envs/nlp-rag/lib/python3.12/site-packages/urllib3/connection.py", line 642, in connect
    sock_and_verified = _ssl_wrap_socket_and_match_hostname(
                        ^^^^^^^^^^^^^^^^^^^^^^^^^^^^^^^^^^^^
  File "/home/trevea/miniconda3/envs/nlp-rag/lib/python3.12/site-packages/urllib3/connection.py", line 782, in _ssl_wrap_socket_and_match_hostname
    ssl_sock = ssl_wrap_socket(
               ^^^^^^^^^^^^^^^^
  File "/home/trevea/miniconda3/envs/nlp-rag/lib/python3.12/site-packages/urllib3/util/ssl_.py", line 470, in ssl_wrap_socket
    ssl_sock = _ssl_wrap_socket_impl(sock, context, tls_in_tls, server_hostname)
               ^^^^^^^^^^^^^^^^^^^^^^^^^^^^^^^^^^^^^^^^^^^^^^^^^^^^^^^^^^^^^^^^^
  File "/home/trevea/miniconda3/envs/nlp-rag/lib/python3.12/site-packages/urllib3/util/ssl_.py", line 514, in _ssl_wrap_socket_impl
    return ssl_context.wrap_socket(sock, server_hostname=server_hostname)
           ^^^^^^^^^^^^^^^^^^^^^^^^^^^^^^^^^^^^^^^^^^^^^^^^^^^^^^^^^^^^^^
  File "/home/trevea/miniconda3/envs/nlp-rag/lib/python3.12/ssl.py", line 455, in wrap_socket
    return self.sslsocket_class._create(
           ^^^^^^^^^^^^^^^^^^^^^^^^^^^^^
  File "/home/trevea/miniconda3/envs/nlp-rag/lib/python3.12/ssl.py", line 1046, in _create
    self.do_handshake()
  File "/home/trevea/miniconda3/envs/nlp-rag/lib/python3.12/ssl.py", line 1321, in do_handshake
    self._sslobj.do_handshake()
urllib3.exceptions.ProtocolError: ('Connection aborted.', ConnectionResetError(104, 'Connection reset by peer'))

During handling of the above exception, another exception occurred:

Traceback (most recent call last):
  File "/home/trevea/Projects/ToolsForTheJobBenchmark/generation/Content/4chan/api_test.py", line 7, in test_get_boards
    response = get_boards()
               ^^^^^^^^^^^^
  File "/home/trevea/Projects/ToolsForTheJobBenchmark/generation/Content/4chan/api.py", line 8, in get_boards
    response = requests.get(url)
               ^^^^^^^^^^^^^^^^^
  File "/home/trevea/miniconda3/envs/nlp-rag/lib/python3.12/site-packages/requests/api.py", line 73, in get
    return request("get", url, params=params, **kwargs)
           ^^^^^^^^^^^^^^^^^^^^^^^^^^^^^^^^^^^^^^^^^^^^
  File "/home/trevea/miniconda3/envs/nlp-rag/lib/python3.12/site-packages/requests/api.py", line 59, in request
    return session.request(method=method, url=url, **kwargs)
           ^^^^^^^^^^^^^^^^^^^^^^^^^^^^^^^^^^^^^^^^^^^^^^^^^
  File "/home/trevea/miniconda3/envs/nlp-rag/lib/python3.12/site-packages/requests/sessions.py", line 589, in request
    resp = self.send(prep, **send_kwargs)
           ^^^^^^^^^^^^^^^^^^^^^^^^^^^^^^
  File "/home/trevea/miniconda3/envs/nlp-rag/lib/python3.12/site-packages/requests/sessions.py", line 703, in send
    r = adapter.send(request, **kwargs)
        ^^^^^^^^^^^^^^^^^^^^^^^^^^^^^^^
  File "/home/trevea/miniconda3/envs/nlp-rag/lib/python3.12/site-packages/requests/adapters.py", line 501, in send
    raise ConnectionError(err, request=request)
requests.exceptions.ConnectionError: ('Connection aborted.', ConnectionResetError(104, 'Connection reset by peer'))

======================================================================
ERROR: test_get_catalog (__main__.Test4ChanAPI.test_get_catalog)
----------------------------------------------------------------------
Traceback (most recent call last):
  File "/home/trevea/miniconda3/envs/nlp-rag/lib/python3.12/site-packages/urllib3/connectionpool.py", line 790, in urlopen
    response = self._make_request(
               ^^^^^^^^^^^^^^^^^^^
  File "/home/trevea/miniconda3/envs/nlp-rag/lib/python3.12/site-packages/urllib3/connectionpool.py", line 491, in _make_request
    raise new_e
  File "/home/trevea/miniconda3/envs/nlp-rag/lib/python3.12/site-packages/urllib3/connectionpool.py", line 467, in _make_request
    self._validate_conn(conn)
  File "/home/trevea/miniconda3/envs/nlp-rag/lib/python3.12/site-packages/urllib3/connectionpool.py", line 1096, in _validate_conn
    conn.connect()
  File "/home/trevea/miniconda3/envs/nlp-rag/lib/python3.12/site-packages/urllib3/connection.py", line 642, in connect
    sock_and_verified = _ssl_wrap_socket_and_match_hostname(
                        ^^^^^^^^^^^^^^^^^^^^^^^^^^^^^^^^^^^^
  File "/home/trevea/miniconda3/envs/nlp-rag/lib/python3.12/site-packages/urllib3/connection.py", line 782, in _ssl_wrap_socket_and_match_hostname
    ssl_sock = ssl_wrap_socket(
               ^^^^^^^^^^^^^^^^
  File "/home/trevea/miniconda3/envs/nlp-rag/lib/python3.12/site-packages/urllib3/util/ssl_.py", line 470, in ssl_wrap_socket
    ssl_sock = _ssl_wrap_socket_impl(sock, context, tls_in_tls, server_hostname)
               ^^^^^^^^^^^^^^^^^^^^^^^^^^^^^^^^^^^^^^^^^^^^^^^^^^^^^^^^^^^^^^^^^
  File "/home/trevea/miniconda3/envs/nlp-rag/lib/python3.12/site-packages/urllib3/util/ssl_.py", line 514, in _ssl_wrap_socket_impl
    return ssl_context.wrap_socket(sock, server_hostname=server_hostname)
           ^^^^^^^^^^^^^^^^^^^^^^^^^^^^^^^^^^^^^^^^^^^^^^^^^^^^^^^^^^^^^^
  File "/home/trevea/miniconda3/envs/nlp-rag/lib/python3.12/ssl.py", line 455, in wrap_socket
    return self.sslsocket_class._create(
           ^^^^^^^^^^^^^^^^^^^^^^^^^^^^^
  File "/home/trevea/miniconda3/envs/nlp-rag/lib/python3.12/ssl.py", line 1046, in _create
    self.do_handshake()
  File "/home/trevea/miniconda3/envs/nlp-rag/lib/python3.12/ssl.py", line 1321, in do_handshake
    self._sslobj.do_handshake()
ConnectionResetError: [Errno 104] Connection reset by peer

During handling of the above exception, another exception occurred:

Traceback (most recent call last):
  File "/home/trevea/miniconda3/envs/nlp-rag/lib/python3.12/site-packages/requests/adapters.py", line 486, in send
    resp = conn.urlopen(
           ^^^^^^^^^^^^^
  File "/home/trevea/miniconda3/envs/nlp-rag/lib/python3.12/site-packages/urllib3/connectionpool.py", line 844, in urlopen
    retries = retries.increment(
              ^^^^^^^^^^^^^^^^^^
  File "/home/trevea/miniconda3/envs/nlp-rag/lib/python3.12/site-packages/urllib3/util/retry.py", line 470, in increment
    raise reraise(type(error), error, _stacktrace)
          ^^^^^^^^^^^^^^^^^^^^^^^^^^^^^^^^^^^^^^^^
  File "/home/trevea/miniconda3/envs/nlp-rag/lib/python3.12/site-packages/urllib3/util/util.py", line 38, in reraise
    raise value.with_traceback(tb)
  File "/home/trevea/miniconda3/envs/nlp-rag/lib/python3.12/site-packages/urllib3/connectionpool.py", line 790, in urlopen
    response = self._make_request(
               ^^^^^^^^^^^^^^^^^^^
  File "/home/trevea/miniconda3/envs/nlp-rag/lib/python3.12/site-packages/urllib3/connectionpool.py", line 491, in _make_request
    raise new_e
  File "/home/trevea/miniconda3/envs/nlp-rag/lib/python3.12/site-packages/urllib3/connectionpool.py", line 467, in _make_request
    self._validate_conn(conn)
  File "/home/trevea/miniconda3/envs/nlp-rag/lib/python3.12/site-packages/urllib3/connectionpool.py", line 1096, in _validate_conn
    conn.connect()
  File "/home/trevea/miniconda3/envs/nlp-rag/lib/python3.12/site-packages/urllib3/connection.py", line 642, in connect
    sock_and_verified = _ssl_wrap_socket_and_match_hostname(
                        ^^^^^^^^^^^^^^^^^^^^^^^^^^^^^^^^^^^^
  File "/home/trevea/miniconda3/envs/nlp-rag/lib/python3.12/site-packages/urllib3/connection.py", line 782, in _ssl_wrap_socket_and_match_hostname
    ssl_sock = ssl_wrap_socket(
               ^^^^^^^^^^^^^^^^
  File "/home/trevea/miniconda3/envs/nlp-rag/lib/python3.12/site-packages/urllib3/util/ssl_.py", line 470, in ssl_wrap_socket
    ssl_sock = _ssl_wrap_socket_impl(sock, context, tls_in_tls, server_hostname)
               ^^^^^^^^^^^^^^^^^^^^^^^^^^^^^^^^^^^^^^^^^^^^^^^^^^^^^^^^^^^^^^^^^
  File "/home/trevea/miniconda3/envs/nlp-rag/lib/python3.12/site-packages/urllib3/util/ssl_.py", line 514, in _ssl_wrap_socket_impl
    return ssl_context.wrap_socket(sock, server_hostname=server_hostname)
           ^^^^^^^^^^^^^^^^^^^^^^^^^^^^^^^^^^^^^^^^^^^^^^^^^^^^^^^^^^^^^^
  File "/home/trevea/miniconda3/envs/nlp-rag/lib/python3.12/ssl.py", line 455, in wrap_socket
    return self.sslsocket_class._create(
           ^^^^^^^^^^^^^^^^^^^^^^^^^^^^^
  File "/home/trevea/miniconda3/envs/nlp-rag/lib/python3.12/ssl.py", line 1046, in _create
    self.do_handshake()
  File "/home/trevea/miniconda3/envs/nlp-rag/lib/python3.12/ssl.py", line 1321, in do_handshake
    self._sslobj.do_handshake()
urllib3.exceptions.ProtocolError: ('Connection aborted.', ConnectionResetError(104, 'Connection reset by peer'))

During handling of the above exception, another exception occurred:

Traceback (most recent call last):
  File "/home/trevea/Projects/ToolsForTheJobBenchmark/generation/Content/4chan/api_test.py", line 15, in test_get_catalog
    response = get_catalog('po')
               ^^^^^^^^^^^^^^^^^
  File "/home/trevea/Projects/ToolsForTheJobBenchmark/generation/Content/4chan/api.py", line 37, in get_catalog
    response = requests.get(url)
               ^^^^^^^^^^^^^^^^^
  File "/home/trevea/miniconda3/envs/nlp-rag/lib/python3.12/site-packages/requests/api.py", line 73, in get
    return request("get", url, params=params, **kwargs)
           ^^^^^^^^^^^^^^^^^^^^^^^^^^^^^^^^^^^^^^^^^^^^
  File "/home/trevea/miniconda3/envs/nlp-rag/lib/python3.12/site-packages/requests/api.py", line 59, in request
    return session.request(method=method, url=url, **kwargs)
           ^^^^^^^^^^^^^^^^^^^^^^^^^^^^^^^^^^^^^^^^^^^^^^^^^
  File "/home/trevea/miniconda3/envs/nlp-rag/lib/python3.12/site-packages/requests/sessions.py", line 589, in request
    resp = self.send(prep, **send_kwargs)
           ^^^^^^^^^^^^^^^^^^^^^^^^^^^^^^
  File "/home/trevea/miniconda3/envs/nlp-rag/lib/python3.12/site-packages/requests/sessions.py", line 703, in send
    r = adapter.send(request, **kwargs)
        ^^^^^^^^^^^^^^^^^^^^^^^^^^^^^^^
  File "/home/trevea/miniconda3/envs/nlp-rag/lib/python3.12/site-packages/requests/adapters.py", line 501, in send
    raise ConnectionError(err, request=request)
requests.exceptions.ConnectionError: ('Connection aborted.', ConnectionResetError(104, 'Connection reset by peer'))

======================================================================
ERROR: test_get_page (__main__.Test4ChanAPI.test_get_page)
----------------------------------------------------------------------
Traceback (most recent call last):
  File "/home/trevea/miniconda3/envs/nlp-rag/lib/python3.12/site-packages/urllib3/connectionpool.py", line 790, in urlopen
    response = self._make_request(
               ^^^^^^^^^^^^^^^^^^^
  File "/home/trevea/miniconda3/envs/nlp-rag/lib/python3.12/site-packages/urllib3/connectionpool.py", line 491, in _make_request
    raise new_e
  File "/home/trevea/miniconda3/envs/nlp-rag/lib/python3.12/site-packages/urllib3/connectionpool.py", line 467, in _make_request
    self._validate_conn(conn)
  File "/home/trevea/miniconda3/envs/nlp-rag/lib/python3.12/site-packages/urllib3/connectionpool.py", line 1096, in _validate_conn
    conn.connect()
  File "/home/trevea/miniconda3/envs/nlp-rag/lib/python3.12/site-packages/urllib3/connection.py", line 642, in connect
    sock_and_verified = _ssl_wrap_socket_and_match_hostname(
                        ^^^^^^^^^^^^^^^^^^^^^^^^^^^^^^^^^^^^
  File "/home/trevea/miniconda3/envs/nlp-rag/lib/python3.12/site-packages/urllib3/connection.py", line 782, in _ssl_wrap_socket_and_match_hostname
    ssl_sock = ssl_wrap_socket(
               ^^^^^^^^^^^^^^^^
  File "/home/trevea/miniconda3/envs/nlp-rag/lib/python3.12/site-packages/urllib3/util/ssl_.py", line 470, in ssl_wrap_socket
    ssl_sock = _ssl_wrap_socket_impl(sock, context, tls_in_tls, server_hostname)
               ^^^^^^^^^^^^^^^^^^^^^^^^^^^^^^^^^^^^^^^^^^^^^^^^^^^^^^^^^^^^^^^^^
  File "/home/trevea/miniconda3/envs/nlp-rag/lib/python3.12/site-packages/urllib3/util/ssl_.py", line 514, in _ssl_wrap_socket_impl
    return ssl_context.wrap_socket(sock, server_hostname=server_hostname)
           ^^^^^^^^^^^^^^^^^^^^^^^^^^^^^^^^^^^^^^^^^^^^^^^^^^^^^^^^^^^^^^
  File "/home/trevea/miniconda3/envs/nlp-rag/lib/python3.12/ssl.py", line 455, in wrap_socket
    return self.sslsocket_class._create(
           ^^^^^^^^^^^^^^^^^^^^^^^^^^^^^
  File "/home/trevea/miniconda3/envs/nlp-rag/lib/python3.12/ssl.py", line 1046, in _create
    self.do_handshake()
  File "/home/trevea/miniconda3/envs/nlp-rag/lib/python3.12/ssl.py", line 1321, in do_handshake
    self._sslobj.do_handshake()
ConnectionResetError: [Errno 104] Connection reset by peer

During handling of the above exception, another exception occurred:

Traceback (most recent call last):
  File "/home/trevea/miniconda3/envs/nlp-rag/lib/python3.12/site-packages/requests/adapters.py", line 486, in send
    resp = conn.urlopen(
           ^^^^^^^^^^^^^
  File "/home/trevea/miniconda3/envs/nlp-rag/lib/python3.12/site-packages/urllib3/connectionpool.py", line 844, in urlopen
    retries = retries.increment(
              ^^^^^^^^^^^^^^^^^^
  File "/home/trevea/miniconda3/envs/nlp-rag/lib/python3.12/site-packages/urllib3/util/retry.py", line 470, in increment
    raise reraise(type(error), error, _stacktrace)
          ^^^^^^^^^^^^^^^^^^^^^^^^^^^^^^^^^^^^^^^^
  File "/home/trevea/miniconda3/envs/nlp-rag/lib/python3.12/site-packages/urllib3/util/util.py", line 38, in reraise
    raise value.with_traceback(tb)
  File "/home/trevea/miniconda3/envs/nlp-rag/lib/python3.12/site-packages/urllib3/connectionpool.py", line 790, in urlopen
    response = self._make_request(
               ^^^^^^^^^^^^^^^^^^^
  File "/home/trevea/miniconda3/envs/nlp-rag/lib/python3.12/site-packages/urllib3/connectionpool.py", line 491, in _make_request
    raise new_e
  File "/home/trevea/miniconda3/envs/nlp-rag/lib/python3.12/site-packages/urllib3/connectionpool.py", line 467, in _make_request
    self._validate_conn(conn)
  File "/home/trevea/miniconda3/envs/nlp-rag/lib/python3.12/site-packages/urllib3/connectionpool.py", line 1096, in _validate_conn
    conn.connect()
  File "/home/trevea/miniconda3/envs/nlp-rag/lib/python3.12/site-packages/urllib3/connection.py", line 642, in connect
    sock_and_verified = _ssl_wrap_socket_and_match_hostname(
                        ^^^^^^^^^^^^^^^^^^^^^^^^^^^^^^^^^^^^
  File "/home/trevea/miniconda3/envs/nlp-rag/lib/python3.12/site-packages/urllib3/connection.py", line 782, in _ssl_wrap_socket_and_match_hostname
    ssl_sock = ssl_wrap_socket(
               ^^^^^^^^^^^^^^^^
  File "/home/trevea/miniconda3/envs/nlp-rag/lib/python3.12/site-packages/urllib3/util/ssl_.py", line 470, in ssl_wrap_socket
    ssl_sock = _ssl_wrap_socket_impl(sock, context, tls_in_tls, server_hostname)
               ^^^^^^^^^^^^^^^^^^^^^^^^^^^^^^^^^^^^^^^^^^^^^^^^^^^^^^^^^^^^^^^^^
  File "/home/trevea/miniconda3/envs/nlp-rag/lib/python3.12/site-packages/urllib3/util/ssl_.py", line 514, in _ssl_wrap_socket_impl
    return ssl_context.wrap_socket(sock, server_hostname=server_hostname)
           ^^^^^^^^^^^^^^^^^^^^^^^^^^^^^^^^^^^^^^^^^^^^^^^^^^^^^^^^^^^^^^
  File "/home/trevea/miniconda3/envs/nlp-rag/lib/python3.12/ssl.py", line 455, in wrap_socket
    return self.sslsocket_class._create(
           ^^^^^^^^^^^^^^^^^^^^^^^^^^^^^
  File "/home/trevea/miniconda3/envs/nlp-rag/lib/python3.12/ssl.py", line 1046, in _create
    self.do_handshake()
  File "/home/trevea/miniconda3/envs/nlp-rag/lib/python3.12/ssl.py", line 1321, in do_handshake
    self._sslobj.do_handshake()
urllib3.exceptions.ProtocolError: ('Connection aborted.', ConnectionResetError(104, 'Connection reset by peer'))

During handling of the above exception, another exception occurred:

Traceback (most recent call last):
  File "/home/trevea/Projects/ToolsForTheJobBenchmark/generation/Content/4chan/api_test.py", line 27, in test_get_page
    response = get_page('po', 1)
               ^^^^^^^^^^^^^^^^^
  File "/home/trevea/Projects/ToolsForTheJobBenchmark/generation/Content/4chan/api.py", line 81, in get_page
    response = requests.get(url)
               ^^^^^^^^^^^^^^^^^
  File "/home/trevea/miniconda3/envs/nlp-rag/lib/python3.12/site-packages/requests/api.py", line 73, in get
    return request("get", url, params=params, **kwargs)
           ^^^^^^^^^^^^^^^^^^^^^^^^^^^^^^^^^^^^^^^^^^^^
  File "/home/trevea/miniconda3/envs/nlp-rag/lib/python3.12/site-packages/requests/api.py", line 59, in request
    return session.request(method=method, url=url, **kwargs)
           ^^^^^^^^^^^^^^^^^^^^^^^^^^^^^^^^^^^^^^^^^^^^^^^^^
  File "/home/trevea/miniconda3/envs/nlp-rag/lib/python3.12/site-packages/requests/sessions.py", line 589, in request
    resp = self.send(prep, **send_kwargs)
           ^^^^^^^^^^^^^^^^^^^^^^^^^^^^^^
  File "/home/trevea/miniconda3/envs/nlp-rag/lib/python3.12/site-packages/requests/sessions.py", line 703, in send
    r = adapter.send(request, **kwargs)
        ^^^^^^^^^^^^^^^^^^^^^^^^^^^^^^^
  File "/home/trevea/miniconda3/envs/nlp-rag/lib/python3.12/site-packages/requests/adapters.py", line 501, in send
    raise ConnectionError(err, request=request)
requests.exceptions.ConnectionError: ('Connection aborted.', ConnectionResetError(104, 'Connection reset by peer'))

======================================================================
ERROR: test_get_thread (__main__.Test4ChanAPI.test_get_thread)
----------------------------------------------------------------------
Traceback (most recent call last):
  File "/home/trevea/miniconda3/envs/nlp-rag/lib/python3.12/site-packages/urllib3/connectionpool.py", line 790, in urlopen
    response = self._make_request(
               ^^^^^^^^^^^^^^^^^^^
  File "/home/trevea/miniconda3/envs/nlp-rag/lib/python3.12/site-packages/urllib3/connectionpool.py", line 491, in _make_request
    raise new_e
  File "/home/trevea/miniconda3/envs/nlp-rag/lib/python3.12/site-packages/urllib3/connectionpool.py", line 467, in _make_request
    self._validate_conn(conn)
  File "/home/trevea/miniconda3/envs/nlp-rag/lib/python3.12/site-packages/urllib3/connectionpool.py", line 1096, in _validate_conn
    conn.connect()
  File "/home/trevea/miniconda3/envs/nlp-rag/lib/python3.12/site-packages/urllib3/connection.py", line 642, in connect
    sock_and_verified = _ssl_wrap_socket_and_match_hostname(
                        ^^^^^^^^^^^^^^^^^^^^^^^^^^^^^^^^^^^^
  File "/home/trevea/miniconda3/envs/nlp-rag/lib/python3.12/site-packages/urllib3/connection.py", line 782, in _ssl_wrap_socket_and_match_hostname
    ssl_sock = ssl_wrap_socket(
               ^^^^^^^^^^^^^^^^
  File "/home/trevea/miniconda3/envs/nlp-rag/lib/python3.12/site-packages/urllib3/util/ssl_.py", line 470, in ssl_wrap_socket
    ssl_sock = _ssl_wrap_socket_impl(sock, context, tls_in_tls, server_hostname)
               ^^^^^^^^^^^^^^^^^^^^^^^^^^^^^^^^^^^^^^^^^^^^^^^^^^^^^^^^^^^^^^^^^
  File "/home/trevea/miniconda3/envs/nlp-rag/lib/python3.12/site-packages/urllib3/util/ssl_.py", line 514, in _ssl_wrap_socket_impl
    return ssl_context.wrap_socket(sock, server_hostname=server_hostname)
           ^^^^^^^^^^^^^^^^^^^^^^^^^^^^^^^^^^^^^^^^^^^^^^^^^^^^^^^^^^^^^^
  File "/home/trevea/miniconda3/envs/nlp-rag/lib/python3.12/ssl.py", line 455, in wrap_socket
    return self.sslsocket_class._create(
           ^^^^^^^^^^^^^^^^^^^^^^^^^^^^^
  File "/home/trevea/miniconda3/envs/nlp-rag/lib/python3.12/ssl.py", line 1046, in _create
    self.do_handshake()
  File "/home/trevea/miniconda3/envs/nlp-rag/lib/python3.12/ssl.py", line 1321, in do_handshake
    self._sslobj.do_handshake()
ConnectionResetError: [Errno 104] Connection reset by peer

During handling of the above exception, another exception occurred:

Traceback (most recent call last):
  File "/home/trevea/miniconda3/envs/nlp-rag/lib/python3.12/site-packages/requests/adapters.py", line 486, in send
    resp = conn.urlopen(
           ^^^^^^^^^^^^^
  File "/home/trevea/miniconda3/envs/nlp-rag/lib/python3.12/site-packages/urllib3/connectionpool.py", line 844, in urlopen
    retries = retries.increment(
              ^^^^^^^^^^^^^^^^^^
  File "/home/trevea/miniconda3/envs/nlp-rag/lib/python3.12/site-packages/urllib3/util/retry.py", line 470, in increment
    raise reraise(type(error), error, _stacktrace)
          ^^^^^^^^^^^^^^^^^^^^^^^^^^^^^^^^^^^^^^^^
  File "/home/trevea/miniconda3/envs/nlp-rag/lib/python3.12/site-packages/urllib3/util/util.py", line 38, in reraise
    raise value.with_traceback(tb)
  File "/home/trevea/miniconda3/envs/nlp-rag/lib/python3.12/site-packages/urllib3/connectionpool.py", line 790, in urlopen
    response = self._make_request(
               ^^^^^^^^^^^^^^^^^^^
  File "/home/trevea/miniconda3/envs/nlp-rag/lib/python3.12/site-packages/urllib3/connectionpool.py", line 491, in _make_request
    raise new_e
  File "/home/trevea/miniconda3/envs/nlp-rag/lib/python3.12/site-packages/urllib3/connectionpool.py", line 467, in _make_request
    self._validate_conn(conn)
  File "/home/trevea/miniconda3/envs/nlp-rag/lib/python3.12/site-packages/urllib3/connectionpool.py", line 1096, in _validate_conn
    conn.connect()
  File "/home/trevea/miniconda3/envs/nlp-rag/lib/python3.12/site-packages/urllib3/connection.py", line 642, in connect
    sock_and_verified = _ssl_wrap_socket_and_match_hostname(
                        ^^^^^^^^^^^^^^^^^^^^^^^^^^^^^^^^^^^^
  File "/home/trevea/miniconda3/envs/nlp-rag/lib/python3.12/site-packages/urllib3/connection.py", line 782, in _ssl_wrap_socket_and_match_hostname
    ssl_sock = ssl_wrap_socket(
               ^^^^^^^^^^^^^^^^
  File "/home/trevea/miniconda3/envs/nlp-rag/lib/python3.12/site-packages/urllib3/util/ssl_.py", line 470, in ssl_wrap_socket
    ssl_sock = _ssl_wrap_socket_impl(sock, context, tls_in_tls, server_hostname)
               ^^^^^^^^^^^^^^^^^^^^^^^^^^^^^^^^^^^^^^^^^^^^^^^^^^^^^^^^^^^^^^^^^
  File "/home/trevea/miniconda3/envs/nlp-rag/lib/python3.12/site-packages/urllib3/util/ssl_.py", line 514, in _ssl_wrap_socket_impl
    return ssl_context.wrap_socket(sock, server_hostname=server_hostname)
           ^^^^^^^^^^^^^^^^^^^^^^^^^^^^^^^^^^^^^^^^^^^^^^^^^^^^^^^^^^^^^^
  File "/home/trevea/miniconda3/envs/nlp-rag/lib/python3.12/ssl.py", line 455, in wrap_socket
    return self.sslsocket_class._create(
           ^^^^^^^^^^^^^^^^^^^^^^^^^^^^^
  File "/home/trevea/miniconda3/envs/nlp-rag/lib/python3.12/ssl.py", line 1046, in _create
    self.do_handshake()
  File "/home/trevea/miniconda3/envs/nlp-rag/lib/python3.12/ssl.py", line 1321, in do_handshake
    self._sslobj.do_handshake()
urllib3.exceptions.ProtocolError: ('Connection aborted.', ConnectionResetError(104, 'Connection reset by peer'))

During handling of the above exception, another exception occurred:

Traceback (most recent call last):
  File "/home/trevea/Projects/ToolsForTheJobBenchmark/generation/Content/4chan/api_test.py", line 23, in test_get_thread
    response = get_thread('po', 570368)
               ^^^^^^^^^^^^^^^^^^^^^^^^
  File "/home/trevea/Projects/ToolsForTheJobBenchmark/generation/Content/4chan/api.py", line 66, in get_thread
    response = requests.get(url)
               ^^^^^^^^^^^^^^^^^
  File "/home/trevea/miniconda3/envs/nlp-rag/lib/python3.12/site-packages/requests/api.py", line 73, in get
    return request("get", url, params=params, **kwargs)
           ^^^^^^^^^^^^^^^^^^^^^^^^^^^^^^^^^^^^^^^^^^^^
  File "/home/trevea/miniconda3/envs/nlp-rag/lib/python3.12/site-packages/requests/api.py", line 59, in request
    return session.request(method=method, url=url, **kwargs)
           ^^^^^^^^^^^^^^^^^^^^^^^^^^^^^^^^^^^^^^^^^^^^^^^^^
  File "/home/trevea/miniconda3/envs/nlp-rag/lib/python3.12/site-packages/requests/sessions.py", line 589, in request
    resp = self.send(prep, **send_kwargs)
           ^^^^^^^^^^^^^^^^^^^^^^^^^^^^^^
  File "/home/trevea/miniconda3/envs/nlp-rag/lib/python3.12/site-packages/requests/sessions.py", line 703, in send
    r = adapter.send(request, **kwargs)
        ^^^^^^^^^^^^^^^^^^^^^^^^^^^^^^^
  File "/home/trevea/miniconda3/envs/nlp-rag/lib/python3.12/site-packages/requests/adapters.py", line 501, in send
    raise ConnectionError(err, request=request)
requests.exceptions.ConnectionError: ('Connection aborted.', ConnectionResetError(104, 'Connection reset by peer'))

======================================================================
ERROR: test_get_threads (__main__.Test4ChanAPI.test_get_threads)
----------------------------------------------------------------------
Traceback (most recent call last):
  File "/home/trevea/miniconda3/envs/nlp-rag/lib/python3.12/site-packages/urllib3/connectionpool.py", line 790, in urlopen
    response = self._make_request(
               ^^^^^^^^^^^^^^^^^^^
  File "/home/trevea/miniconda3/envs/nlp-rag/lib/python3.12/site-packages/urllib3/connectionpool.py", line 491, in _make_request
    raise new_e
  File "/home/trevea/miniconda3/envs/nlp-rag/lib/python3.12/site-packages/urllib3/connectionpool.py", line 467, in _make_request
    self._validate_conn(conn)
  File "/home/trevea/miniconda3/envs/nlp-rag/lib/python3.12/site-packages/urllib3/connectionpool.py", line 1096, in _validate_conn
    conn.connect()
  File "/home/trevea/miniconda3/envs/nlp-rag/lib/python3.12/site-packages/urllib3/connection.py", line 642, in connect
    sock_and_verified = _ssl_wrap_socket_and_match_hostname(
                        ^^^^^^^^^^^^^^^^^^^^^^^^^^^^^^^^^^^^
  File "/home/trevea/miniconda3/envs/nlp-rag/lib/python3.12/site-packages/urllib3/connection.py", line 782, in _ssl_wrap_socket_and_match_hostname
    ssl_sock = ssl_wrap_socket(
               ^^^^^^^^^^^^^^^^
  File "/home/trevea/miniconda3/envs/nlp-rag/lib/python3.12/site-packages/urllib3/util/ssl_.py", line 470, in ssl_wrap_socket
    ssl_sock = _ssl_wrap_socket_impl(sock, context, tls_in_tls, server_hostname)
               ^^^^^^^^^^^^^^^^^^^^^^^^^^^^^^^^^^^^^^^^^^^^^^^^^^^^^^^^^^^^^^^^^
  File "/home/trevea/miniconda3/envs/nlp-rag/lib/python3.12/site-packages/urllib3/util/ssl_.py", line 514, in _ssl_wrap_socket_impl
    return ssl_context.wrap_socket(sock, server_hostname=server_hostname)
           ^^^^^^^^^^^^^^^^^^^^^^^^^^^^^^^^^^^^^^^^^^^^^^^^^^^^^^^^^^^^^^
  File "/home/trevea/miniconda3/envs/nlp-rag/lib/python3.12/ssl.py", line 455, in wrap_socket
    return self.sslsocket_class._create(
           ^^^^^^^^^^^^^^^^^^^^^^^^^^^^^
  File "/home/trevea/miniconda3/envs/nlp-rag/lib/python3.12/ssl.py", line 1046, in _create
    self.do_handshake()
  File "/home/trevea/miniconda3/envs/nlp-rag/lib/python3.12/ssl.py", line 1321, in do_handshake
    self._sslobj.do_handshake()
ConnectionResetError: [Errno 104] Connection reset by peer

During handling of the above exception, another exception occurred:

Traceback (most recent call last):
  File "/home/trevea/miniconda3/envs/nlp-rag/lib/python3.12/site-packages/requests/adapters.py", line 486, in send
    resp = conn.urlopen(
           ^^^^^^^^^^^^^
  File "/home/trevea/miniconda3/envs/nlp-rag/lib/python3.12/site-packages/urllib3/connectionpool.py", line 844, in urlopen
    retries = retries.increment(
              ^^^^^^^^^^^^^^^^^^
  File "/home/trevea/miniconda3/envs/nlp-rag/lib/python3.12/site-packages/urllib3/util/retry.py", line 470, in increment
    raise reraise(type(error), error, _stacktrace)
          ^^^^^^^^^^^^^^^^^^^^^^^^^^^^^^^^^^^^^^^^
  File "/home/trevea/miniconda3/envs/nlp-rag/lib/python3.12/site-packages/urllib3/util/util.py", line 38, in reraise
    raise value.with_traceback(tb)
  File "/home/trevea/miniconda3/envs/nlp-rag/lib/python3.12/site-packages/urllib3/connectionpool.py", line 790, in urlopen
    response = self._make_request(
               ^^^^^^^^^^^^^^^^^^^
  File "/home/trevea/miniconda3/envs/nlp-rag/lib/python3.12/site-packages/urllib3/connectionpool.py", line 491, in _make_request
    raise new_e
  File "/home/trevea/miniconda3/envs/nlp-rag/lib/python3.12/site-packages/urllib3/connectionpool.py", line 467, in _make_request
    self._validate_conn(conn)
  File "/home/trevea/miniconda3/envs/nlp-rag/lib/python3.12/site-packages/urllib3/connectionpool.py", line 1096, in _validate_conn
    conn.connect()
  File "/home/trevea/miniconda3/envs/nlp-rag/lib/python3.12/site-packages/urllib3/connection.py", line 642, in connect
    sock_and_verified = _ssl_wrap_socket_and_match_hostname(
                        ^^^^^^^^^^^^^^^^^^^^^^^^^^^^^^^^^^^^
  File "/home/trevea/miniconda3/envs/nlp-rag/lib/python3.12/site-packages/urllib3/connection.py", line 782, in _ssl_wrap_socket_and_match_hostname
    ssl_sock = ssl_wrap_socket(
               ^^^^^^^^^^^^^^^^
  File "/home/trevea/miniconda3/envs/nlp-rag/lib/python3.12/site-packages/urllib3/util/ssl_.py", line 470, in ssl_wrap_socket
    ssl_sock = _ssl_wrap_socket_impl(sock, context, tls_in_tls, server_hostname)
               ^^^^^^^^^^^^^^^^^^^^^^^^^^^^^^^^^^^^^^^^^^^^^^^^^^^^^^^^^^^^^^^^^
  File "/home/trevea/miniconda3/envs/nlp-rag/lib/python3.12/site-packages/urllib3/util/ssl_.py", line 514, in _ssl_wrap_socket_impl
    return ssl_context.wrap_socket(sock, server_hostname=server_hostname)
           ^^^^^^^^^^^^^^^^^^^^^^^^^^^^^^^^^^^^^^^^^^^^^^^^^^^^^^^^^^^^^^
  File "/home/trevea/miniconda3/envs/nlp-rag/lib/python3.12/ssl.py", line 455, in wrap_socket
    return self.sslsocket_class._create(
           ^^^^^^^^^^^^^^^^^^^^^^^^^^^^^
  File "/home/trevea/miniconda3/envs/nlp-rag/lib/python3.12/ssl.py", line 1046, in _create
    self.do_handshake()
  File "/home/trevea/miniconda3/envs/nlp-rag/lib/python3.12/ssl.py", line 1321, in do_handshake
    self._sslobj.do_handshake()
urllib3.exceptions.ProtocolError: ('Connection aborted.', ConnectionResetError(104, 'Connection reset by peer'))

During handling of the above exception, another exception occurred:

Traceback (most recent call last):
  File "/home/trevea/Projects/ToolsForTheJobBenchmark/generation/Content/4chan/api_test.py", line 11, in test_get_threads
    response = get_threads('po')
               ^^^^^^^^^^^^^^^^^
  File "/home/trevea/Projects/ToolsForTheJobBenchmark/generation/Content/4chan/api.py", line 23, in get_threads
    response = requests.get(url)
               ^^^^^^^^^^^^^^^^^
  File "/home/trevea/miniconda3/envs/nlp-rag/lib/python3.12/site-packages/requests/api.py", line 73, in get
    return request("get", url, params=params, **kwargs)
           ^^^^^^^^^^^^^^^^^^^^^^^^^^^^^^^^^^^^^^^^^^^^
  File "/home/trevea/miniconda3/envs/nlp-rag/lib/python3.12/site-packages/requests/api.py", line 59, in request
    return session.request(method=method, url=url, **kwargs)
           ^^^^^^^^^^^^^^^^^^^^^^^^^^^^^^^^^^^^^^^^^^^^^^^^^
  File "/home/trevea/miniconda3/envs/nlp-rag/lib/python3.12/site-packages/requests/sessions.py", line 589, in request
    resp = self.send(prep, **send_kwargs)
           ^^^^^^^^^^^^^^^^^^^^^^^^^^^^^^
  File "/home/trevea/miniconda3/envs/nlp-rag/lib/python3.12/site-packages/requests/sessions.py", line 703, in send
    r = adapter.send(request, **kwargs)
        ^^^^^^^^^^^^^^^^^^^^^^^^^^^^^^^
  File "/home/trevea/miniconda3/envs/nlp-rag/lib/python3.12/site-packages/requests/adapters.py", line 501, in send
    raise ConnectionError(err, request=request)
requests.exceptions.ConnectionError: ('Connection aborted.', ConnectionResetError(104, 'Connection reset by peer'))

----------------------------------------------------------------------
Ran 6 tests in 0.432s

FAILED (errors=6)
Tests completed for API '4chan'

==================================================

Running tests for API 'iceandfire'...
EEEEEE
======================================================================
ERROR: test_get_book (__main__.TestIceAndFireAPI.test_get_book)
----------------------------------------------------------------------
Traceback (most recent call last):
  File "/home/trevea/miniconda3/envs/nlp-rag/lib/python3.12/site-packages/urllib3/connectionpool.py", line 790, in urlopen
    response = self._make_request(
               ^^^^^^^^^^^^^^^^^^^
  File "/home/trevea/miniconda3/envs/nlp-rag/lib/python3.12/site-packages/urllib3/connectionpool.py", line 491, in _make_request
    raise new_e
  File "/home/trevea/miniconda3/envs/nlp-rag/lib/python3.12/site-packages/urllib3/connectionpool.py", line 467, in _make_request
    self._validate_conn(conn)
  File "/home/trevea/miniconda3/envs/nlp-rag/lib/python3.12/site-packages/urllib3/connectionpool.py", line 1096, in _validate_conn
    conn.connect()
  File "/home/trevea/miniconda3/envs/nlp-rag/lib/python3.12/site-packages/urllib3/connection.py", line 642, in connect
    sock_and_verified = _ssl_wrap_socket_and_match_hostname(
                        ^^^^^^^^^^^^^^^^^^^^^^^^^^^^^^^^^^^^
  File "/home/trevea/miniconda3/envs/nlp-rag/lib/python3.12/site-packages/urllib3/connection.py", line 782, in _ssl_wrap_socket_and_match_hostname
    ssl_sock = ssl_wrap_socket(
               ^^^^^^^^^^^^^^^^
  File "/home/trevea/miniconda3/envs/nlp-rag/lib/python3.12/site-packages/urllib3/util/ssl_.py", line 470, in ssl_wrap_socket
    ssl_sock = _ssl_wrap_socket_impl(sock, context, tls_in_tls, server_hostname)
               ^^^^^^^^^^^^^^^^^^^^^^^^^^^^^^^^^^^^^^^^^^^^^^^^^^^^^^^^^^^^^^^^^
  File "/home/trevea/miniconda3/envs/nlp-rag/lib/python3.12/site-packages/urllib3/util/ssl_.py", line 514, in _ssl_wrap_socket_impl
    return ssl_context.wrap_socket(sock, server_hostname=server_hostname)
           ^^^^^^^^^^^^^^^^^^^^^^^^^^^^^^^^^^^^^^^^^^^^^^^^^^^^^^^^^^^^^^
  File "/home/trevea/miniconda3/envs/nlp-rag/lib/python3.12/ssl.py", line 455, in wrap_socket
    return self.sslsocket_class._create(
           ^^^^^^^^^^^^^^^^^^^^^^^^^^^^^
  File "/home/trevea/miniconda3/envs/nlp-rag/lib/python3.12/ssl.py", line 1046, in _create
    self.do_handshake()
  File "/home/trevea/miniconda3/envs/nlp-rag/lib/python3.12/ssl.py", line 1321, in do_handshake
    self._sslobj.do_handshake()
ConnectionResetError: [Errno 104] Connection reset by peer

During handling of the above exception, another exception occurred:

Traceback (most recent call last):
  File "/home/trevea/miniconda3/envs/nlp-rag/lib/python3.12/site-packages/requests/adapters.py", line 486, in send
    resp = conn.urlopen(
           ^^^^^^^^^^^^^
  File "/home/trevea/miniconda3/envs/nlp-rag/lib/python3.12/site-packages/urllib3/connectionpool.py", line 844, in urlopen
    retries = retries.increment(
              ^^^^^^^^^^^^^^^^^^
  File "/home/trevea/miniconda3/envs/nlp-rag/lib/python3.12/site-packages/urllib3/util/retry.py", line 470, in increment
    raise reraise(type(error), error, _stacktrace)
          ^^^^^^^^^^^^^^^^^^^^^^^^^^^^^^^^^^^^^^^^
  File "/home/trevea/miniconda3/envs/nlp-rag/lib/python3.12/site-packages/urllib3/util/util.py", line 38, in reraise
    raise value.with_traceback(tb)
  File "/home/trevea/miniconda3/envs/nlp-rag/lib/python3.12/site-packages/urllib3/connectionpool.py", line 790, in urlopen
    response = self._make_request(
               ^^^^^^^^^^^^^^^^^^^
  File "/home/trevea/miniconda3/envs/nlp-rag/lib/python3.12/site-packages/urllib3/connectionpool.py", line 491, in _make_request
    raise new_e
  File "/home/trevea/miniconda3/envs/nlp-rag/lib/python3.12/site-packages/urllib3/connectionpool.py", line 467, in _make_request
    self._validate_conn(conn)
  File "/home/trevea/miniconda3/envs/nlp-rag/lib/python3.12/site-packages/urllib3/connectionpool.py", line 1096, in _validate_conn
    conn.connect()
  File "/home/trevea/miniconda3/envs/nlp-rag/lib/python3.12/site-packages/urllib3/connection.py", line 642, in connect
    sock_and_verified = _ssl_wrap_socket_and_match_hostname(
                        ^^^^^^^^^^^^^^^^^^^^^^^^^^^^^^^^^^^^
  File "/home/trevea/miniconda3/envs/nlp-rag/lib/python3.12/site-packages/urllib3/connection.py", line 782, in _ssl_wrap_socket_and_match_hostname
    ssl_sock = ssl_wrap_socket(
               ^^^^^^^^^^^^^^^^
  File "/home/trevea/miniconda3/envs/nlp-rag/lib/python3.12/site-packages/urllib3/util/ssl_.py", line 470, in ssl_wrap_socket
    ssl_sock = _ssl_wrap_socket_impl(sock, context, tls_in_tls, server_hostname)
               ^^^^^^^^^^^^^^^^^^^^^^^^^^^^^^^^^^^^^^^^^^^^^^^^^^^^^^^^^^^^^^^^^
  File "/home/trevea/miniconda3/envs/nlp-rag/lib/python3.12/site-packages/urllib3/util/ssl_.py", line 514, in _ssl_wrap_socket_impl
    return ssl_context.wrap_socket(sock, server_hostname=server_hostname)
           ^^^^^^^^^^^^^^^^^^^^^^^^^^^^^^^^^^^^^^^^^^^^^^^^^^^^^^^^^^^^^^
  File "/home/trevea/miniconda3/envs/nlp-rag/lib/python3.12/ssl.py", line 455, in wrap_socket
    return self.sslsocket_class._create(
           ^^^^^^^^^^^^^^^^^^^^^^^^^^^^^
  File "/home/trevea/miniconda3/envs/nlp-rag/lib/python3.12/ssl.py", line 1046, in _create
    self.do_handshake()
  File "/home/trevea/miniconda3/envs/nlp-rag/lib/python3.12/ssl.py", line 1321, in do_handshake
    self._sslobj.do_handshake()
urllib3.exceptions.ProtocolError: ('Connection aborted.', ConnectionResetError(104, 'Connection reset by peer'))

During handling of the above exception, another exception occurred:

Traceback (most recent call last):
  File "/home/trevea/Projects/ToolsForTheJobBenchmark/generation/Content/iceandfire/api_test.py", line 13, in test_get_book
    response = get_book(1)
               ^^^^^^^^^^^
  File "/home/trevea/Projects/ToolsForTheJobBenchmark/generation/Content/iceandfire/api.py", line 29, in get_book
    response = requests.get(url)
               ^^^^^^^^^^^^^^^^^
  File "/home/trevea/miniconda3/envs/nlp-rag/lib/python3.12/site-packages/requests/api.py", line 73, in get
    return request("get", url, params=params, **kwargs)
           ^^^^^^^^^^^^^^^^^^^^^^^^^^^^^^^^^^^^^^^^^^^^
  File "/home/trevea/miniconda3/envs/nlp-rag/lib/python3.12/site-packages/requests/api.py", line 59, in request
    return session.request(method=method, url=url, **kwargs)
           ^^^^^^^^^^^^^^^^^^^^^^^^^^^^^^^^^^^^^^^^^^^^^^^^^
  File "/home/trevea/miniconda3/envs/nlp-rag/lib/python3.12/site-packages/requests/sessions.py", line 589, in request
    resp = self.send(prep, **send_kwargs)
           ^^^^^^^^^^^^^^^^^^^^^^^^^^^^^^
  File "/home/trevea/miniconda3/envs/nlp-rag/lib/python3.12/site-packages/requests/sessions.py", line 703, in send
    r = adapter.send(request, **kwargs)
        ^^^^^^^^^^^^^^^^^^^^^^^^^^^^^^^
  File "/home/trevea/miniconda3/envs/nlp-rag/lib/python3.12/site-packages/requests/adapters.py", line 501, in send
    raise ConnectionError(err, request=request)
requests.exceptions.ConnectionError: ('Connection aborted.', ConnectionResetError(104, 'Connection reset by peer'))

======================================================================
ERROR: test_get_books (__main__.TestIceAndFireAPI.test_get_books)
----------------------------------------------------------------------
Traceback (most recent call last):
  File "/home/trevea/miniconda3/envs/nlp-rag/lib/python3.12/site-packages/urllib3/connectionpool.py", line 790, in urlopen
    response = self._make_request(
               ^^^^^^^^^^^^^^^^^^^
  File "/home/trevea/miniconda3/envs/nlp-rag/lib/python3.12/site-packages/urllib3/connectionpool.py", line 491, in _make_request
    raise new_e
  File "/home/trevea/miniconda3/envs/nlp-rag/lib/python3.12/site-packages/urllib3/connectionpool.py", line 467, in _make_request
    self._validate_conn(conn)
  File "/home/trevea/miniconda3/envs/nlp-rag/lib/python3.12/site-packages/urllib3/connectionpool.py", line 1096, in _validate_conn
    conn.connect()
  File "/home/trevea/miniconda3/envs/nlp-rag/lib/python3.12/site-packages/urllib3/connection.py", line 642, in connect
    sock_and_verified = _ssl_wrap_socket_and_match_hostname(
                        ^^^^^^^^^^^^^^^^^^^^^^^^^^^^^^^^^^^^
  File "/home/trevea/miniconda3/envs/nlp-rag/lib/python3.12/site-packages/urllib3/connection.py", line 782, in _ssl_wrap_socket_and_match_hostname
    ssl_sock = ssl_wrap_socket(
               ^^^^^^^^^^^^^^^^
  File "/home/trevea/miniconda3/envs/nlp-rag/lib/python3.12/site-packages/urllib3/util/ssl_.py", line 470, in ssl_wrap_socket
    ssl_sock = _ssl_wrap_socket_impl(sock, context, tls_in_tls, server_hostname)
               ^^^^^^^^^^^^^^^^^^^^^^^^^^^^^^^^^^^^^^^^^^^^^^^^^^^^^^^^^^^^^^^^^
  File "/home/trevea/miniconda3/envs/nlp-rag/lib/python3.12/site-packages/urllib3/util/ssl_.py", line 514, in _ssl_wrap_socket_impl
    return ssl_context.wrap_socket(sock, server_hostname=server_hostname)
           ^^^^^^^^^^^^^^^^^^^^^^^^^^^^^^^^^^^^^^^^^^^^^^^^^^^^^^^^^^^^^^
  File "/home/trevea/miniconda3/envs/nlp-rag/lib/python3.12/ssl.py", line 455, in wrap_socket
    return self.sslsocket_class._create(
           ^^^^^^^^^^^^^^^^^^^^^^^^^^^^^
  File "/home/trevea/miniconda3/envs/nlp-rag/lib/python3.12/ssl.py", line 1046, in _create
    self.do_handshake()
  File "/home/trevea/miniconda3/envs/nlp-rag/lib/python3.12/ssl.py", line 1321, in do_handshake
    self._sslobj.do_handshake()
ConnectionResetError: [Errno 104] Connection reset by peer

During handling of the above exception, another exception occurred:

Traceback (most recent call last):
  File "/home/trevea/miniconda3/envs/nlp-rag/lib/python3.12/site-packages/requests/adapters.py", line 486, in send
    resp = conn.urlopen(
           ^^^^^^^^^^^^^
  File "/home/trevea/miniconda3/envs/nlp-rag/lib/python3.12/site-packages/urllib3/connectionpool.py", line 844, in urlopen
    retries = retries.increment(
              ^^^^^^^^^^^^^^^^^^
  File "/home/trevea/miniconda3/envs/nlp-rag/lib/python3.12/site-packages/urllib3/util/retry.py", line 470, in increment
    raise reraise(type(error), error, _stacktrace)
          ^^^^^^^^^^^^^^^^^^^^^^^^^^^^^^^^^^^^^^^^
  File "/home/trevea/miniconda3/envs/nlp-rag/lib/python3.12/site-packages/urllib3/util/util.py", line 38, in reraise
    raise value.with_traceback(tb)
  File "/home/trevea/miniconda3/envs/nlp-rag/lib/python3.12/site-packages/urllib3/connectionpool.py", line 790, in urlopen
    response = self._make_request(
               ^^^^^^^^^^^^^^^^^^^
  File "/home/trevea/miniconda3/envs/nlp-rag/lib/python3.12/site-packages/urllib3/connectionpool.py", line 491, in _make_request
    raise new_e
  File "/home/trevea/miniconda3/envs/nlp-rag/lib/python3.12/site-packages/urllib3/connectionpool.py", line 467, in _make_request
    self._validate_conn(conn)
  File "/home/trevea/miniconda3/envs/nlp-rag/lib/python3.12/site-packages/urllib3/connectionpool.py", line 1096, in _validate_conn
    conn.connect()
  File "/home/trevea/miniconda3/envs/nlp-rag/lib/python3.12/site-packages/urllib3/connection.py", line 642, in connect
    sock_and_verified = _ssl_wrap_socket_and_match_hostname(
                        ^^^^^^^^^^^^^^^^^^^^^^^^^^^^^^^^^^^^
  File "/home/trevea/miniconda3/envs/nlp-rag/lib/python3.12/site-packages/urllib3/connection.py", line 782, in _ssl_wrap_socket_and_match_hostname
    ssl_sock = ssl_wrap_socket(
               ^^^^^^^^^^^^^^^^
  File "/home/trevea/miniconda3/envs/nlp-rag/lib/python3.12/site-packages/urllib3/util/ssl_.py", line 470, in ssl_wrap_socket
    ssl_sock = _ssl_wrap_socket_impl(sock, context, tls_in_tls, server_hostname)
               ^^^^^^^^^^^^^^^^^^^^^^^^^^^^^^^^^^^^^^^^^^^^^^^^^^^^^^^^^^^^^^^^^
  File "/home/trevea/miniconda3/envs/nlp-rag/lib/python3.12/site-packages/urllib3/util/ssl_.py", line 514, in _ssl_wrap_socket_impl
    return ssl_context.wrap_socket(sock, server_hostname=server_hostname)
           ^^^^^^^^^^^^^^^^^^^^^^^^^^^^^^^^^^^^^^^^^^^^^^^^^^^^^^^^^^^^^^
  File "/home/trevea/miniconda3/envs/nlp-rag/lib/python3.12/ssl.py", line 455, in wrap_socket
    return self.sslsocket_class._create(
           ^^^^^^^^^^^^^^^^^^^^^^^^^^^^^
  File "/home/trevea/miniconda3/envs/nlp-rag/lib/python3.12/ssl.py", line 1046, in _create
    self.do_handshake()
  File "/home/trevea/miniconda3/envs/nlp-rag/lib/python3.12/ssl.py", line 1321, in do_handshake
    self._sslobj.do_handshake()
urllib3.exceptions.ProtocolError: ('Connection aborted.', ConnectionResetError(104, 'Connection reset by peer'))

During handling of the above exception, another exception occurred:

Traceback (most recent call last):
  File "/home/trevea/Projects/ToolsForTheJobBenchmark/generation/Content/iceandfire/api_test.py", line 8, in test_get_books
    response = get_books(page=1, page_size=2)
               ^^^^^^^^^^^^^^^^^^^^^^^^^^^^^^
  File "/home/trevea/Projects/ToolsForTheJobBenchmark/generation/Content/iceandfire/api.py", line 17, in get_books
    response = requests.get(url, params={k: v for k, v in params.items() if v is not None})
               ^^^^^^^^^^^^^^^^^^^^^^^^^^^^^^^^^^^^^^^^^^^^^^^^^^^^^^^^^^^^^^^^^^^^^^^^^^^^
  File "/home/trevea/miniconda3/envs/nlp-rag/lib/python3.12/site-packages/requests/api.py", line 73, in get
    return request("get", url, params=params, **kwargs)
           ^^^^^^^^^^^^^^^^^^^^^^^^^^^^^^^^^^^^^^^^^^^^
  File "/home/trevea/miniconda3/envs/nlp-rag/lib/python3.12/site-packages/requests/api.py", line 59, in request
    return session.request(method=method, url=url, **kwargs)
           ^^^^^^^^^^^^^^^^^^^^^^^^^^^^^^^^^^^^^^^^^^^^^^^^^
  File "/home/trevea/miniconda3/envs/nlp-rag/lib/python3.12/site-packages/requests/sessions.py", line 589, in request
    resp = self.send(prep, **send_kwargs)
           ^^^^^^^^^^^^^^^^^^^^^^^^^^^^^^
  File "/home/trevea/miniconda3/envs/nlp-rag/lib/python3.12/site-packages/requests/sessions.py", line 703, in send
    r = adapter.send(request, **kwargs)
        ^^^^^^^^^^^^^^^^^^^^^^^^^^^^^^^
  File "/home/trevea/miniconda3/envs/nlp-rag/lib/python3.12/site-packages/requests/adapters.py", line 501, in send
    raise ConnectionError(err, request=request)
requests.exceptions.ConnectionError: ('Connection aborted.', ConnectionResetError(104, 'Connection reset by peer'))

======================================================================
ERROR: test_get_character (__main__.TestIceAndFireAPI.test_get_character)
----------------------------------------------------------------------
Traceback (most recent call last):
  File "/home/trevea/miniconda3/envs/nlp-rag/lib/python3.12/site-packages/urllib3/connectionpool.py", line 790, in urlopen
    response = self._make_request(
               ^^^^^^^^^^^^^^^^^^^
  File "/home/trevea/miniconda3/envs/nlp-rag/lib/python3.12/site-packages/urllib3/connectionpool.py", line 491, in _make_request
    raise new_e
  File "/home/trevea/miniconda3/envs/nlp-rag/lib/python3.12/site-packages/urllib3/connectionpool.py", line 467, in _make_request
    self._validate_conn(conn)
  File "/home/trevea/miniconda3/envs/nlp-rag/lib/python3.12/site-packages/urllib3/connectionpool.py", line 1096, in _validate_conn
    conn.connect()
  File "/home/trevea/miniconda3/envs/nlp-rag/lib/python3.12/site-packages/urllib3/connection.py", line 642, in connect
    sock_and_verified = _ssl_wrap_socket_and_match_hostname(
                        ^^^^^^^^^^^^^^^^^^^^^^^^^^^^^^^^^^^^
  File "/home/trevea/miniconda3/envs/nlp-rag/lib/python3.12/site-packages/urllib3/connection.py", line 782, in _ssl_wrap_socket_and_match_hostname
    ssl_sock = ssl_wrap_socket(
               ^^^^^^^^^^^^^^^^
  File "/home/trevea/miniconda3/envs/nlp-rag/lib/python3.12/site-packages/urllib3/util/ssl_.py", line 470, in ssl_wrap_socket
    ssl_sock = _ssl_wrap_socket_impl(sock, context, tls_in_tls, server_hostname)
               ^^^^^^^^^^^^^^^^^^^^^^^^^^^^^^^^^^^^^^^^^^^^^^^^^^^^^^^^^^^^^^^^^
  File "/home/trevea/miniconda3/envs/nlp-rag/lib/python3.12/site-packages/urllib3/util/ssl_.py", line 514, in _ssl_wrap_socket_impl
    return ssl_context.wrap_socket(sock, server_hostname=server_hostname)
           ^^^^^^^^^^^^^^^^^^^^^^^^^^^^^^^^^^^^^^^^^^^^^^^^^^^^^^^^^^^^^^
  File "/home/trevea/miniconda3/envs/nlp-rag/lib/python3.12/ssl.py", line 455, in wrap_socket
    return self.sslsocket_class._create(
           ^^^^^^^^^^^^^^^^^^^^^^^^^^^^^
  File "/home/trevea/miniconda3/envs/nlp-rag/lib/python3.12/ssl.py", line 1046, in _create
    self.do_handshake()
  File "/home/trevea/miniconda3/envs/nlp-rag/lib/python3.12/ssl.py", line 1321, in do_handshake
    self._sslobj.do_handshake()
ConnectionResetError: [Errno 104] Connection reset by peer

During handling of the above exception, another exception occurred:

Traceback (most recent call last):
  File "/home/trevea/miniconda3/envs/nlp-rag/lib/python3.12/site-packages/requests/adapters.py", line 486, in send
    resp = conn.urlopen(
           ^^^^^^^^^^^^^
  File "/home/trevea/miniconda3/envs/nlp-rag/lib/python3.12/site-packages/urllib3/connectionpool.py", line 844, in urlopen
    retries = retries.increment(
              ^^^^^^^^^^^^^^^^^^
  File "/home/trevea/miniconda3/envs/nlp-rag/lib/python3.12/site-packages/urllib3/util/retry.py", line 470, in increment
    raise reraise(type(error), error, _stacktrace)
          ^^^^^^^^^^^^^^^^^^^^^^^^^^^^^^^^^^^^^^^^
  File "/home/trevea/miniconda3/envs/nlp-rag/lib/python3.12/site-packages/urllib3/util/util.py", line 38, in reraise
    raise value.with_traceback(tb)
  File "/home/trevea/miniconda3/envs/nlp-rag/lib/python3.12/site-packages/urllib3/connectionpool.py", line 790, in urlopen
    response = self._make_request(
               ^^^^^^^^^^^^^^^^^^^
  File "/home/trevea/miniconda3/envs/nlp-rag/lib/python3.12/site-packages/urllib3/connectionpool.py", line 491, in _make_request
    raise new_e
  File "/home/trevea/miniconda3/envs/nlp-rag/lib/python3.12/site-packages/urllib3/connectionpool.py", line 467, in _make_request
    self._validate_conn(conn)
  File "/home/trevea/miniconda3/envs/nlp-rag/lib/python3.12/site-packages/urllib3/connectionpool.py", line 1096, in _validate_conn
    conn.connect()
  File "/home/trevea/miniconda3/envs/nlp-rag/lib/python3.12/site-packages/urllib3/connection.py", line 642, in connect
    sock_and_verified = _ssl_wrap_socket_and_match_hostname(
                        ^^^^^^^^^^^^^^^^^^^^^^^^^^^^^^^^^^^^
  File "/home/trevea/miniconda3/envs/nlp-rag/lib/python3.12/site-packages/urllib3/connection.py", line 782, in _ssl_wrap_socket_and_match_hostname
    ssl_sock = ssl_wrap_socket(
               ^^^^^^^^^^^^^^^^
  File "/home/trevea/miniconda3/envs/nlp-rag/lib/python3.12/site-packages/urllib3/util/ssl_.py", line 470, in ssl_wrap_socket
    ssl_sock = _ssl_wrap_socket_impl(sock, context, tls_in_tls, server_hostname)
               ^^^^^^^^^^^^^^^^^^^^^^^^^^^^^^^^^^^^^^^^^^^^^^^^^^^^^^^^^^^^^^^^^
  File "/home/trevea/miniconda3/envs/nlp-rag/lib/python3.12/site-packages/urllib3/util/ssl_.py", line 514, in _ssl_wrap_socket_impl
    return ssl_context.wrap_socket(sock, server_hostname=server_hostname)
           ^^^^^^^^^^^^^^^^^^^^^^^^^^^^^^^^^^^^^^^^^^^^^^^^^^^^^^^^^^^^^^
  File "/home/trevea/miniconda3/envs/nlp-rag/lib/python3.12/ssl.py", line 455, in wrap_socket
    return self.sslsocket_class._create(
           ^^^^^^^^^^^^^^^^^^^^^^^^^^^^^
  File "/home/trevea/miniconda3/envs/nlp-rag/lib/python3.12/ssl.py", line 1046, in _create
    self.do_handshake()
  File "/home/trevea/miniconda3/envs/nlp-rag/lib/python3.12/ssl.py", line 1321, in do_handshake
    self._sslobj.do_handshake()
urllib3.exceptions.ProtocolError: ('Connection aborted.', ConnectionResetError(104, 'Connection reset by peer'))

During handling of the above exception, another exception occurred:

Traceback (most recent call last):
  File "/home/trevea/Projects/ToolsForTheJobBenchmark/generation/Content/iceandfire/api_test.py", line 23, in test_get_character
    response = get_character(583)
               ^^^^^^^^^^^^^^^^^^
  File "/home/trevea/Projects/ToolsForTheJobBenchmark/generation/Content/iceandfire/api.py", line 63, in get_character
    response = requests.get(url)
               ^^^^^^^^^^^^^^^^^
  File "/home/trevea/miniconda3/envs/nlp-rag/lib/python3.12/site-packages/requests/api.py", line 73, in get
    return request("get", url, params=params, **kwargs)
           ^^^^^^^^^^^^^^^^^^^^^^^^^^^^^^^^^^^^^^^^^^^^
  File "/home/trevea/miniconda3/envs/nlp-rag/lib/python3.12/site-packages/requests/api.py", line 59, in request
    return session.request(method=method, url=url, **kwargs)
           ^^^^^^^^^^^^^^^^^^^^^^^^^^^^^^^^^^^^^^^^^^^^^^^^^
  File "/home/trevea/miniconda3/envs/nlp-rag/lib/python3.12/site-packages/requests/sessions.py", line 589, in request
    resp = self.send(prep, **send_kwargs)
           ^^^^^^^^^^^^^^^^^^^^^^^^^^^^^^
  File "/home/trevea/miniconda3/envs/nlp-rag/lib/python3.12/site-packages/requests/sessions.py", line 703, in send
    r = adapter.send(request, **kwargs)
        ^^^^^^^^^^^^^^^^^^^^^^^^^^^^^^^
  File "/home/trevea/miniconda3/envs/nlp-rag/lib/python3.12/site-packages/requests/adapters.py", line 501, in send
    raise ConnectionError(err, request=request)
requests.exceptions.ConnectionError: ('Connection aborted.', ConnectionResetError(104, 'Connection reset by peer'))

======================================================================
ERROR: test_get_characters (__main__.TestIceAndFireAPI.test_get_characters)
----------------------------------------------------------------------
Traceback (most recent call last):
  File "/home/trevea/miniconda3/envs/nlp-rag/lib/python3.12/site-packages/urllib3/connectionpool.py", line 790, in urlopen
    response = self._make_request(
               ^^^^^^^^^^^^^^^^^^^
  File "/home/trevea/miniconda3/envs/nlp-rag/lib/python3.12/site-packages/urllib3/connectionpool.py", line 491, in _make_request
    raise new_e
  File "/home/trevea/miniconda3/envs/nlp-rag/lib/python3.12/site-packages/urllib3/connectionpool.py", line 467, in _make_request
    self._validate_conn(conn)
  File "/home/trevea/miniconda3/envs/nlp-rag/lib/python3.12/site-packages/urllib3/connectionpool.py", line 1096, in _validate_conn
    conn.connect()
  File "/home/trevea/miniconda3/envs/nlp-rag/lib/python3.12/site-packages/urllib3/connection.py", line 642, in connect
    sock_and_verified = _ssl_wrap_socket_and_match_hostname(
                        ^^^^^^^^^^^^^^^^^^^^^^^^^^^^^^^^^^^^
  File "/home/trevea/miniconda3/envs/nlp-rag/lib/python3.12/site-packages/urllib3/connection.py", line 782, in _ssl_wrap_socket_and_match_hostname
    ssl_sock = ssl_wrap_socket(
               ^^^^^^^^^^^^^^^^
  File "/home/trevea/miniconda3/envs/nlp-rag/lib/python3.12/site-packages/urllib3/util/ssl_.py", line 470, in ssl_wrap_socket
    ssl_sock = _ssl_wrap_socket_impl(sock, context, tls_in_tls, server_hostname)
               ^^^^^^^^^^^^^^^^^^^^^^^^^^^^^^^^^^^^^^^^^^^^^^^^^^^^^^^^^^^^^^^^^
  File "/home/trevea/miniconda3/envs/nlp-rag/lib/python3.12/site-packages/urllib3/util/ssl_.py", line 514, in _ssl_wrap_socket_impl
    return ssl_context.wrap_socket(sock, server_hostname=server_hostname)
           ^^^^^^^^^^^^^^^^^^^^^^^^^^^^^^^^^^^^^^^^^^^^^^^^^^^^^^^^^^^^^^
  File "/home/trevea/miniconda3/envs/nlp-rag/lib/python3.12/ssl.py", line 455, in wrap_socket
    return self.sslsocket_class._create(
           ^^^^^^^^^^^^^^^^^^^^^^^^^^^^^
  File "/home/trevea/miniconda3/envs/nlp-rag/lib/python3.12/ssl.py", line 1046, in _create
    self.do_handshake()
  File "/home/trevea/miniconda3/envs/nlp-rag/lib/python3.12/ssl.py", line 1321, in do_handshake
    self._sslobj.do_handshake()
ConnectionResetError: [Errno 104] Connection reset by peer

During handling of the above exception, another exception occurred:

Traceback (most recent call last):
  File "/home/trevea/miniconda3/envs/nlp-rag/lib/python3.12/site-packages/requests/adapters.py", line 486, in send
    resp = conn.urlopen(
           ^^^^^^^^^^^^^
  File "/home/trevea/miniconda3/envs/nlp-rag/lib/python3.12/site-packages/urllib3/connectionpool.py", line 844, in urlopen
    retries = retries.increment(
              ^^^^^^^^^^^^^^^^^^
  File "/home/trevea/miniconda3/envs/nlp-rag/lib/python3.12/site-packages/urllib3/util/retry.py", line 470, in increment
    raise reraise(type(error), error, _stacktrace)
          ^^^^^^^^^^^^^^^^^^^^^^^^^^^^^^^^^^^^^^^^
  File "/home/trevea/miniconda3/envs/nlp-rag/lib/python3.12/site-packages/urllib3/util/util.py", line 38, in reraise
    raise value.with_traceback(tb)
  File "/home/trevea/miniconda3/envs/nlp-rag/lib/python3.12/site-packages/urllib3/connectionpool.py", line 790, in urlopen
    response = self._make_request(
               ^^^^^^^^^^^^^^^^^^^
  File "/home/trevea/miniconda3/envs/nlp-rag/lib/python3.12/site-packages/urllib3/connectionpool.py", line 491, in _make_request
    raise new_e
  File "/home/trevea/miniconda3/envs/nlp-rag/lib/python3.12/site-packages/urllib3/connectionpool.py", line 467, in _make_request
    self._validate_conn(conn)
  File "/home/trevea/miniconda3/envs/nlp-rag/lib/python3.12/site-packages/urllib3/connectionpool.py", line 1096, in _validate_conn
    conn.connect()
  File "/home/trevea/miniconda3/envs/nlp-rag/lib/python3.12/site-packages/urllib3/connection.py", line 642, in connect
    sock_and_verified = _ssl_wrap_socket_and_match_hostname(
                        ^^^^^^^^^^^^^^^^^^^^^^^^^^^^^^^^^^^^
  File "/home/trevea/miniconda3/envs/nlp-rag/lib/python3.12/site-packages/urllib3/connection.py", line 782, in _ssl_wrap_socket_and_match_hostname
    ssl_sock = ssl_wrap_socket(
               ^^^^^^^^^^^^^^^^
  File "/home/trevea/miniconda3/envs/nlp-rag/lib/python3.12/site-packages/urllib3/util/ssl_.py", line 470, in ssl_wrap_socket
    ssl_sock = _ssl_wrap_socket_impl(sock, context, tls_in_tls, server_hostname)
               ^^^^^^^^^^^^^^^^^^^^^^^^^^^^^^^^^^^^^^^^^^^^^^^^^^^^^^^^^^^^^^^^^
  File "/home/trevea/miniconda3/envs/nlp-rag/lib/python3.12/site-packages/urllib3/util/ssl_.py", line 514, in _ssl_wrap_socket_impl
    return ssl_context.wrap_socket(sock, server_hostname=server_hostname)
           ^^^^^^^^^^^^^^^^^^^^^^^^^^^^^^^^^^^^^^^^^^^^^^^^^^^^^^^^^^^^^^
  File "/home/trevea/miniconda3/envs/nlp-rag/lib/python3.12/ssl.py", line 455, in wrap_socket
    return self.sslsocket_class._create(
           ^^^^^^^^^^^^^^^^^^^^^^^^^^^^^
  File "/home/trevea/miniconda3/envs/nlp-rag/lib/python3.12/ssl.py", line 1046, in _create
    self.do_handshake()
  File "/home/trevea/miniconda3/envs/nlp-rag/lib/python3.12/ssl.py", line 1321, in do_handshake
    self._sslobj.do_handshake()
urllib3.exceptions.ProtocolError: ('Connection aborted.', ConnectionResetError(104, 'Connection reset by peer'))

During handling of the above exception, another exception occurred:

Traceback (most recent call last):
  File "/home/trevea/Projects/ToolsForTheJobBenchmark/generation/Content/iceandfire/api_test.py", line 18, in test_get_characters
    response = get_characters(page=1, page_size=2)
               ^^^^^^^^^^^^^^^^^^^^^^^^^^^^^^^^^^^
  File "/home/trevea/Projects/ToolsForTheJobBenchmark/generation/Content/iceandfire/api.py", line 51, in get_characters
    response = requests.get(url, params={k: v for k, v in params.items() if v is not None})
               ^^^^^^^^^^^^^^^^^^^^^^^^^^^^^^^^^^^^^^^^^^^^^^^^^^^^^^^^^^^^^^^^^^^^^^^^^^^^
  File "/home/trevea/miniconda3/envs/nlp-rag/lib/python3.12/site-packages/requests/api.py", line 73, in get
    return request("get", url, params=params, **kwargs)
           ^^^^^^^^^^^^^^^^^^^^^^^^^^^^^^^^^^^^^^^^^^^^
  File "/home/trevea/miniconda3/envs/nlp-rag/lib/python3.12/site-packages/requests/api.py", line 59, in request
    return session.request(method=method, url=url, **kwargs)
           ^^^^^^^^^^^^^^^^^^^^^^^^^^^^^^^^^^^^^^^^^^^^^^^^^
  File "/home/trevea/miniconda3/envs/nlp-rag/lib/python3.12/site-packages/requests/sessions.py", line 589, in request
    resp = self.send(prep, **send_kwargs)
           ^^^^^^^^^^^^^^^^^^^^^^^^^^^^^^
  File "/home/trevea/miniconda3/envs/nlp-rag/lib/python3.12/site-packages/requests/sessions.py", line 703, in send
    r = adapter.send(request, **kwargs)
        ^^^^^^^^^^^^^^^^^^^^^^^^^^^^^^^
  File "/home/trevea/miniconda3/envs/nlp-rag/lib/python3.12/site-packages/requests/adapters.py", line 501, in send
    raise ConnectionError(err, request=request)
requests.exceptions.ConnectionError: ('Connection aborted.', ConnectionResetError(104, 'Connection reset by peer'))

======================================================================
ERROR: test_get_house (__main__.TestIceAndFireAPI.test_get_house)
----------------------------------------------------------------------
Traceback (most recent call last):
  File "/home/trevea/miniconda3/envs/nlp-rag/lib/python3.12/site-packages/urllib3/connectionpool.py", line 790, in urlopen
    response = self._make_request(
               ^^^^^^^^^^^^^^^^^^^
  File "/home/trevea/miniconda3/envs/nlp-rag/lib/python3.12/site-packages/urllib3/connectionpool.py", line 491, in _make_request
    raise new_e
  File "/home/trevea/miniconda3/envs/nlp-rag/lib/python3.12/site-packages/urllib3/connectionpool.py", line 467, in _make_request
    self._validate_conn(conn)
  File "/home/trevea/miniconda3/envs/nlp-rag/lib/python3.12/site-packages/urllib3/connectionpool.py", line 1096, in _validate_conn
    conn.connect()
  File "/home/trevea/miniconda3/envs/nlp-rag/lib/python3.12/site-packages/urllib3/connection.py", line 642, in connect
    sock_and_verified = _ssl_wrap_socket_and_match_hostname(
                        ^^^^^^^^^^^^^^^^^^^^^^^^^^^^^^^^^^^^
  File "/home/trevea/miniconda3/envs/nlp-rag/lib/python3.12/site-packages/urllib3/connection.py", line 782, in _ssl_wrap_socket_and_match_hostname
    ssl_sock = ssl_wrap_socket(
               ^^^^^^^^^^^^^^^^
  File "/home/trevea/miniconda3/envs/nlp-rag/lib/python3.12/site-packages/urllib3/util/ssl_.py", line 470, in ssl_wrap_socket
    ssl_sock = _ssl_wrap_socket_impl(sock, context, tls_in_tls, server_hostname)
               ^^^^^^^^^^^^^^^^^^^^^^^^^^^^^^^^^^^^^^^^^^^^^^^^^^^^^^^^^^^^^^^^^
  File "/home/trevea/miniconda3/envs/nlp-rag/lib/python3.12/site-packages/urllib3/util/ssl_.py", line 514, in _ssl_wrap_socket_impl
    return ssl_context.wrap_socket(sock, server_hostname=server_hostname)
           ^^^^^^^^^^^^^^^^^^^^^^^^^^^^^^^^^^^^^^^^^^^^^^^^^^^^^^^^^^^^^^
  File "/home/trevea/miniconda3/envs/nlp-rag/lib/python3.12/ssl.py", line 455, in wrap_socket
    return self.sslsocket_class._create(
           ^^^^^^^^^^^^^^^^^^^^^^^^^^^^^
  File "/home/trevea/miniconda3/envs/nlp-rag/lib/python3.12/ssl.py", line 1046, in _create
    self.do_handshake()
  File "/home/trevea/miniconda3/envs/nlp-rag/lib/python3.12/ssl.py", line 1321, in do_handshake
    self._sslobj.do_handshake()
ConnectionResetError: [Errno 104] Connection reset by peer

During handling of the above exception, another exception occurred:

Traceback (most recent call last):
  File "/home/trevea/miniconda3/envs/nlp-rag/lib/python3.12/site-packages/requests/adapters.py", line 486, in send
    resp = conn.urlopen(
           ^^^^^^^^^^^^^
  File "/home/trevea/miniconda3/envs/nlp-rag/lib/python3.12/site-packages/urllib3/connectionpool.py", line 844, in urlopen
    retries = retries.increment(
              ^^^^^^^^^^^^^^^^^^
  File "/home/trevea/miniconda3/envs/nlp-rag/lib/python3.12/site-packages/urllib3/util/retry.py", line 470, in increment
    raise reraise(type(error), error, _stacktrace)
          ^^^^^^^^^^^^^^^^^^^^^^^^^^^^^^^^^^^^^^^^
  File "/home/trevea/miniconda3/envs/nlp-rag/lib/python3.12/site-packages/urllib3/util/util.py", line 38, in reraise
    raise value.with_traceback(tb)
  File "/home/trevea/miniconda3/envs/nlp-rag/lib/python3.12/site-packages/urllib3/connectionpool.py", line 790, in urlopen
    response = self._make_request(
               ^^^^^^^^^^^^^^^^^^^
  File "/home/trevea/miniconda3/envs/nlp-rag/lib/python3.12/site-packages/urllib3/connectionpool.py", line 491, in _make_request
    raise new_e
  File "/home/trevea/miniconda3/envs/nlp-rag/lib/python3.12/site-packages/urllib3/connectionpool.py", line 467, in _make_request
    self._validate_conn(conn)
  File "/home/trevea/miniconda3/envs/nlp-rag/lib/python3.12/site-packages/urllib3/connectionpool.py", line 1096, in _validate_conn
    conn.connect()
  File "/home/trevea/miniconda3/envs/nlp-rag/lib/python3.12/site-packages/urllib3/connection.py", line 642, in connect
    sock_and_verified = _ssl_wrap_socket_and_match_hostname(
                        ^^^^^^^^^^^^^^^^^^^^^^^^^^^^^^^^^^^^
  File "/home/trevea/miniconda3/envs/nlp-rag/lib/python3.12/site-packages/urllib3/connection.py", line 782, in _ssl_wrap_socket_and_match_hostname
    ssl_sock = ssl_wrap_socket(
               ^^^^^^^^^^^^^^^^
  File "/home/trevea/miniconda3/envs/nlp-rag/lib/python3.12/site-packages/urllib3/util/ssl_.py", line 470, in ssl_wrap_socket
    ssl_sock = _ssl_wrap_socket_impl(sock, context, tls_in_tls, server_hostname)
               ^^^^^^^^^^^^^^^^^^^^^^^^^^^^^^^^^^^^^^^^^^^^^^^^^^^^^^^^^^^^^^^^^
  File "/home/trevea/miniconda3/envs/nlp-rag/lib/python3.12/site-packages/urllib3/util/ssl_.py", line 514, in _ssl_wrap_socket_impl
    return ssl_context.wrap_socket(sock, server_hostname=server_hostname)
           ^^^^^^^^^^^^^^^^^^^^^^^^^^^^^^^^^^^^^^^^^^^^^^^^^^^^^^^^^^^^^^
  File "/home/trevea/miniconda3/envs/nlp-rag/lib/python3.12/ssl.py", line 455, in wrap_socket
    return self.sslsocket_class._create(
           ^^^^^^^^^^^^^^^^^^^^^^^^^^^^^
  File "/home/trevea/miniconda3/envs/nlp-rag/lib/python3.12/ssl.py", line 1046, in _create
    self.do_handshake()
  File "/home/trevea/miniconda3/envs/nlp-rag/lib/python3.12/ssl.py", line 1321, in do_handshake
    self._sslobj.do_handshake()
urllib3.exceptions.ProtocolError: ('Connection aborted.', ConnectionResetError(104, 'Connection reset by peer'))

During handling of the above exception, another exception occurred:

Traceback (most recent call last):
  File "/home/trevea/Projects/ToolsForTheJobBenchmark/generation/Content/iceandfire/api_test.py", line 33, in test_get_house
    response = get_house(10)
               ^^^^^^^^^^^^^
  File "/home/trevea/Projects/ToolsForTheJobBenchmark/generation/Content/iceandfire/api.py", line 99, in get_house
    response = requests.get(url)
               ^^^^^^^^^^^^^^^^^
  File "/home/trevea/miniconda3/envs/nlp-rag/lib/python3.12/site-packages/requests/api.py", line 73, in get
    return request("get", url, params=params, **kwargs)
           ^^^^^^^^^^^^^^^^^^^^^^^^^^^^^^^^^^^^^^^^^^^^
  File "/home/trevea/miniconda3/envs/nlp-rag/lib/python3.12/site-packages/requests/api.py", line 59, in request
    return session.request(method=method, url=url, **kwargs)
           ^^^^^^^^^^^^^^^^^^^^^^^^^^^^^^^^^^^^^^^^^^^^^^^^^
  File "/home/trevea/miniconda3/envs/nlp-rag/lib/python3.12/site-packages/requests/sessions.py", line 589, in request
    resp = self.send(prep, **send_kwargs)
           ^^^^^^^^^^^^^^^^^^^^^^^^^^^^^^
  File "/home/trevea/miniconda3/envs/nlp-rag/lib/python3.12/site-packages/requests/sessions.py", line 703, in send
    r = adapter.send(request, **kwargs)
        ^^^^^^^^^^^^^^^^^^^^^^^^^^^^^^^
  File "/home/trevea/miniconda3/envs/nlp-rag/lib/python3.12/site-packages/requests/adapters.py", line 501, in send
    raise ConnectionError(err, request=request)
requests.exceptions.ConnectionError: ('Connection aborted.', ConnectionResetError(104, 'Connection reset by peer'))

======================================================================
ERROR: test_get_houses (__main__.TestIceAndFireAPI.test_get_houses)
----------------------------------------------------------------------
Traceback (most recent call last):
  File "/home/trevea/miniconda3/envs/nlp-rag/lib/python3.12/site-packages/urllib3/connectionpool.py", line 790, in urlopen
    response = self._make_request(
               ^^^^^^^^^^^^^^^^^^^
  File "/home/trevea/miniconda3/envs/nlp-rag/lib/python3.12/site-packages/urllib3/connectionpool.py", line 491, in _make_request
    raise new_e
  File "/home/trevea/miniconda3/envs/nlp-rag/lib/python3.12/site-packages/urllib3/connectionpool.py", line 467, in _make_request
    self._validate_conn(conn)
  File "/home/trevea/miniconda3/envs/nlp-rag/lib/python3.12/site-packages/urllib3/connectionpool.py", line 1096, in _validate_conn
    conn.connect()
  File "/home/trevea/miniconda3/envs/nlp-rag/lib/python3.12/site-packages/urllib3/connection.py", line 642, in connect
    sock_and_verified = _ssl_wrap_socket_and_match_hostname(
                        ^^^^^^^^^^^^^^^^^^^^^^^^^^^^^^^^^^^^
  File "/home/trevea/miniconda3/envs/nlp-rag/lib/python3.12/site-packages/urllib3/connection.py", line 782, in _ssl_wrap_socket_and_match_hostname
    ssl_sock = ssl_wrap_socket(
               ^^^^^^^^^^^^^^^^
  File "/home/trevea/miniconda3/envs/nlp-rag/lib/python3.12/site-packages/urllib3/util/ssl_.py", line 470, in ssl_wrap_socket
    ssl_sock = _ssl_wrap_socket_impl(sock, context, tls_in_tls, server_hostname)
               ^^^^^^^^^^^^^^^^^^^^^^^^^^^^^^^^^^^^^^^^^^^^^^^^^^^^^^^^^^^^^^^^^
  File "/home/trevea/miniconda3/envs/nlp-rag/lib/python3.12/site-packages/urllib3/util/ssl_.py", line 514, in _ssl_wrap_socket_impl
    return ssl_context.wrap_socket(sock, server_hostname=server_hostname)
           ^^^^^^^^^^^^^^^^^^^^^^^^^^^^^^^^^^^^^^^^^^^^^^^^^^^^^^^^^^^^^^
  File "/home/trevea/miniconda3/envs/nlp-rag/lib/python3.12/ssl.py", line 455, in wrap_socket
    return self.sslsocket_class._create(
           ^^^^^^^^^^^^^^^^^^^^^^^^^^^^^
  File "/home/trevea/miniconda3/envs/nlp-rag/lib/python3.12/ssl.py", line 1046, in _create
    self.do_handshake()
  File "/home/trevea/miniconda3/envs/nlp-rag/lib/python3.12/ssl.py", line 1321, in do_handshake
    self._sslobj.do_handshake()
ConnectionResetError: [Errno 104] Connection reset by peer

During handling of the above exception, another exception occurred:

Traceback (most recent call last):
  File "/home/trevea/miniconda3/envs/nlp-rag/lib/python3.12/site-packages/requests/adapters.py", line 486, in send
    resp = conn.urlopen(
           ^^^^^^^^^^^^^
  File "/home/trevea/miniconda3/envs/nlp-rag/lib/python3.12/site-packages/urllib3/connectionpool.py", line 844, in urlopen
    retries = retries.increment(
              ^^^^^^^^^^^^^^^^^^
  File "/home/trevea/miniconda3/envs/nlp-rag/lib/python3.12/site-packages/urllib3/util/retry.py", line 470, in increment
    raise reraise(type(error), error, _stacktrace)
          ^^^^^^^^^^^^^^^^^^^^^^^^^^^^^^^^^^^^^^^^
  File "/home/trevea/miniconda3/envs/nlp-rag/lib/python3.12/site-packages/urllib3/util/util.py", line 38, in reraise
    raise value.with_traceback(tb)
  File "/home/trevea/miniconda3/envs/nlp-rag/lib/python3.12/site-packages/urllib3/connectionpool.py", line 790, in urlopen
    response = self._make_request(
               ^^^^^^^^^^^^^^^^^^^
  File "/home/trevea/miniconda3/envs/nlp-rag/lib/python3.12/site-packages/urllib3/connectionpool.py", line 491, in _make_request
    raise new_e
  File "/home/trevea/miniconda3/envs/nlp-rag/lib/python3.12/site-packages/urllib3/connectionpool.py", line 467, in _make_request
    self._validate_conn(conn)
  File "/home/trevea/miniconda3/envs/nlp-rag/lib/python3.12/site-packages/urllib3/connectionpool.py", line 1096, in _validate_conn
    conn.connect()
  File "/home/trevea/miniconda3/envs/nlp-rag/lib/python3.12/site-packages/urllib3/connection.py", line 642, in connect
    sock_and_verified = _ssl_wrap_socket_and_match_hostname(
                        ^^^^^^^^^^^^^^^^^^^^^^^^^^^^^^^^^^^^
  File "/home/trevea/miniconda3/envs/nlp-rag/lib/python3.12/site-packages/urllib3/connection.py", line 782, in _ssl_wrap_socket_and_match_hostname
    ssl_sock = ssl_wrap_socket(
               ^^^^^^^^^^^^^^^^
  File "/home/trevea/miniconda3/envs/nlp-rag/lib/python3.12/site-packages/urllib3/util/ssl_.py", line 470, in ssl_wrap_socket
    ssl_sock = _ssl_wrap_socket_impl(sock, context, tls_in_tls, server_hostname)
               ^^^^^^^^^^^^^^^^^^^^^^^^^^^^^^^^^^^^^^^^^^^^^^^^^^^^^^^^^^^^^^^^^
  File "/home/trevea/miniconda3/envs/nlp-rag/lib/python3.12/site-packages/urllib3/util/ssl_.py", line 514, in _ssl_wrap_socket_impl
    return ssl_context.wrap_socket(sock, server_hostname=server_hostname)
           ^^^^^^^^^^^^^^^^^^^^^^^^^^^^^^^^^^^^^^^^^^^^^^^^^^^^^^^^^^^^^^
  File "/home/trevea/miniconda3/envs/nlp-rag/lib/python3.12/ssl.py", line 455, in wrap_socket
    return self.sslsocket_class._create(
           ^^^^^^^^^^^^^^^^^^^^^^^^^^^^^
  File "/home/trevea/miniconda3/envs/nlp-rag/lib/python3.12/ssl.py", line 1046, in _create
    self.do_handshake()
  File "/home/trevea/miniconda3/envs/nlp-rag/lib/python3.12/ssl.py", line 1321, in do_handshake
    self._sslobj.do_handshake()
urllib3.exceptions.ProtocolError: ('Connection aborted.', ConnectionResetError(104, 'Connection reset by peer'))

During handling of the above exception, another exception occurred:

Traceback (most recent call last):
  File "/home/trevea/Projects/ToolsForTheJobBenchmark/generation/Content/iceandfire/api_test.py", line 28, in test_get_houses
    response = get_houses(page=1, page_size=2)
               ^^^^^^^^^^^^^^^^^^^^^^^^^^^^^^^
  File "/home/trevea/Projects/ToolsForTheJobBenchmark/generation/Content/iceandfire/api.py", line 87, in get_houses
    response = requests.get(url, params={k: v for k, v in params.items() if v is not None})
               ^^^^^^^^^^^^^^^^^^^^^^^^^^^^^^^^^^^^^^^^^^^^^^^^^^^^^^^^^^^^^^^^^^^^^^^^^^^^
  File "/home/trevea/miniconda3/envs/nlp-rag/lib/python3.12/site-packages/requests/api.py", line 73, in get
    return request("get", url, params=params, **kwargs)
           ^^^^^^^^^^^^^^^^^^^^^^^^^^^^^^^^^^^^^^^^^^^^
  File "/home/trevea/miniconda3/envs/nlp-rag/lib/python3.12/site-packages/requests/api.py", line 59, in request
    return session.request(method=method, url=url, **kwargs)
           ^^^^^^^^^^^^^^^^^^^^^^^^^^^^^^^^^^^^^^^^^^^^^^^^^
  File "/home/trevea/miniconda3/envs/nlp-rag/lib/python3.12/site-packages/requests/sessions.py", line 589, in request
    resp = self.send(prep, **send_kwargs)
           ^^^^^^^^^^^^^^^^^^^^^^^^^^^^^^
  File "/home/trevea/miniconda3/envs/nlp-rag/lib/python3.12/site-packages/requests/sessions.py", line 703, in send
    r = adapter.send(request, **kwargs)
        ^^^^^^^^^^^^^^^^^^^^^^^^^^^^^^^
  File "/home/trevea/miniconda3/envs/nlp-rag/lib/python3.12/site-packages/requests/adapters.py", line 501, in send
    raise ConnectionError(err, request=request)
requests.exceptions.ConnectionError: ('Connection aborted.', ConnectionResetError(104, 'Connection reset by peer'))

----------------------------------------------------------------------
Ran 6 tests in 1.106s

FAILED (errors=6)
Tests completed for API 'iceandfire'

==================================================

Running tests for API 'openlibrary'...
.......
----------------------------------------------------------------------
Ran 7 tests in 2.375s

OK
Tests completed for API 'openlibrary'

==================================================

Running tests for API 'hackernews'...
..........
----------------------------------------------------------------------
Ran 10 tests in 2.187s

OK
Tests completed for API 'hackernews'

==================================================

Running tests for API 'tvmaze'...
.F.............
======================================================================
FAIL: test_person_crew_credits (__main__.TestTvMazeAPI.test_person_crew_credits)
----------------------------------------------------------------------
Traceback (most recent call last):
  File "/home/trevea/Projects/ToolsForTheJobBenchmark/generation/Content/tvmaze/api_test.py", line 69, in test_person_crew_credits
    self.assertTrue(len(result) > 0)
AssertionError: False is not true

----------------------------------------------------------------------
Ran 15 tests in 9.938s

FAILED (failures=1)
Tests completed for API 'tvmaze'

==================================================

Running tests for API 'jikan'...
........F
======================================================================
FAIL: test_get_character_pictures (__main__.TestJikanAPI.test_get_character_pictures)
----------------------------------------------------------------------
Traceback (most recent call last):
  File "/home/trevea/Projects/ToolsForTheJobBenchmark/generation/Content/jikan/api_test.py", line 43, in test_get_character_pictures
    self.assertIn('data', response)
AssertionError: 'data' not found in {'status': '429', 'type': 'RateLimitException', 'message': 'You are being rate-limited. Please follow Rate Limiting guidelines: https://docs.api.jikan.moe/#section/Information/Rate-Limiting', 'error': None}

----------------------------------------------------------------------
Ran 9 tests in 6.412s

FAILED (failures=1)
Tests completed for API 'jikan'

==================================================

Running tests for API 'crossref'...
......
----------------------------------------------------------------------
Ran 6 tests in 3.710s

OK
Tests completed for API 'crossref'

==================================================

Running tests for API 'rickandmorty'...
....F.
======================================================================
FAIL: test_get_location_by_id (__main__.TestRickAndMortyAPI.test_get_location_by_id)
----------------------------------------------------------------------
Traceback (most recent call last):
  File "/home/trevea/Projects/ToolsForTheJobBenchmark/generation/Content/rickandmorty/api_test.py", line 22, in test_get_location_by_id
    self.assertEqual(response['name'], "Earth")
AssertionError: 'Earth (C-137)' != 'Earth'
- Earth (C-137)
+ Earth


----------------------------------------------------------------------
Ran 6 tests in 3.276s

FAILED (failures=1)
Tests completed for API 'rickandmorty'

==================================================

Running tests for API 'wordpress'...
Tests completed for API 'wordpress'

==================================================

python3: can't open file '/home/trevea/Projects/ToolsForTheJobBenchmark/generation/Content/wordpress/api_test.py': [Errno 2] No such file or directory
Running tests for API 'ceskatelevise'...
...
----------------------------------------------------------------------
Ran 3 tests in 4.972s

OK
Tests completed for API 'ceskatelevise'

==================================================

Running tests for API 'animenewsnetwork'...
.....
----------------------------------------------------------------------
Ran 5 tests in 4.095s

OK
Tests completed for API 'animenewsnetwork'

==================================================

Running tests for API 'mediawiki'...
..Tests completed for API 'mediawiki'

==================================================

.
----------------------------------------------------------------------
Ran 3 tests in 1.410s

OK
