Running tests for API 'cocktail'...
Tests completed for API 'cocktail'

==================================================

python3: can't open file '/home/trevea/Projects/ToolsForTheJobBenchmark/generation/Food/cocktail/api_test.py': [Errno 2] No such file or directory
Running tests for API 'openbrewery'...
EEEEEE
======================================================================
ERROR: test_autocomplete_breweries (__main__.TestOpenBreweryAPI.test_autocomplete_breweries)
----------------------------------------------------------------------
Traceback (most recent call last):
  File "/home/trevea/miniconda3/envs/nlp-rag/lib/python3.12/site-packages/urllib3/connectionpool.py", line 790, in urlopen
    response = self._make_request(
               ^^^^^^^^^^^^^^^^^^^
  File "/home/trevea/miniconda3/envs/nlp-rag/lib/python3.12/site-packages/urllib3/connectionpool.py", line 491, in _make_request
    raise new_e
  File "/home/trevea/miniconda3/envs/nlp-rag/lib/python3.12/site-packages/urllib3/connectionpool.py", line 467, in _make_request
    self._validate_conn(conn)
  File "/home/trevea/miniconda3/envs/nlp-rag/lib/python3.12/site-packages/urllib3/connectionpool.py", line 1096, in _validate_conn
    conn.connect()
  File "/home/trevea/miniconda3/envs/nlp-rag/lib/python3.12/site-packages/urllib3/connection.py", line 642, in connect
    sock_and_verified = _ssl_wrap_socket_and_match_hostname(
                        ^^^^^^^^^^^^^^^^^^^^^^^^^^^^^^^^^^^^
  File "/home/trevea/miniconda3/envs/nlp-rag/lib/python3.12/site-packages/urllib3/connection.py", line 782, in _ssl_wrap_socket_and_match_hostname
    ssl_sock = ssl_wrap_socket(
               ^^^^^^^^^^^^^^^^
  File "/home/trevea/miniconda3/envs/nlp-rag/lib/python3.12/site-packages/urllib3/util/ssl_.py", line 470, in ssl_wrap_socket
    ssl_sock = _ssl_wrap_socket_impl(sock, context, tls_in_tls, server_hostname)
               ^^^^^^^^^^^^^^^^^^^^^^^^^^^^^^^^^^^^^^^^^^^^^^^^^^^^^^^^^^^^^^^^^
  File "/home/trevea/miniconda3/envs/nlp-rag/lib/python3.12/site-packages/urllib3/util/ssl_.py", line 514, in _ssl_wrap_socket_impl
    return ssl_context.wrap_socket(sock, server_hostname=server_hostname)
           ^^^^^^^^^^^^^^^^^^^^^^^^^^^^^^^^^^^^^^^^^^^^^^^^^^^^^^^^^^^^^^
  File "/home/trevea/miniconda3/envs/nlp-rag/lib/python3.12/ssl.py", line 455, in wrap_socket
    return self.sslsocket_class._create(
           ^^^^^^^^^^^^^^^^^^^^^^^^^^^^^
  File "/home/trevea/miniconda3/envs/nlp-rag/lib/python3.12/ssl.py", line 1046, in _create
    self.do_handshake()
  File "/home/trevea/miniconda3/envs/nlp-rag/lib/python3.12/ssl.py", line 1321, in do_handshake
    self._sslobj.do_handshake()
ConnectionResetError: [Errno 104] Connection reset by peer

During handling of the above exception, another exception occurred:

Traceback (most recent call last):
  File "/home/trevea/miniconda3/envs/nlp-rag/lib/python3.12/site-packages/requests/adapters.py", line 486, in send
    resp = conn.urlopen(
           ^^^^^^^^^^^^^
  File "/home/trevea/miniconda3/envs/nlp-rag/lib/python3.12/site-packages/urllib3/connectionpool.py", line 844, in urlopen
    retries = retries.increment(
              ^^^^^^^^^^^^^^^^^^
  File "/home/trevea/miniconda3/envs/nlp-rag/lib/python3.12/site-packages/urllib3/util/retry.py", line 470, in increment
    raise reraise(type(error), error, _stacktrace)
          ^^^^^^^^^^^^^^^^^^^^^^^^^^^^^^^^^^^^^^^^
  File "/home/trevea/miniconda3/envs/nlp-rag/lib/python3.12/site-packages/urllib3/util/util.py", line 38, in reraise
    raise value.with_traceback(tb)
  File "/home/trevea/miniconda3/envs/nlp-rag/lib/python3.12/site-packages/urllib3/connectionpool.py", line 790, in urlopen
    response = self._make_request(
               ^^^^^^^^^^^^^^^^^^^
  File "/home/trevea/miniconda3/envs/nlp-rag/lib/python3.12/site-packages/urllib3/connectionpool.py", line 491, in _make_request
    raise new_e
  File "/home/trevea/miniconda3/envs/nlp-rag/lib/python3.12/site-packages/urllib3/connectionpool.py", line 467, in _make_request
    self._validate_conn(conn)
  File "/home/trevea/miniconda3/envs/nlp-rag/lib/python3.12/site-packages/urllib3/connectionpool.py", line 1096, in _validate_conn
    conn.connect()
  File "/home/trevea/miniconda3/envs/nlp-rag/lib/python3.12/site-packages/urllib3/connection.py", line 642, in connect
    sock_and_verified = _ssl_wrap_socket_and_match_hostname(
                        ^^^^^^^^^^^^^^^^^^^^^^^^^^^^^^^^^^^^
  File "/home/trevea/miniconda3/envs/nlp-rag/lib/python3.12/site-packages/urllib3/connection.py", line 782, in _ssl_wrap_socket_and_match_hostname
    ssl_sock = ssl_wrap_socket(
               ^^^^^^^^^^^^^^^^
  File "/home/trevea/miniconda3/envs/nlp-rag/lib/python3.12/site-packages/urllib3/util/ssl_.py", line 470, in ssl_wrap_socket
    ssl_sock = _ssl_wrap_socket_impl(sock, context, tls_in_tls, server_hostname)
               ^^^^^^^^^^^^^^^^^^^^^^^^^^^^^^^^^^^^^^^^^^^^^^^^^^^^^^^^^^^^^^^^^
  File "/home/trevea/miniconda3/envs/nlp-rag/lib/python3.12/site-packages/urllib3/util/ssl_.py", line 514, in _ssl_wrap_socket_impl
    return ssl_context.wrap_socket(sock, server_hostname=server_hostname)
           ^^^^^^^^^^^^^^^^^^^^^^^^^^^^^^^^^^^^^^^^^^^^^^^^^^^^^^^^^^^^^^
  File "/home/trevea/miniconda3/envs/nlp-rag/lib/python3.12/ssl.py", line 455, in wrap_socket
    return self.sslsocket_class._create(
           ^^^^^^^^^^^^^^^^^^^^^^^^^^^^^
  File "/home/trevea/miniconda3/envs/nlp-rag/lib/python3.12/ssl.py", line 1046, in _create
    self.do_handshake()
  File "/home/trevea/miniconda3/envs/nlp-rag/lib/python3.12/ssl.py", line 1321, in do_handshake
    self._sslobj.do_handshake()
urllib3.exceptions.ProtocolError: ('Connection aborted.', ConnectionResetError(104, 'Connection reset by peer'))

During handling of the above exception, another exception occurred:

Traceback (most recent call last):
  File "/home/trevea/Projects/ToolsForTheJobBenchmark/generation/Food/openbrewery/api_test.py", line 23, in test_autocomplete_breweries
    response = autocomplete_breweries('dog')
               ^^^^^^^^^^^^^^^^^^^^^^^^^^^^^
  File "/home/trevea/Projects/ToolsForTheJobBenchmark/generation/Food/openbrewery/api.py", line 66, in autocomplete_breweries
    response = requests.get(url, params=params)
               ^^^^^^^^^^^^^^^^^^^^^^^^^^^^^^^^
  File "/home/trevea/miniconda3/envs/nlp-rag/lib/python3.12/site-packages/requests/api.py", line 73, in get
    return request("get", url, params=params, **kwargs)
           ^^^^^^^^^^^^^^^^^^^^^^^^^^^^^^^^^^^^^^^^^^^^
  File "/home/trevea/miniconda3/envs/nlp-rag/lib/python3.12/site-packages/requests/api.py", line 59, in request
    return session.request(method=method, url=url, **kwargs)
           ^^^^^^^^^^^^^^^^^^^^^^^^^^^^^^^^^^^^^^^^^^^^^^^^^
  File "/home/trevea/miniconda3/envs/nlp-rag/lib/python3.12/site-packages/requests/sessions.py", line 589, in request
    resp = self.send(prep, **send_kwargs)
           ^^^^^^^^^^^^^^^^^^^^^^^^^^^^^^
  File "/home/trevea/miniconda3/envs/nlp-rag/lib/python3.12/site-packages/requests/sessions.py", line 703, in send
    r = adapter.send(request, **kwargs)
        ^^^^^^^^^^^^^^^^^^^^^^^^^^^^^^^
  File "/home/trevea/miniconda3/envs/nlp-rag/lib/python3.12/site-packages/requests/adapters.py", line 501, in send
    raise ConnectionError(err, request=request)
requests.exceptions.ConnectionError: ('Connection aborted.', ConnectionResetError(104, 'Connection reset by peer'))

======================================================================
ERROR: test_get_breweries_metadata (__main__.TestOpenBreweryAPI.test_get_breweries_metadata)
----------------------------------------------------------------------
Traceback (most recent call last):
  File "/home/trevea/miniconda3/envs/nlp-rag/lib/python3.12/site-packages/urllib3/connectionpool.py", line 790, in urlopen
    response = self._make_request(
               ^^^^^^^^^^^^^^^^^^^
  File "/home/trevea/miniconda3/envs/nlp-rag/lib/python3.12/site-packages/urllib3/connectionpool.py", line 491, in _make_request
    raise new_e
  File "/home/trevea/miniconda3/envs/nlp-rag/lib/python3.12/site-packages/urllib3/connectionpool.py", line 467, in _make_request
    self._validate_conn(conn)
  File "/home/trevea/miniconda3/envs/nlp-rag/lib/python3.12/site-packages/urllib3/connectionpool.py", line 1096, in _validate_conn
    conn.connect()
  File "/home/trevea/miniconda3/envs/nlp-rag/lib/python3.12/site-packages/urllib3/connection.py", line 642, in connect
    sock_and_verified = _ssl_wrap_socket_and_match_hostname(
                        ^^^^^^^^^^^^^^^^^^^^^^^^^^^^^^^^^^^^
  File "/home/trevea/miniconda3/envs/nlp-rag/lib/python3.12/site-packages/urllib3/connection.py", line 782, in _ssl_wrap_socket_and_match_hostname
    ssl_sock = ssl_wrap_socket(
               ^^^^^^^^^^^^^^^^
  File "/home/trevea/miniconda3/envs/nlp-rag/lib/python3.12/site-packages/urllib3/util/ssl_.py", line 470, in ssl_wrap_socket
    ssl_sock = _ssl_wrap_socket_impl(sock, context, tls_in_tls, server_hostname)
               ^^^^^^^^^^^^^^^^^^^^^^^^^^^^^^^^^^^^^^^^^^^^^^^^^^^^^^^^^^^^^^^^^
  File "/home/trevea/miniconda3/envs/nlp-rag/lib/python3.12/site-packages/urllib3/util/ssl_.py", line 514, in _ssl_wrap_socket_impl
    return ssl_context.wrap_socket(sock, server_hostname=server_hostname)
           ^^^^^^^^^^^^^^^^^^^^^^^^^^^^^^^^^^^^^^^^^^^^^^^^^^^^^^^^^^^^^^
  File "/home/trevea/miniconda3/envs/nlp-rag/lib/python3.12/ssl.py", line 455, in wrap_socket
    return self.sslsocket_class._create(
           ^^^^^^^^^^^^^^^^^^^^^^^^^^^^^
  File "/home/trevea/miniconda3/envs/nlp-rag/lib/python3.12/ssl.py", line 1046, in _create
    self.do_handshake()
  File "/home/trevea/miniconda3/envs/nlp-rag/lib/python3.12/ssl.py", line 1321, in do_handshake
    self._sslobj.do_handshake()
ConnectionResetError: [Errno 104] Connection reset by peer

During handling of the above exception, another exception occurred:

Traceback (most recent call last):
  File "/home/trevea/miniconda3/envs/nlp-rag/lib/python3.12/site-packages/requests/adapters.py", line 486, in send
    resp = conn.urlopen(
           ^^^^^^^^^^^^^
  File "/home/trevea/miniconda3/envs/nlp-rag/lib/python3.12/site-packages/urllib3/connectionpool.py", line 844, in urlopen
    retries = retries.increment(
              ^^^^^^^^^^^^^^^^^^
  File "/home/trevea/miniconda3/envs/nlp-rag/lib/python3.12/site-packages/urllib3/util/retry.py", line 470, in increment
    raise reraise(type(error), error, _stacktrace)
          ^^^^^^^^^^^^^^^^^^^^^^^^^^^^^^^^^^^^^^^^
  File "/home/trevea/miniconda3/envs/nlp-rag/lib/python3.12/site-packages/urllib3/util/util.py", line 38, in reraise
    raise value.with_traceback(tb)
  File "/home/trevea/miniconda3/envs/nlp-rag/lib/python3.12/site-packages/urllib3/connectionpool.py", line 790, in urlopen
    response = self._make_request(
               ^^^^^^^^^^^^^^^^^^^
  File "/home/trevea/miniconda3/envs/nlp-rag/lib/python3.12/site-packages/urllib3/connectionpool.py", line 491, in _make_request
    raise new_e
  File "/home/trevea/miniconda3/envs/nlp-rag/lib/python3.12/site-packages/urllib3/connectionpool.py", line 467, in _make_request
    self._validate_conn(conn)
  File "/home/trevea/miniconda3/envs/nlp-rag/lib/python3.12/site-packages/urllib3/connectionpool.py", line 1096, in _validate_conn
    conn.connect()
  File "/home/trevea/miniconda3/envs/nlp-rag/lib/python3.12/site-packages/urllib3/connection.py", line 642, in connect
    sock_and_verified = _ssl_wrap_socket_and_match_hostname(
                        ^^^^^^^^^^^^^^^^^^^^^^^^^^^^^^^^^^^^
  File "/home/trevea/miniconda3/envs/nlp-rag/lib/python3.12/site-packages/urllib3/connection.py", line 782, in _ssl_wrap_socket_and_match_hostname
    ssl_sock = ssl_wrap_socket(
               ^^^^^^^^^^^^^^^^
  File "/home/trevea/miniconda3/envs/nlp-rag/lib/python3.12/site-packages/urllib3/util/ssl_.py", line 470, in ssl_wrap_socket
    ssl_sock = _ssl_wrap_socket_impl(sock, context, tls_in_tls, server_hostname)
               ^^^^^^^^^^^^^^^^^^^^^^^^^^^^^^^^^^^^^^^^^^^^^^^^^^^^^^^^^^^^^^^^^
  File "/home/trevea/miniconda3/envs/nlp-rag/lib/python3.12/site-packages/urllib3/util/ssl_.py", line 514, in _ssl_wrap_socket_impl
    return ssl_context.wrap_socket(sock, server_hostname=server_hostname)
           ^^^^^^^^^^^^^^^^^^^^^^^^^^^^^^^^^^^^^^^^^^^^^^^^^^^^^^^^^^^^^^
  File "/home/trevea/miniconda3/envs/nlp-rag/lib/python3.12/ssl.py", line 455, in wrap_socket
    return self.sslsocket_class._create(
           ^^^^^^^^^^^^^^^^^^^^^^^^^^^^^
  File "/home/trevea/miniconda3/envs/nlp-rag/lib/python3.12/ssl.py", line 1046, in _create
    self.do_handshake()
  File "/home/trevea/miniconda3/envs/nlp-rag/lib/python3.12/ssl.py", line 1321, in do_handshake
    self._sslobj.do_handshake()
urllib3.exceptions.ProtocolError: ('Connection aborted.', ConnectionResetError(104, 'Connection reset by peer'))

During handling of the above exception, another exception occurred:

Traceback (most recent call last):
  File "/home/trevea/Projects/ToolsForTheJobBenchmark/generation/Food/openbrewery/api_test.py", line 27, in test_get_breweries_metadata
    response = get_breweries_metadata()
               ^^^^^^^^^^^^^^^^^^^^^^^^
  File "/home/trevea/Projects/ToolsForTheJobBenchmark/generation/Food/openbrewery/api.py", line 77, in get_breweries_metadata
    response = requests.get(url)
               ^^^^^^^^^^^^^^^^^
  File "/home/trevea/miniconda3/envs/nlp-rag/lib/python3.12/site-packages/requests/api.py", line 73, in get
    return request("get", url, params=params, **kwargs)
           ^^^^^^^^^^^^^^^^^^^^^^^^^^^^^^^^^^^^^^^^^^^^
  File "/home/trevea/miniconda3/envs/nlp-rag/lib/python3.12/site-packages/requests/api.py", line 59, in request
    return session.request(method=method, url=url, **kwargs)
           ^^^^^^^^^^^^^^^^^^^^^^^^^^^^^^^^^^^^^^^^^^^^^^^^^
  File "/home/trevea/miniconda3/envs/nlp-rag/lib/python3.12/site-packages/requests/sessions.py", line 589, in request
    resp = self.send(prep, **send_kwargs)
           ^^^^^^^^^^^^^^^^^^^^^^^^^^^^^^
  File "/home/trevea/miniconda3/envs/nlp-rag/lib/python3.12/site-packages/requests/sessions.py", line 703, in send
    r = adapter.send(request, **kwargs)
        ^^^^^^^^^^^^^^^^^^^^^^^^^^^^^^^
  File "/home/trevea/miniconda3/envs/nlp-rag/lib/python3.12/site-packages/requests/adapters.py", line 501, in send
    raise ConnectionError(err, request=request)
requests.exceptions.ConnectionError: ('Connection aborted.', ConnectionResetError(104, 'Connection reset by peer'))

======================================================================
ERROR: test_get_brewery_by_id (__main__.TestOpenBreweryAPI.test_get_brewery_by_id)
----------------------------------------------------------------------
Traceback (most recent call last):
  File "/home/trevea/miniconda3/envs/nlp-rag/lib/python3.12/site-packages/urllib3/connectionpool.py", line 790, in urlopen
    response = self._make_request(
               ^^^^^^^^^^^^^^^^^^^
  File "/home/trevea/miniconda3/envs/nlp-rag/lib/python3.12/site-packages/urllib3/connectionpool.py", line 491, in _make_request
    raise new_e
  File "/home/trevea/miniconda3/envs/nlp-rag/lib/python3.12/site-packages/urllib3/connectionpool.py", line 467, in _make_request
    self._validate_conn(conn)
  File "/home/trevea/miniconda3/envs/nlp-rag/lib/python3.12/site-packages/urllib3/connectionpool.py", line 1096, in _validate_conn
    conn.connect()
  File "/home/trevea/miniconda3/envs/nlp-rag/lib/python3.12/site-packages/urllib3/connection.py", line 642, in connect
    sock_and_verified = _ssl_wrap_socket_and_match_hostname(
                        ^^^^^^^^^^^^^^^^^^^^^^^^^^^^^^^^^^^^
  File "/home/trevea/miniconda3/envs/nlp-rag/lib/python3.12/site-packages/urllib3/connection.py", line 782, in _ssl_wrap_socket_and_match_hostname
    ssl_sock = ssl_wrap_socket(
               ^^^^^^^^^^^^^^^^
  File "/home/trevea/miniconda3/envs/nlp-rag/lib/python3.12/site-packages/urllib3/util/ssl_.py", line 470, in ssl_wrap_socket
    ssl_sock = _ssl_wrap_socket_impl(sock, context, tls_in_tls, server_hostname)
               ^^^^^^^^^^^^^^^^^^^^^^^^^^^^^^^^^^^^^^^^^^^^^^^^^^^^^^^^^^^^^^^^^
  File "/home/trevea/miniconda3/envs/nlp-rag/lib/python3.12/site-packages/urllib3/util/ssl_.py", line 514, in _ssl_wrap_socket_impl
    return ssl_context.wrap_socket(sock, server_hostname=server_hostname)
           ^^^^^^^^^^^^^^^^^^^^^^^^^^^^^^^^^^^^^^^^^^^^^^^^^^^^^^^^^^^^^^
  File "/home/trevea/miniconda3/envs/nlp-rag/lib/python3.12/ssl.py", line 455, in wrap_socket
    return self.sslsocket_class._create(
           ^^^^^^^^^^^^^^^^^^^^^^^^^^^^^
  File "/home/trevea/miniconda3/envs/nlp-rag/lib/python3.12/ssl.py", line 1046, in _create
    self.do_handshake()
  File "/home/trevea/miniconda3/envs/nlp-rag/lib/python3.12/ssl.py", line 1321, in do_handshake
    self._sslobj.do_handshake()
ConnectionResetError: [Errno 104] Connection reset by peer

During handling of the above exception, another exception occurred:

Traceback (most recent call last):
  File "/home/trevea/miniconda3/envs/nlp-rag/lib/python3.12/site-packages/requests/adapters.py", line 486, in send
    resp = conn.urlopen(
           ^^^^^^^^^^^^^
  File "/home/trevea/miniconda3/envs/nlp-rag/lib/python3.12/site-packages/urllib3/connectionpool.py", line 844, in urlopen
    retries = retries.increment(
              ^^^^^^^^^^^^^^^^^^
  File "/home/trevea/miniconda3/envs/nlp-rag/lib/python3.12/site-packages/urllib3/util/retry.py", line 470, in increment
    raise reraise(type(error), error, _stacktrace)
          ^^^^^^^^^^^^^^^^^^^^^^^^^^^^^^^^^^^^^^^^
  File "/home/trevea/miniconda3/envs/nlp-rag/lib/python3.12/site-packages/urllib3/util/util.py", line 38, in reraise
    raise value.with_traceback(tb)
  File "/home/trevea/miniconda3/envs/nlp-rag/lib/python3.12/site-packages/urllib3/connectionpool.py", line 790, in urlopen
    response = self._make_request(
               ^^^^^^^^^^^^^^^^^^^
  File "/home/trevea/miniconda3/envs/nlp-rag/lib/python3.12/site-packages/urllib3/connectionpool.py", line 491, in _make_request
    raise new_e
  File "/home/trevea/miniconda3/envs/nlp-rag/lib/python3.12/site-packages/urllib3/connectionpool.py", line 467, in _make_request
    self._validate_conn(conn)
  File "/home/trevea/miniconda3/envs/nlp-rag/lib/python3.12/site-packages/urllib3/connectionpool.py", line 1096, in _validate_conn
    conn.connect()
  File "/home/trevea/miniconda3/envs/nlp-rag/lib/python3.12/site-packages/urllib3/connection.py", line 642, in connect
    sock_and_verified = _ssl_wrap_socket_and_match_hostname(
                        ^^^^^^^^^^^^^^^^^^^^^^^^^^^^^^^^^^^^
  File "/home/trevea/miniconda3/envs/nlp-rag/lib/python3.12/site-packages/urllib3/connection.py", line 782, in _ssl_wrap_socket_and_match_hostname
    ssl_sock = ssl_wrap_socket(
               ^^^^^^^^^^^^^^^^
  File "/home/trevea/miniconda3/envs/nlp-rag/lib/python3.12/site-packages/urllib3/util/ssl_.py", line 470, in ssl_wrap_socket
    ssl_sock = _ssl_wrap_socket_impl(sock, context, tls_in_tls, server_hostname)
               ^^^^^^^^^^^^^^^^^^^^^^^^^^^^^^^^^^^^^^^^^^^^^^^^^^^^^^^^^^^^^^^^^
  File "/home/trevea/miniconda3/envs/nlp-rag/lib/python3.12/site-packages/urllib3/util/ssl_.py", line 514, in _ssl_wrap_socket_impl
    return ssl_context.wrap_socket(sock, server_hostname=server_hostname)
           ^^^^^^^^^^^^^^^^^^^^^^^^^^^^^^^^^^^^^^^^^^^^^^^^^^^^^^^^^^^^^^
  File "/home/trevea/miniconda3/envs/nlp-rag/lib/python3.12/ssl.py", line 455, in wrap_socket
    return self.sslsocket_class._create(
           ^^^^^^^^^^^^^^^^^^^^^^^^^^^^^
  File "/home/trevea/miniconda3/envs/nlp-rag/lib/python3.12/ssl.py", line 1046, in _create
    self.do_handshake()
  File "/home/trevea/miniconda3/envs/nlp-rag/lib/python3.12/ssl.py", line 1321, in do_handshake
    self._sslobj.do_handshake()
urllib3.exceptions.ProtocolError: ('Connection aborted.', ConnectionResetError(104, 'Connection reset by peer'))

During handling of the above exception, another exception occurred:

Traceback (most recent call last):
  File "/home/trevea/Projects/ToolsForTheJobBenchmark/generation/Food/openbrewery/api_test.py", line 7, in test_get_brewery_by_id
    response = get_brewery_by_id('bnaf9f')
               ^^^^^^^^^^^^^^^^^^^^^^^^^^^
  File "/home/trevea/Projects/ToolsForTheJobBenchmark/generation/Food/openbrewery/api.py", line 9, in get_brewery_by_id
    response = requests.get(url)
               ^^^^^^^^^^^^^^^^^
  File "/home/trevea/miniconda3/envs/nlp-rag/lib/python3.12/site-packages/requests/api.py", line 73, in get
    return request("get", url, params=params, **kwargs)
           ^^^^^^^^^^^^^^^^^^^^^^^^^^^^^^^^^^^^^^^^^^^^
  File "/home/trevea/miniconda3/envs/nlp-rag/lib/python3.12/site-packages/requests/api.py", line 59, in request
    return session.request(method=method, url=url, **kwargs)
           ^^^^^^^^^^^^^^^^^^^^^^^^^^^^^^^^^^^^^^^^^^^^^^^^^
  File "/home/trevea/miniconda3/envs/nlp-rag/lib/python3.12/site-packages/requests/sessions.py", line 589, in request
    resp = self.send(prep, **send_kwargs)
           ^^^^^^^^^^^^^^^^^^^^^^^^^^^^^^
  File "/home/trevea/miniconda3/envs/nlp-rag/lib/python3.12/site-packages/requests/sessions.py", line 703, in send
    r = adapter.send(request, **kwargs)
        ^^^^^^^^^^^^^^^^^^^^^^^^^^^^^^^
  File "/home/trevea/miniconda3/envs/nlp-rag/lib/python3.12/site-packages/requests/adapters.py", line 501, in send
    raise ConnectionError(err, request=request)
requests.exceptions.ConnectionError: ('Connection aborted.', ConnectionResetError(104, 'Connection reset by peer'))

======================================================================
ERROR: test_get_random_brewery (__main__.TestOpenBreweryAPI.test_get_random_brewery)
----------------------------------------------------------------------
Traceback (most recent call last):
  File "/home/trevea/miniconda3/envs/nlp-rag/lib/python3.12/site-packages/urllib3/connectionpool.py", line 790, in urlopen
    response = self._make_request(
               ^^^^^^^^^^^^^^^^^^^
  File "/home/trevea/miniconda3/envs/nlp-rag/lib/python3.12/site-packages/urllib3/connectionpool.py", line 491, in _make_request
    raise new_e
  File "/home/trevea/miniconda3/envs/nlp-rag/lib/python3.12/site-packages/urllib3/connectionpool.py", line 467, in _make_request
    self._validate_conn(conn)
  File "/home/trevea/miniconda3/envs/nlp-rag/lib/python3.12/site-packages/urllib3/connectionpool.py", line 1096, in _validate_conn
    conn.connect()
  File "/home/trevea/miniconda3/envs/nlp-rag/lib/python3.12/site-packages/urllib3/connection.py", line 642, in connect
    sock_and_verified = _ssl_wrap_socket_and_match_hostname(
                        ^^^^^^^^^^^^^^^^^^^^^^^^^^^^^^^^^^^^
  File "/home/trevea/miniconda3/envs/nlp-rag/lib/python3.12/site-packages/urllib3/connection.py", line 782, in _ssl_wrap_socket_and_match_hostname
    ssl_sock = ssl_wrap_socket(
               ^^^^^^^^^^^^^^^^
  File "/home/trevea/miniconda3/envs/nlp-rag/lib/python3.12/site-packages/urllib3/util/ssl_.py", line 470, in ssl_wrap_socket
    ssl_sock = _ssl_wrap_socket_impl(sock, context, tls_in_tls, server_hostname)
               ^^^^^^^^^^^^^^^^^^^^^^^^^^^^^^^^^^^^^^^^^^^^^^^^^^^^^^^^^^^^^^^^^
  File "/home/trevea/miniconda3/envs/nlp-rag/lib/python3.12/site-packages/urllib3/util/ssl_.py", line 514, in _ssl_wrap_socket_impl
    return ssl_context.wrap_socket(sock, server_hostname=server_hostname)
           ^^^^^^^^^^^^^^^^^^^^^^^^^^^^^^^^^^^^^^^^^^^^^^^^^^^^^^^^^^^^^^
  File "/home/trevea/miniconda3/envs/nlp-rag/lib/python3.12/ssl.py", line 455, in wrap_socket
    return self.sslsocket_class._create(
           ^^^^^^^^^^^^^^^^^^^^^^^^^^^^^
  File "/home/trevea/miniconda3/envs/nlp-rag/lib/python3.12/ssl.py", line 1046, in _create
    self.do_handshake()
  File "/home/trevea/miniconda3/envs/nlp-rag/lib/python3.12/ssl.py", line 1321, in do_handshake
    self._sslobj.do_handshake()
ConnectionResetError: [Errno 104] Connection reset by peer

During handling of the above exception, another exception occurred:

Traceback (most recent call last):
  File "/home/trevea/miniconda3/envs/nlp-rag/lib/python3.12/site-packages/requests/adapters.py", line 486, in send
    resp = conn.urlopen(
           ^^^^^^^^^^^^^
  File "/home/trevea/miniconda3/envs/nlp-rag/lib/python3.12/site-packages/urllib3/connectionpool.py", line 844, in urlopen
    retries = retries.increment(
              ^^^^^^^^^^^^^^^^^^
  File "/home/trevea/miniconda3/envs/nlp-rag/lib/python3.12/site-packages/urllib3/util/retry.py", line 470, in increment
    raise reraise(type(error), error, _stacktrace)
          ^^^^^^^^^^^^^^^^^^^^^^^^^^^^^^^^^^^^^^^^
  File "/home/trevea/miniconda3/envs/nlp-rag/lib/python3.12/site-packages/urllib3/util/util.py", line 38, in reraise
    raise value.with_traceback(tb)
  File "/home/trevea/miniconda3/envs/nlp-rag/lib/python3.12/site-packages/urllib3/connectionpool.py", line 790, in urlopen
    response = self._make_request(
               ^^^^^^^^^^^^^^^^^^^
  File "/home/trevea/miniconda3/envs/nlp-rag/lib/python3.12/site-packages/urllib3/connectionpool.py", line 491, in _make_request
    raise new_e
  File "/home/trevea/miniconda3/envs/nlp-rag/lib/python3.12/site-packages/urllib3/connectionpool.py", line 467, in _make_request
    self._validate_conn(conn)
  File "/home/trevea/miniconda3/envs/nlp-rag/lib/python3.12/site-packages/urllib3/connectionpool.py", line 1096, in _validate_conn
    conn.connect()
  File "/home/trevea/miniconda3/envs/nlp-rag/lib/python3.12/site-packages/urllib3/connection.py", line 642, in connect
    sock_and_verified = _ssl_wrap_socket_and_match_hostname(
                        ^^^^^^^^^^^^^^^^^^^^^^^^^^^^^^^^^^^^
  File "/home/trevea/miniconda3/envs/nlp-rag/lib/python3.12/site-packages/urllib3/connection.py", line 782, in _ssl_wrap_socket_and_match_hostname
    ssl_sock = ssl_wrap_socket(
               ^^^^^^^^^^^^^^^^
  File "/home/trevea/miniconda3/envs/nlp-rag/lib/python3.12/site-packages/urllib3/util/ssl_.py", line 470, in ssl_wrap_socket
    ssl_sock = _ssl_wrap_socket_impl(sock, context, tls_in_tls, server_hostname)
               ^^^^^^^^^^^^^^^^^^^^^^^^^^^^^^^^^^^^^^^^^^^^^^^^^^^^^^^^^^^^^^^^^
  File "/home/trevea/miniconda3/envs/nlp-rag/lib/python3.12/site-packages/urllib3/util/ssl_.py", line 514, in _ssl_wrap_socket_impl
    return ssl_context.wrap_socket(sock, server_hostname=server_hostname)
           ^^^^^^^^^^^^^^^^^^^^^^^^^^^^^^^^^^^^^^^^^^^^^^^^^^^^^^^^^^^^^^
  File "/home/trevea/miniconda3/envs/nlp-rag/lib/python3.12/ssl.py", line 455, in wrap_socket
    return self.sslsocket_class._create(
           ^^^^^^^^^^^^^^^^^^^^^^^^^^^^^
  File "/home/trevea/miniconda3/envs/nlp-rag/lib/python3.12/ssl.py", line 1046, in _create
    self.do_handshake()
  File "/home/trevea/miniconda3/envs/nlp-rag/lib/python3.12/ssl.py", line 1321, in do_handshake
    self._sslobj.do_handshake()
urllib3.exceptions.ProtocolError: ('Connection aborted.', ConnectionResetError(104, 'Connection reset by peer'))

During handling of the above exception, another exception occurred:

Traceback (most recent call last):
  File "/home/trevea/Projects/ToolsForTheJobBenchmark/generation/Food/openbrewery/api_test.py", line 15, in test_get_random_brewery
    response = get_random_brewery()
               ^^^^^^^^^^^^^^^^^^^^
  File "/home/trevea/Projects/ToolsForTheJobBenchmark/generation/Food/openbrewery/api.py", line 38, in get_random_brewery
    response = requests.get(url, params=params)
               ^^^^^^^^^^^^^^^^^^^^^^^^^^^^^^^^
  File "/home/trevea/miniconda3/envs/nlp-rag/lib/python3.12/site-packages/requests/api.py", line 73, in get
    return request("get", url, params=params, **kwargs)
           ^^^^^^^^^^^^^^^^^^^^^^^^^^^^^^^^^^^^^^^^^^^^
  File "/home/trevea/miniconda3/envs/nlp-rag/lib/python3.12/site-packages/requests/api.py", line 59, in request
    return session.request(method=method, url=url, **kwargs)
           ^^^^^^^^^^^^^^^^^^^^^^^^^^^^^^^^^^^^^^^^^^^^^^^^^
  File "/home/trevea/miniconda3/envs/nlp-rag/lib/python3.12/site-packages/requests/sessions.py", line 589, in request
    resp = self.send(prep, **send_kwargs)
           ^^^^^^^^^^^^^^^^^^^^^^^^^^^^^^
  File "/home/trevea/miniconda3/envs/nlp-rag/lib/python3.12/site-packages/requests/sessions.py", line 703, in send
    r = adapter.send(request, **kwargs)
        ^^^^^^^^^^^^^^^^^^^^^^^^^^^^^^^
  File "/home/trevea/miniconda3/envs/nlp-rag/lib/python3.12/site-packages/requests/adapters.py", line 501, in send
    raise ConnectionError(err, request=request)
requests.exceptions.ConnectionError: ('Connection aborted.', ConnectionResetError(104, 'Connection reset by peer'))

======================================================================
ERROR: test_list_breweries (__main__.TestOpenBreweryAPI.test_list_breweries)
----------------------------------------------------------------------
Traceback (most recent call last):
  File "/home/trevea/miniconda3/envs/nlp-rag/lib/python3.12/site-packages/urllib3/connectionpool.py", line 790, in urlopen
    response = self._make_request(
               ^^^^^^^^^^^^^^^^^^^
  File "/home/trevea/miniconda3/envs/nlp-rag/lib/python3.12/site-packages/urllib3/connectionpool.py", line 491, in _make_request
    raise new_e
  File "/home/trevea/miniconda3/envs/nlp-rag/lib/python3.12/site-packages/urllib3/connectionpool.py", line 467, in _make_request
    self._validate_conn(conn)
  File "/home/trevea/miniconda3/envs/nlp-rag/lib/python3.12/site-packages/urllib3/connectionpool.py", line 1096, in _validate_conn
    conn.connect()
  File "/home/trevea/miniconda3/envs/nlp-rag/lib/python3.12/site-packages/urllib3/connection.py", line 642, in connect
    sock_and_verified = _ssl_wrap_socket_and_match_hostname(
                        ^^^^^^^^^^^^^^^^^^^^^^^^^^^^^^^^^^^^
  File "/home/trevea/miniconda3/envs/nlp-rag/lib/python3.12/site-packages/urllib3/connection.py", line 782, in _ssl_wrap_socket_and_match_hostname
    ssl_sock = ssl_wrap_socket(
               ^^^^^^^^^^^^^^^^
  File "/home/trevea/miniconda3/envs/nlp-rag/lib/python3.12/site-packages/urllib3/util/ssl_.py", line 470, in ssl_wrap_socket
    ssl_sock = _ssl_wrap_socket_impl(sock, context, tls_in_tls, server_hostname)
               ^^^^^^^^^^^^^^^^^^^^^^^^^^^^^^^^^^^^^^^^^^^^^^^^^^^^^^^^^^^^^^^^^
  File "/home/trevea/miniconda3/envs/nlp-rag/lib/python3.12/site-packages/urllib3/util/ssl_.py", line 514, in _ssl_wrap_socket_impl
    return ssl_context.wrap_socket(sock, server_hostname=server_hostname)
           ^^^^^^^^^^^^^^^^^^^^^^^^^^^^^^^^^^^^^^^^^^^^^^^^^^^^^^^^^^^^^^
  File "/home/trevea/miniconda3/envs/nlp-rag/lib/python3.12/ssl.py", line 455, in wrap_socket
    return self.sslsocket_class._create(
           ^^^^^^^^^^^^^^^^^^^^^^^^^^^^^
  File "/home/trevea/miniconda3/envs/nlp-rag/lib/python3.12/ssl.py", line 1046, in _create
    self.do_handshake()
  File "/home/trevea/miniconda3/envs/nlp-rag/lib/python3.12/ssl.py", line 1321, in do_handshake
    self._sslobj.do_handshake()
ConnectionResetError: [Errno 104] Connection reset by peer

During handling of the above exception, another exception occurred:

Traceback (most recent call last):
  File "/home/trevea/miniconda3/envs/nlp-rag/lib/python3.12/site-packages/requests/adapters.py", line 486, in send
    resp = conn.urlopen(
           ^^^^^^^^^^^^^
  File "/home/trevea/miniconda3/envs/nlp-rag/lib/python3.12/site-packages/urllib3/connectionpool.py", line 844, in urlopen
    retries = retries.increment(
              ^^^^^^^^^^^^^^^^^^
  File "/home/trevea/miniconda3/envs/nlp-rag/lib/python3.12/site-packages/urllib3/util/retry.py", line 470, in increment
    raise reraise(type(error), error, _stacktrace)
          ^^^^^^^^^^^^^^^^^^^^^^^^^^^^^^^^^^^^^^^^
  File "/home/trevea/miniconda3/envs/nlp-rag/lib/python3.12/site-packages/urllib3/util/util.py", line 38, in reraise
    raise value.with_traceback(tb)
  File "/home/trevea/miniconda3/envs/nlp-rag/lib/python3.12/site-packages/urllib3/connectionpool.py", line 790, in urlopen
    response = self._make_request(
               ^^^^^^^^^^^^^^^^^^^
  File "/home/trevea/miniconda3/envs/nlp-rag/lib/python3.12/site-packages/urllib3/connectionpool.py", line 491, in _make_request
    raise new_e
  File "/home/trevea/miniconda3/envs/nlp-rag/lib/python3.12/site-packages/urllib3/connectionpool.py", line 467, in _make_request
    self._validate_conn(conn)
  File "/home/trevea/miniconda3/envs/nlp-rag/lib/python3.12/site-packages/urllib3/connectionpool.py", line 1096, in _validate_conn
    conn.connect()
  File "/home/trevea/miniconda3/envs/nlp-rag/lib/python3.12/site-packages/urllib3/connection.py", line 642, in connect
    sock_and_verified = _ssl_wrap_socket_and_match_hostname(
                        ^^^^^^^^^^^^^^^^^^^^^^^^^^^^^^^^^^^^
  File "/home/trevea/miniconda3/envs/nlp-rag/lib/python3.12/site-packages/urllib3/connection.py", line 782, in _ssl_wrap_socket_and_match_hostname
    ssl_sock = ssl_wrap_socket(
               ^^^^^^^^^^^^^^^^
  File "/home/trevea/miniconda3/envs/nlp-rag/lib/python3.12/site-packages/urllib3/util/ssl_.py", line 470, in ssl_wrap_socket
    ssl_sock = _ssl_wrap_socket_impl(sock, context, tls_in_tls, server_hostname)
               ^^^^^^^^^^^^^^^^^^^^^^^^^^^^^^^^^^^^^^^^^^^^^^^^^^^^^^^^^^^^^^^^^
  File "/home/trevea/miniconda3/envs/nlp-rag/lib/python3.12/site-packages/urllib3/util/ssl_.py", line 514, in _ssl_wrap_socket_impl
    return ssl_context.wrap_socket(sock, server_hostname=server_hostname)
           ^^^^^^^^^^^^^^^^^^^^^^^^^^^^^^^^^^^^^^^^^^^^^^^^^^^^^^^^^^^^^^
  File "/home/trevea/miniconda3/envs/nlp-rag/lib/python3.12/ssl.py", line 455, in wrap_socket
    return self.sslsocket_class._create(
           ^^^^^^^^^^^^^^^^^^^^^^^^^^^^^
  File "/home/trevea/miniconda3/envs/nlp-rag/lib/python3.12/ssl.py", line 1046, in _create
    self.do_handshake()
  File "/home/trevea/miniconda3/envs/nlp-rag/lib/python3.12/ssl.py", line 1321, in do_handshake
    self._sslobj.do_handshake()
urllib3.exceptions.ProtocolError: ('Connection aborted.', ConnectionResetError(104, 'Connection reset by peer'))

During handling of the above exception, another exception occurred:

Traceback (most recent call last):
  File "/home/trevea/Projects/ToolsForTheJobBenchmark/generation/Food/openbrewery/api_test.py", line 11, in test_list_breweries
    response = list_breweries()
               ^^^^^^^^^^^^^^^^
  File "/home/trevea/Projects/ToolsForTheJobBenchmark/generation/Food/openbrewery/api.py", line 24, in list_breweries
    response = requests.get(url, params=params)
               ^^^^^^^^^^^^^^^^^^^^^^^^^^^^^^^^
  File "/home/trevea/miniconda3/envs/nlp-rag/lib/python3.12/site-packages/requests/api.py", line 73, in get
    return request("get", url, params=params, **kwargs)
           ^^^^^^^^^^^^^^^^^^^^^^^^^^^^^^^^^^^^^^^^^^^^
  File "/home/trevea/miniconda3/envs/nlp-rag/lib/python3.12/site-packages/requests/api.py", line 59, in request
    return session.request(method=method, url=url, **kwargs)
           ^^^^^^^^^^^^^^^^^^^^^^^^^^^^^^^^^^^^^^^^^^^^^^^^^
  File "/home/trevea/miniconda3/envs/nlp-rag/lib/python3.12/site-packages/requests/sessions.py", line 589, in request
    resp = self.send(prep, **send_kwargs)
           ^^^^^^^^^^^^^^^^^^^^^^^^^^^^^^
  File "/home/trevea/miniconda3/envs/nlp-rag/lib/python3.12/site-packages/requests/sessions.py", line 703, in send
    r = adapter.send(request, **kwargs)
        ^^^^^^^^^^^^^^^^^^^^^^^^^^^^^^^
  File "/home/trevea/miniconda3/envs/nlp-rag/lib/python3.12/site-packages/requests/adapters.py", line 501, in send
    raise ConnectionError(err, request=request)
requests.exceptions.ConnectionError: ('Connection aborted.', ConnectionResetError(104, 'Connection reset by peer'))

======================================================================
ERROR: test_search_breweries (__main__.TestOpenBreweryAPI.test_search_breweries)
----------------------------------------------------------------------
Traceback (most recent call last):
  File "/home/trevea/miniconda3/envs/nlp-rag/lib/python3.12/site-packages/urllib3/connectionpool.py", line 790, in urlopen
    response = self._make_request(
               ^^^^^^^^^^^^^^^^^^^
  File "/home/trevea/miniconda3/envs/nlp-rag/lib/python3.12/site-packages/urllib3/connectionpool.py", line 491, in _make_request
    raise new_e
  File "/home/trevea/miniconda3/envs/nlp-rag/lib/python3.12/site-packages/urllib3/connectionpool.py", line 467, in _make_request
    self._validate_conn(conn)
  File "/home/trevea/miniconda3/envs/nlp-rag/lib/python3.12/site-packages/urllib3/connectionpool.py", line 1096, in _validate_conn
    conn.connect()
  File "/home/trevea/miniconda3/envs/nlp-rag/lib/python3.12/site-packages/urllib3/connection.py", line 642, in connect
    sock_and_verified = _ssl_wrap_socket_and_match_hostname(
                        ^^^^^^^^^^^^^^^^^^^^^^^^^^^^^^^^^^^^
  File "/home/trevea/miniconda3/envs/nlp-rag/lib/python3.12/site-packages/urllib3/connection.py", line 782, in _ssl_wrap_socket_and_match_hostname
    ssl_sock = ssl_wrap_socket(
               ^^^^^^^^^^^^^^^^
  File "/home/trevea/miniconda3/envs/nlp-rag/lib/python3.12/site-packages/urllib3/util/ssl_.py", line 470, in ssl_wrap_socket
    ssl_sock = _ssl_wrap_socket_impl(sock, context, tls_in_tls, server_hostname)
               ^^^^^^^^^^^^^^^^^^^^^^^^^^^^^^^^^^^^^^^^^^^^^^^^^^^^^^^^^^^^^^^^^
  File "/home/trevea/miniconda3/envs/nlp-rag/lib/python3.12/site-packages/urllib3/util/ssl_.py", line 514, in _ssl_wrap_socket_impl
    return ssl_context.wrap_socket(sock, server_hostname=server_hostname)
           ^^^^^^^^^^^^^^^^^^^^^^^^^^^^^^^^^^^^^^^^^^^^^^^^^^^^^^^^^^^^^^
  File "/home/trevea/miniconda3/envs/nlp-rag/lib/python3.12/ssl.py", line 455, in wrap_socket
    return self.sslsocket_class._create(
           ^^^^^^^^^^^^^^^^^^^^^^^^^^^^^
  File "/home/trevea/miniconda3/envs/nlp-rag/lib/python3.12/ssl.py", line 1046, in _create
    self.do_handshake()
  File "/home/trevea/miniconda3/envs/nlp-rag/lib/python3.12/ssl.py", line 1321, in do_handshake
    self._sslobj.do_handshake()
ConnectionResetError: [Errno 104] Connection reset by peer

During handling of the above exception, another exception occurred:

Traceback (most recent call last):
  File "/home/trevea/miniconda3/envs/nlp-rag/lib/python3.12/site-packages/requests/adapters.py", line 486, in send
    resp = conn.urlopen(
           ^^^^^^^^^^^^^
  File "/home/trevea/miniconda3/envs/nlp-rag/lib/python3.12/site-packages/urllib3/connectionpool.py", line 844, in urlopen
    retries = retries.increment(
              ^^^^^^^^^^^^^^^^^^
  File "/home/trevea/miniconda3/envs/nlp-rag/lib/python3.12/site-packages/urllib3/util/retry.py", line 470, in increment
    raise reraise(type(error), error, _stacktrace)
          ^^^^^^^^^^^^^^^^^^^^^^^^^^^^^^^^^^^^^^^^
  File "/home/trevea/miniconda3/envs/nlp-rag/lib/python3.12/site-packages/urllib3/util/util.py", line 38, in reraise
    raise value.with_traceback(tb)
  File "/home/trevea/miniconda3/envs/nlp-rag/lib/python3.12/site-packages/urllib3/connectionpool.py", line 790, in urlopen
    response = self._make_request(
               ^^^^^^^^^^^^^^^^^^^
  File "/home/trevea/miniconda3/envs/nlp-rag/lib/python3.12/site-packages/urllib3/connectionpool.py", line 491, in _make_request
    raise new_e
  File "/home/trevea/miniconda3/envs/nlp-rag/lib/python3.12/site-packages/urllib3/connectionpool.py", line 467, in _make_request
    self._validate_conn(conn)
  File "/home/trevea/miniconda3/envs/nlp-rag/lib/python3.12/site-packages/urllib3/connectionpool.py", line 1096, in _validate_conn
    conn.connect()
  File "/home/trevea/miniconda3/envs/nlp-rag/lib/python3.12/site-packages/urllib3/connection.py", line 642, in connect
    sock_and_verified = _ssl_wrap_socket_and_match_hostname(
                        ^^^^^^^^^^^^^^^^^^^^^^^^^^^^^^^^^^^^
  File "/home/trevea/miniconda3/envs/nlp-rag/lib/python3.12/site-packages/urllib3/connection.py", line 782, in _ssl_wrap_socket_and_match_hostname
    ssl_sock = ssl_wrap_socket(
               ^^^^^^^^^^^^^^^^
  File "/home/trevea/miniconda3/envs/nlp-rag/lib/python3.12/site-packages/urllib3/util/ssl_.py", line 470, in ssl_wrap_socket
    ssl_sock = _ssl_wrap_socket_impl(sock, context, tls_in_tls, server_hostname)
               ^^^^^^^^^^^^^^^^^^^^^^^^^^^^^^^^^^^^^^^^^^^^^^^^^^^^^^^^^^^^^^^^^
  File "/home/trevea/miniconda3/envs/nlp-rag/lib/python3.12/site-packages/urllib3/util/ssl_.py", line 514, in _ssl_wrap_socket_impl
    return ssl_context.wrap_socket(sock, server_hostname=server_hostname)
           ^^^^^^^^^^^^^^^^^^^^^^^^^^^^^^^^^^^^^^^^^^^^^^^^^^^^^^^^^^^^^^
  File "/home/trevea/miniconda3/envs/nlp-rag/lib/python3.12/ssl.py", line 455, in wrap_socket
    return self.sslsocket_class._create(
           ^^^^^^^^^^^^^^^^^^^^^^^^^^^^^
  File "/home/trevea/miniconda3/envs/nlp-rag/lib/python3.12/ssl.py", line 1046, in _create
    self.do_handshake()
  File "/home/trevea/miniconda3/envs/nlp-rag/lib/python3.12/ssl.py", line 1321, in do_handshake
    self._sslobj.do_handshake()
urllib3.exceptions.ProtocolError: ('Connection aborted.', ConnectionResetError(104, 'Connection reset by peer'))

During handling of the above exception, another exception occurred:

Traceback (most recent call last):
  File "/home/trevea/Projects/ToolsForTheJobBenchmark/generation/Food/openbrewery/api_test.py", line 19, in test_search_breweries
    response = search_breweries('ale')
               ^^^^^^^^^^^^^^^^^^^^^^^
  File "/home/trevea/Projects/ToolsForTheJobBenchmark/generation/Food/openbrewery/api.py", line 52, in search_breweries
    response = requests.get(url, params=params)
               ^^^^^^^^^^^^^^^^^^^^^^^^^^^^^^^^
  File "/home/trevea/miniconda3/envs/nlp-rag/lib/python3.12/site-packages/requests/api.py", line 73, in get
    return request("get", url, params=params, **kwargs)
           ^^^^^^^^^^^^^^^^^^^^^^^^^^^^^^^^^^^^^^^^^^^^
  File "/home/trevea/miniconda3/envs/nlp-rag/lib/python3.12/site-packages/requests/api.py", line 59, in request
    return session.request(method=method, url=url, **kwargs)
           ^^^^^^^^^^^^^^^^^^^^^^^^^^^^^^^^^^^^^^^^^^^^^^^^^
  File "/home/trevea/miniconda3/envs/nlp-rag/lib/python3.12/site-packages/requests/sessions.py", line 589, in request
    resp = self.send(prep, **send_kwargs)
           ^^^^^^^^^^^^^^^^^^^^^^^^^^^^^^
  File "/home/trevea/miniconda3/envs/nlp-rag/lib/python3.12/site-packages/requests/sessions.py", line 703, in send
    r = adapter.send(request, **kwargs)
        ^^^^^^^^^^^^^^^^^^^^^^^^^^^^^^^
  File "/home/trevea/miniconda3/envs/nlp-rag/lib/python3.12/site-packages/requests/adapters.py", line 501, in send
    raise ConnectionError(err, request=request)
requests.exceptions.ConnectionError: ('Connection aborted.', ConnectionResetError(104, 'Connection reset by peer'))

----------------------------------------------------------------------
Ran 6 tests in 0.536s

FAILED (errors=6)
Tests completed for API 'openbrewery'

==================================================

Running tests for API 'whiskyhunter'...
EEEEE
======================================================================
ERROR: test_auction_data (__main__.TestWhiskyHunterAPI.test_auction_data)
----------------------------------------------------------------------
Traceback (most recent call last):
  File "/home/trevea/miniconda3/envs/nlp-rag/lib/python3.12/site-packages/urllib3/connection.py", line 203, in _new_conn
    sock = connection.create_connection(
           ^^^^^^^^^^^^^^^^^^^^^^^^^^^^^
  File "/home/trevea/miniconda3/envs/nlp-rag/lib/python3.12/site-packages/urllib3/util/connection.py", line 60, in create_connection
    for res in socket.getaddrinfo(host, port, family, socket.SOCK_STREAM):
               ^^^^^^^^^^^^^^^^^^^^^^^^^^^^^^^^^^^^^^^^^^^^^^^^^^^^^^^^^^
  File "/home/trevea/miniconda3/envs/nlp-rag/lib/python3.12/socket.py", line 963, in getaddrinfo
    for res in _socket.getaddrinfo(host, port, family, type, proto, flags):
               ^^^^^^^^^^^^^^^^^^^^^^^^^^^^^^^^^^^^^^^^^^^^^^^^^^^^^^^^^^^
socket.gaierror: [Errno -2] Name or service not known

The above exception was the direct cause of the following exception:

Traceback (most recent call last):
  File "/home/trevea/miniconda3/envs/nlp-rag/lib/python3.12/site-packages/urllib3/connectionpool.py", line 790, in urlopen
    response = self._make_request(
               ^^^^^^^^^^^^^^^^^^^
  File "/home/trevea/miniconda3/envs/nlp-rag/lib/python3.12/site-packages/urllib3/connectionpool.py", line 491, in _make_request
    raise new_e
  File "/home/trevea/miniconda3/envs/nlp-rag/lib/python3.12/site-packages/urllib3/connectionpool.py", line 467, in _make_request
    self._validate_conn(conn)
  File "/home/trevea/miniconda3/envs/nlp-rag/lib/python3.12/site-packages/urllib3/connectionpool.py", line 1096, in _validate_conn
    conn.connect()
  File "/home/trevea/miniconda3/envs/nlp-rag/lib/python3.12/site-packages/urllib3/connection.py", line 611, in connect
    self.sock = sock = self._new_conn()
                       ^^^^^^^^^^^^^^^^
  File "/home/trevea/miniconda3/envs/nlp-rag/lib/python3.12/site-packages/urllib3/connection.py", line 210, in _new_conn
    raise NameResolutionError(self.host, self, e) from e
urllib3.exceptions.NameResolutionError: <urllib3.connection.HTTPSConnection object at 0x7fad75914b60>: Failed to resolve 'api.whiskyhunter.net' ([Errno -2] Name or service not known)

The above exception was the direct cause of the following exception:

Traceback (most recent call last):
  File "/home/trevea/miniconda3/envs/nlp-rag/lib/python3.12/site-packages/requests/adapters.py", line 486, in send
    resp = conn.urlopen(
           ^^^^^^^^^^^^^
  File "/home/trevea/miniconda3/envs/nlp-rag/lib/python3.12/site-packages/urllib3/connectionpool.py", line 844, in urlopen
    retries = retries.increment(
              ^^^^^^^^^^^^^^^^^^
  File "/home/trevea/miniconda3/envs/nlp-rag/lib/python3.12/site-packages/urllib3/util/retry.py", line 515, in increment
    raise MaxRetryError(_pool, url, reason) from reason  # type: ignore[arg-type]
    ^^^^^^^^^^^^^^^^^^^^^^^^^^^^^^^^^^^^^^^^^^^^^^^^^^^
urllib3.exceptions.MaxRetryError: HTTPSConnectionPool(host='api.whiskyhunter.net', port=443): Max retries exceeded with url: /api/auction_data/catawiki/ (Caused by NameResolutionError("<urllib3.connection.HTTPSConnection object at 0x7fad75914b60>: Failed to resolve 'api.whiskyhunter.net' ([Errno -2] Name or service not known)"))

During handling of the above exception, another exception occurred:

Traceback (most recent call last):
  File "/home/trevea/Projects/ToolsForTheJobBenchmark/generation/Food/whiskyhunter/api_test.py", line 7, in test_auction_data
    response = auction_data(slug='catawiki')
               ^^^^^^^^^^^^^^^^^^^^^^^^^^^^^
  File "/home/trevea/Projects/ToolsForTheJobBenchmark/generation/Food/whiskyhunter/api.py", line 15, in auction_data
    response = requests.get(url, headers=headers)
               ^^^^^^^^^^^^^^^^^^^^^^^^^^^^^^^^^^
  File "/home/trevea/miniconda3/envs/nlp-rag/lib/python3.12/site-packages/requests/api.py", line 73, in get
    return request("get", url, params=params, **kwargs)
           ^^^^^^^^^^^^^^^^^^^^^^^^^^^^^^^^^^^^^^^^^^^^
  File "/home/trevea/miniconda3/envs/nlp-rag/lib/python3.12/site-packages/requests/api.py", line 59, in request
    return session.request(method=method, url=url, **kwargs)
           ^^^^^^^^^^^^^^^^^^^^^^^^^^^^^^^^^^^^^^^^^^^^^^^^^
  File "/home/trevea/miniconda3/envs/nlp-rag/lib/python3.12/site-packages/requests/sessions.py", line 589, in request
    resp = self.send(prep, **send_kwargs)
           ^^^^^^^^^^^^^^^^^^^^^^^^^^^^^^
  File "/home/trevea/miniconda3/envs/nlp-rag/lib/python3.12/site-packages/requests/sessions.py", line 703, in send
    r = adapter.send(request, **kwargs)
        ^^^^^^^^^^^^^^^^^^^^^^^^^^^^^^^
  File "/home/trevea/miniconda3/envs/nlp-rag/lib/python3.12/site-packages/requests/adapters.py", line 519, in send
    raise ConnectionError(e, request=request)
requests.exceptions.ConnectionError: HTTPSConnectionPool(host='api.whiskyhunter.net', port=443): Max retries exceeded with url: /api/auction_data/catawiki/ (Caused by NameResolutionError("<urllib3.connection.HTTPSConnection object at 0x7fad75914b60>: Failed to resolve 'api.whiskyhunter.net' ([Errno -2] Name or service not known)"))

======================================================================
ERROR: test_auctions_data (__main__.TestWhiskyHunterAPI.test_auctions_data)
----------------------------------------------------------------------
Traceback (most recent call last):
  File "/home/trevea/miniconda3/envs/nlp-rag/lib/python3.12/site-packages/urllib3/connection.py", line 203, in _new_conn
    sock = connection.create_connection(
           ^^^^^^^^^^^^^^^^^^^^^^^^^^^^^
  File "/home/trevea/miniconda3/envs/nlp-rag/lib/python3.12/site-packages/urllib3/util/connection.py", line 60, in create_connection
    for res in socket.getaddrinfo(host, port, family, socket.SOCK_STREAM):
               ^^^^^^^^^^^^^^^^^^^^^^^^^^^^^^^^^^^^^^^^^^^^^^^^^^^^^^^^^^
  File "/home/trevea/miniconda3/envs/nlp-rag/lib/python3.12/socket.py", line 963, in getaddrinfo
    for res in _socket.getaddrinfo(host, port, family, type, proto, flags):
               ^^^^^^^^^^^^^^^^^^^^^^^^^^^^^^^^^^^^^^^^^^^^^^^^^^^^^^^^^^^
socket.gaierror: [Errno -2] Name or service not known

The above exception was the direct cause of the following exception:

Traceback (most recent call last):
  File "/home/trevea/miniconda3/envs/nlp-rag/lib/python3.12/site-packages/urllib3/connectionpool.py", line 790, in urlopen
    response = self._make_request(
               ^^^^^^^^^^^^^^^^^^^
  File "/home/trevea/miniconda3/envs/nlp-rag/lib/python3.12/site-packages/urllib3/connectionpool.py", line 491, in _make_request
    raise new_e
  File "/home/trevea/miniconda3/envs/nlp-rag/lib/python3.12/site-packages/urllib3/connectionpool.py", line 467, in _make_request
    self._validate_conn(conn)
  File "/home/trevea/miniconda3/envs/nlp-rag/lib/python3.12/site-packages/urllib3/connectionpool.py", line 1096, in _validate_conn
    conn.connect()
  File "/home/trevea/miniconda3/envs/nlp-rag/lib/python3.12/site-packages/urllib3/connection.py", line 611, in connect
    self.sock = sock = self._new_conn()
                       ^^^^^^^^^^^^^^^^
  File "/home/trevea/miniconda3/envs/nlp-rag/lib/python3.12/site-packages/urllib3/connection.py", line 210, in _new_conn
    raise NameResolutionError(self.host, self, e) from e
urllib3.exceptions.NameResolutionError: <urllib3.connection.HTTPSConnection object at 0x7fad75914d40>: Failed to resolve 'api.whiskyhunter.net' ([Errno -2] Name or service not known)

The above exception was the direct cause of the following exception:

Traceback (most recent call last):
  File "/home/trevea/miniconda3/envs/nlp-rag/lib/python3.12/site-packages/requests/adapters.py", line 486, in send
    resp = conn.urlopen(
           ^^^^^^^^^^^^^
  File "/home/trevea/miniconda3/envs/nlp-rag/lib/python3.12/site-packages/urllib3/connectionpool.py", line 844, in urlopen
    retries = retries.increment(
              ^^^^^^^^^^^^^^^^^^
  File "/home/trevea/miniconda3/envs/nlp-rag/lib/python3.12/site-packages/urllib3/util/retry.py", line 515, in increment
    raise MaxRetryError(_pool, url, reason) from reason  # type: ignore[arg-type]
    ^^^^^^^^^^^^^^^^^^^^^^^^^^^^^^^^^^^^^^^^^^^^^^^^^^^
urllib3.exceptions.MaxRetryError: HTTPSConnectionPool(host='api.whiskyhunter.net', port=443): Max retries exceeded with url: /api/auctions_data/ (Caused by NameResolutionError("<urllib3.connection.HTTPSConnection object at 0x7fad75914d40>: Failed to resolve 'api.whiskyhunter.net' ([Errno -2] Name or service not known)"))

During handling of the above exception, another exception occurred:

Traceback (most recent call last):
  File "/home/trevea/Projects/ToolsForTheJobBenchmark/generation/Food/whiskyhunter/api_test.py", line 11, in test_auctions_data
    response = auctions_data()
               ^^^^^^^^^^^^^^^
  File "/home/trevea/Projects/ToolsForTheJobBenchmark/generation/Food/whiskyhunter/api.py", line 30, in auctions_data
    response = requests.get(url, headers=headers)
               ^^^^^^^^^^^^^^^^^^^^^^^^^^^^^^^^^^
  File "/home/trevea/miniconda3/envs/nlp-rag/lib/python3.12/site-packages/requests/api.py", line 73, in get
    return request("get", url, params=params, **kwargs)
           ^^^^^^^^^^^^^^^^^^^^^^^^^^^^^^^^^^^^^^^^^^^^
  File "/home/trevea/miniconda3/envs/nlp-rag/lib/python3.12/site-packages/requests/api.py", line 59, in request
    return session.request(method=method, url=url, **kwargs)
           ^^^^^^^^^^^^^^^^^^^^^^^^^^^^^^^^^^^^^^^^^^^^^^^^^
  File "/home/trevea/miniconda3/envs/nlp-rag/lib/python3.12/site-packages/requests/sessions.py", line 589, in request
    resp = self.send(prep, **send_kwargs)
           ^^^^^^^^^^^^^^^^^^^^^^^^^^^^^^
  File "/home/trevea/miniconda3/envs/nlp-rag/lib/python3.12/site-packages/requests/sessions.py", line 703, in send
    r = adapter.send(request, **kwargs)
        ^^^^^^^^^^^^^^^^^^^^^^^^^^^^^^^
  File "/home/trevea/miniconda3/envs/nlp-rag/lib/python3.12/site-packages/requests/adapters.py", line 519, in send
    raise ConnectionError(e, request=request)
requests.exceptions.ConnectionError: HTTPSConnectionPool(host='api.whiskyhunter.net', port=443): Max retries exceeded with url: /api/auctions_data/ (Caused by NameResolutionError("<urllib3.connection.HTTPSConnection object at 0x7fad75914d40>: Failed to resolve 'api.whiskyhunter.net' ([Errno -2] Name or service not known)"))

======================================================================
ERROR: test_auctions_info (__main__.TestWhiskyHunterAPI.test_auctions_info)
----------------------------------------------------------------------
Traceback (most recent call last):
  File "/home/trevea/miniconda3/envs/nlp-rag/lib/python3.12/site-packages/urllib3/connection.py", line 203, in _new_conn
    sock = connection.create_connection(
           ^^^^^^^^^^^^^^^^^^^^^^^^^^^^^
  File "/home/trevea/miniconda3/envs/nlp-rag/lib/python3.12/site-packages/urllib3/util/connection.py", line 60, in create_connection
    for res in socket.getaddrinfo(host, port, family, socket.SOCK_STREAM):
               ^^^^^^^^^^^^^^^^^^^^^^^^^^^^^^^^^^^^^^^^^^^^^^^^^^^^^^^^^^
  File "/home/trevea/miniconda3/envs/nlp-rag/lib/python3.12/socket.py", line 963, in getaddrinfo
    for res in _socket.getaddrinfo(host, port, family, type, proto, flags):
               ^^^^^^^^^^^^^^^^^^^^^^^^^^^^^^^^^^^^^^^^^^^^^^^^^^^^^^^^^^^
socket.gaierror: [Errno -2] Name or service not known

The above exception was the direct cause of the following exception:

Traceback (most recent call last):
  File "/home/trevea/miniconda3/envs/nlp-rag/lib/python3.12/site-packages/urllib3/connectionpool.py", line 790, in urlopen
    response = self._make_request(
               ^^^^^^^^^^^^^^^^^^^
  File "/home/trevea/miniconda3/envs/nlp-rag/lib/python3.12/site-packages/urllib3/connectionpool.py", line 491, in _make_request
    raise new_e
  File "/home/trevea/miniconda3/envs/nlp-rag/lib/python3.12/site-packages/urllib3/connectionpool.py", line 467, in _make_request
    self._validate_conn(conn)
  File "/home/trevea/miniconda3/envs/nlp-rag/lib/python3.12/site-packages/urllib3/connectionpool.py", line 1096, in _validate_conn
    conn.connect()
  File "/home/trevea/miniconda3/envs/nlp-rag/lib/python3.12/site-packages/urllib3/connection.py", line 611, in connect
    self.sock = sock = self._new_conn()
                       ^^^^^^^^^^^^^^^^
  File "/home/trevea/miniconda3/envs/nlp-rag/lib/python3.12/site-packages/urllib3/connection.py", line 210, in _new_conn
    raise NameResolutionError(self.host, self, e) from e
urllib3.exceptions.NameResolutionError: <urllib3.connection.HTTPSConnection object at 0x7fad75915d60>: Failed to resolve 'api.whiskyhunter.net' ([Errno -2] Name or service not known)

The above exception was the direct cause of the following exception:

Traceback (most recent call last):
  File "/home/trevea/miniconda3/envs/nlp-rag/lib/python3.12/site-packages/requests/adapters.py", line 486, in send
    resp = conn.urlopen(
           ^^^^^^^^^^^^^
  File "/home/trevea/miniconda3/envs/nlp-rag/lib/python3.12/site-packages/urllib3/connectionpool.py", line 844, in urlopen
    retries = retries.increment(
              ^^^^^^^^^^^^^^^^^^
  File "/home/trevea/miniconda3/envs/nlp-rag/lib/python3.12/site-packages/urllib3/util/retry.py", line 515, in increment
    raise MaxRetryError(_pool, url, reason) from reason  # type: ignore[arg-type]
    ^^^^^^^^^^^^^^^^^^^^^^^^^^^^^^^^^^^^^^^^^^^^^^^^^^^
urllib3.exceptions.MaxRetryError: HTTPSConnectionPool(host='api.whiskyhunter.net', port=443): Max retries exceeded with url: /api/auctions_info/ (Caused by NameResolutionError("<urllib3.connection.HTTPSConnection object at 0x7fad75915d60>: Failed to resolve 'api.whiskyhunter.net' ([Errno -2] Name or service not known)"))

During handling of the above exception, another exception occurred:

Traceback (most recent call last):
  File "/home/trevea/Projects/ToolsForTheJobBenchmark/generation/Food/whiskyhunter/api_test.py", line 15, in test_auctions_info
    response = auctions_info()
               ^^^^^^^^^^^^^^^
  File "/home/trevea/Projects/ToolsForTheJobBenchmark/generation/Food/whiskyhunter/api.py", line 45, in auctions_info
    response = requests.get(url, headers=headers)
               ^^^^^^^^^^^^^^^^^^^^^^^^^^^^^^^^^^
  File "/home/trevea/miniconda3/envs/nlp-rag/lib/python3.12/site-packages/requests/api.py", line 73, in get
    return request("get", url, params=params, **kwargs)
           ^^^^^^^^^^^^^^^^^^^^^^^^^^^^^^^^^^^^^^^^^^^^
  File "/home/trevea/miniconda3/envs/nlp-rag/lib/python3.12/site-packages/requests/api.py", line 59, in request
    return session.request(method=method, url=url, **kwargs)
           ^^^^^^^^^^^^^^^^^^^^^^^^^^^^^^^^^^^^^^^^^^^^^^^^^
  File "/home/trevea/miniconda3/envs/nlp-rag/lib/python3.12/site-packages/requests/sessions.py", line 589, in request
    resp = self.send(prep, **send_kwargs)
           ^^^^^^^^^^^^^^^^^^^^^^^^^^^^^^
  File "/home/trevea/miniconda3/envs/nlp-rag/lib/python3.12/site-packages/requests/sessions.py", line 703, in send
    r = adapter.send(request, **kwargs)
        ^^^^^^^^^^^^^^^^^^^^^^^^^^^^^^^
  File "/home/trevea/miniconda3/envs/nlp-rag/lib/python3.12/site-packages/requests/adapters.py", line 519, in send
    raise ConnectionError(e, request=request)
requests.exceptions.ConnectionError: HTTPSConnectionPool(host='api.whiskyhunter.net', port=443): Max retries exceeded with url: /api/auctions_info/ (Caused by NameResolutionError("<urllib3.connection.HTTPSConnection object at 0x7fad75915d60>: Failed to resolve 'api.whiskyhunter.net' ([Errno -2] Name or service not known)"))

======================================================================
ERROR: test_distilleries_info (__main__.TestWhiskyHunterAPI.test_distilleries_info)
----------------------------------------------------------------------
Traceback (most recent call last):
  File "/home/trevea/miniconda3/envs/nlp-rag/lib/python3.12/site-packages/urllib3/connection.py", line 203, in _new_conn
    sock = connection.create_connection(
           ^^^^^^^^^^^^^^^^^^^^^^^^^^^^^
  File "/home/trevea/miniconda3/envs/nlp-rag/lib/python3.12/site-packages/urllib3/util/connection.py", line 60, in create_connection
    for res in socket.getaddrinfo(host, port, family, socket.SOCK_STREAM):
               ^^^^^^^^^^^^^^^^^^^^^^^^^^^^^^^^^^^^^^^^^^^^^^^^^^^^^^^^^^
  File "/home/trevea/miniconda3/envs/nlp-rag/lib/python3.12/socket.py", line 963, in getaddrinfo
    for res in _socket.getaddrinfo(host, port, family, type, proto, flags):
               ^^^^^^^^^^^^^^^^^^^^^^^^^^^^^^^^^^^^^^^^^^^^^^^^^^^^^^^^^^^
socket.gaierror: [Errno -2] Name or service not known

The above exception was the direct cause of the following exception:

Traceback (most recent call last):
  File "/home/trevea/miniconda3/envs/nlp-rag/lib/python3.12/site-packages/urllib3/connectionpool.py", line 790, in urlopen
    response = self._make_request(
               ^^^^^^^^^^^^^^^^^^^
  File "/home/trevea/miniconda3/envs/nlp-rag/lib/python3.12/site-packages/urllib3/connectionpool.py", line 491, in _make_request
    raise new_e
  File "/home/trevea/miniconda3/envs/nlp-rag/lib/python3.12/site-packages/urllib3/connectionpool.py", line 467, in _make_request
    self._validate_conn(conn)
  File "/home/trevea/miniconda3/envs/nlp-rag/lib/python3.12/site-packages/urllib3/connectionpool.py", line 1096, in _validate_conn
    conn.connect()
  File "/home/trevea/miniconda3/envs/nlp-rag/lib/python3.12/site-packages/urllib3/connection.py", line 611, in connect
    self.sock = sock = self._new_conn()
                       ^^^^^^^^^^^^^^^^
  File "/home/trevea/miniconda3/envs/nlp-rag/lib/python3.12/site-packages/urllib3/connection.py", line 210, in _new_conn
    raise NameResolutionError(self.host, self, e) from e
urllib3.exceptions.NameResolutionError: <urllib3.connection.HTTPSConnection object at 0x7fad75916540>: Failed to resolve 'api.whiskyhunter.net' ([Errno -2] Name or service not known)

The above exception was the direct cause of the following exception:

Traceback (most recent call last):
  File "/home/trevea/miniconda3/envs/nlp-rag/lib/python3.12/site-packages/requests/adapters.py", line 486, in send
    resp = conn.urlopen(
           ^^^^^^^^^^^^^
  File "/home/trevea/miniconda3/envs/nlp-rag/lib/python3.12/site-packages/urllib3/connectionpool.py", line 844, in urlopen
    retries = retries.increment(
              ^^^^^^^^^^^^^^^^^^
  File "/home/trevea/miniconda3/envs/nlp-rag/lib/python3.12/site-packages/urllib3/util/retry.py", line 515, in increment
    raise MaxRetryError(_pool, url, reason) from reason  # type: ignore[arg-type]
    ^^^^^^^^^^^^^^^^^^^^^^^^^^^^^^^^^^^^^^^^^^^^^^^^^^^
urllib3.exceptions.MaxRetryError: HTTPSConnectionPool(host='api.whiskyhunter.net', port=443): Max retries exceeded with url: /api/distilleries_info/ (Caused by NameResolutionError("<urllib3.connection.HTTPSConnection object at 0x7fad75916540>: Failed to resolve 'api.whiskyhunter.net' ([Errno -2] Name or service not known)"))

During handling of the above exception, another exception occurred:

Traceback (most recent call last):
  File "/home/trevea/Projects/ToolsForTheJobBenchmark/generation/Food/whiskyhunter/api_test.py", line 19, in test_distilleries_info
    response = distilleries_info()
               ^^^^^^^^^^^^^^^^^^^
  File "/home/trevea/Projects/ToolsForTheJobBenchmark/generation/Food/whiskyhunter/api.py", line 60, in distilleries_info
    response = requests.get(url, headers=headers)
               ^^^^^^^^^^^^^^^^^^^^^^^^^^^^^^^^^^
  File "/home/trevea/miniconda3/envs/nlp-rag/lib/python3.12/site-packages/requests/api.py", line 73, in get
    return request("get", url, params=params, **kwargs)
           ^^^^^^^^^^^^^^^^^^^^^^^^^^^^^^^^^^^^^^^^^^^^
  File "/home/trevea/miniconda3/envs/nlp-rag/lib/python3.12/site-packages/requests/api.py", line 59, in request
    return session.request(method=method, url=url, **kwargs)
           ^^^^^^^^^^^^^^^^^^^^^^^^^^^^^^^^^^^^^^^^^^^^^^^^^
  File "/home/trevea/miniconda3/envs/nlp-rag/lib/python3.12/site-packages/requests/sessions.py", line 589, in request
    resp = self.send(prep, **send_kwargs)
           ^^^^^^^^^^^^^^^^^^^^^^^^^^^^^^
  File "/home/trevea/miniconda3/envs/nlp-rag/lib/python3.12/site-packages/requests/sessions.py", line 703, in send
    r = adapter.send(request, **kwargs)
        ^^^^^^^^^^^^^^^^^^^^^^^^^^^^^^^
  File "/home/trevea/miniconda3/envs/nlp-rag/lib/python3.12/site-packages/requests/adapters.py", line 519, in send
    raise ConnectionError(e, request=request)
requests.exceptions.ConnectionError: HTTPSConnectionPool(host='api.whiskyhunter.net', port=443): Max retries exceeded with url: /api/distilleries_info/ (Caused by NameResolutionError("<urllib3.connection.HTTPSConnection object at 0x7fad75916540>: Failed to resolve 'api.whiskyhunter.net' ([Errno -2] Name or service not known)"))

======================================================================
ERROR: test_distillery_data (__main__.TestWhiskyHunterAPI.test_distillery_data)
----------------------------------------------------------------------
Traceback (most recent call last):
  File "/home/trevea/miniconda3/envs/nlp-rag/lib/python3.12/site-packages/urllib3/connection.py", line 203, in _new_conn
    sock = connection.create_connection(
           ^^^^^^^^^^^^^^^^^^^^^^^^^^^^^
  File "/home/trevea/miniconda3/envs/nlp-rag/lib/python3.12/site-packages/urllib3/util/connection.py", line 60, in create_connection
    for res in socket.getaddrinfo(host, port, family, socket.SOCK_STREAM):
               ^^^^^^^^^^^^^^^^^^^^^^^^^^^^^^^^^^^^^^^^^^^^^^^^^^^^^^^^^^
  File "/home/trevea/miniconda3/envs/nlp-rag/lib/python3.12/socket.py", line 963, in getaddrinfo
    for res in _socket.getaddrinfo(host, port, family, type, proto, flags):
               ^^^^^^^^^^^^^^^^^^^^^^^^^^^^^^^^^^^^^^^^^^^^^^^^^^^^^^^^^^^
socket.gaierror: [Errno -2] Name or service not known

The above exception was the direct cause of the following exception:

Traceback (most recent call last):
  File "/home/trevea/miniconda3/envs/nlp-rag/lib/python3.12/site-packages/urllib3/connectionpool.py", line 790, in urlopen
    response = self._make_request(
               ^^^^^^^^^^^^^^^^^^^
  File "/home/trevea/miniconda3/envs/nlp-rag/lib/python3.12/site-packages/urllib3/connectionpool.py", line 491, in _make_request
    raise new_e
  File "/home/trevea/miniconda3/envs/nlp-rag/lib/python3.12/site-packages/urllib3/connectionpool.py", line 467, in _make_request
    self._validate_conn(conn)
  File "/home/trevea/miniconda3/envs/nlp-rag/lib/python3.12/site-packages/urllib3/connectionpool.py", line 1096, in _validate_conn
    conn.connect()
  File "/home/trevea/miniconda3/envs/nlp-rag/lib/python3.12/site-packages/urllib3/connection.py", line 611, in connect
    self.sock = sock = self._new_conn()
                       ^^^^^^^^^^^^^^^^
  File "/home/trevea/miniconda3/envs/nlp-rag/lib/python3.12/site-packages/urllib3/connection.py", line 210, in _new_conn
    raise NameResolutionError(self.host, self, e) from e
urllib3.exceptions.NameResolutionError: <urllib3.connection.HTTPSConnection object at 0x7fad760862a0>: Failed to resolve 'api.whiskyhunter.net' ([Errno -2] Name or service not known)

The above exception was the direct cause of the following exception:

Traceback (most recent call last):
  File "/home/trevea/miniconda3/envs/nlp-rag/lib/python3.12/site-packages/requests/adapters.py", line 486, in send
    resp = conn.urlopen(
           ^^^^^^^^^^^^^
  File "/home/trevea/miniconda3/envs/nlp-rag/lib/python3.12/site-packages/urllib3/connectionpool.py", line 844, in urlopen
    retries = retries.increment(
              ^^^^^^^^^^^^^^^^^^
  File "/home/trevea/miniconda3/envs/nlp-rag/lib/python3.12/site-packages/urllib3/util/retry.py", line 515, in increment
    raise MaxRetryError(_pool, url, reason) from reason  # type: ignore[arg-type]
    ^^^^^^^^^^^^^^^^^^^^^^^^^^^^^^^^^^^^^^^^^^^^^^^^^^^
urllib3.exceptions.MaxRetryError: HTTPSConnectionPool(host='api.whiskyhunter.net', port=443): Max retries exceeded with url: /api/distillery_data/ardbeg/ (Caused by NameResolutionError("<urllib3.connection.HTTPSConnection object at 0x7fad760862a0>: Failed to resolve 'api.whiskyhunter.net' ([Errno -2] Name or service not known)"))

During handling of the above exception, another exception occurred:

Traceback (most recent call last):
  File "/home/trevea/Projects/ToolsForTheJobBenchmark/generation/Food/whiskyhunter/api_test.py", line 23, in test_distillery_data
    response = distillery_data(slug='ardbeg')
               ^^^^^^^^^^^^^^^^^^^^^^^^^^^^^^
  File "/home/trevea/Projects/ToolsForTheJobBenchmark/generation/Food/whiskyhunter/api.py", line 77, in distillery_data
    response = requests.get(url, headers=headers)
               ^^^^^^^^^^^^^^^^^^^^^^^^^^^^^^^^^^
  File "/home/trevea/miniconda3/envs/nlp-rag/lib/python3.12/site-packages/requests/api.py", line 73, in get
    return request("get", url, params=params, **kwargs)
           ^^^^^^^^^^^^^^^^^^^^^^^^^^^^^^^^^^^^^^^^^^^^
  File "/home/trevea/miniconda3/envs/nlp-rag/lib/python3.12/site-packages/requests/api.py", line 59, in request
    return session.request(method=method, url=url, **kwargs)
           ^^^^^^^^^^^^^^^^^^^^^^^^^^^^^^^^^^^^^^^^^^^^^^^^^
  File "/home/trevea/miniconda3/envs/nlp-rag/lib/python3.12/site-packages/requests/sessions.py", line 589, in request
    resp = self.send(prep, **send_kwargs)
           ^^^^^^^^^^^^^^^^^^^^^^^^^^^^^^
  File "/home/trevea/miniconda3/envs/nlp-rag/lib/python3.12/site-packages/requests/sessions.py", line 703, in send
    r = adapter.send(request, **kwargs)
        ^^^^^^^^^^^^^^^^^^^^^^^^^^^^^^^
  File "/home/trevea/miniconda3/envs/nlp-rag/lib/python3.12/site-packages/requests/adapters.py", line 519, in send
    raise ConnectionError(e, request=request)
requests.exceptions.ConnectionError: HTTPSConnectionPool(host='api.whiskyhunter.net', port=443): Max retries exceeded with url: /api/distillery_data/ardbeg/ (Caused by NameResolutionError("<urllib3.connection.HTTPSConnection object at 0x7fad760862a0>: Failed to resolve 'api.whiskyhunter.net' ([Errno -2] Name or service not known)"))

----------------------------------------------------------------------
Ran 5 tests in 0.285s

FAILED (errors=5)
Tests completed for API 'whiskyhunter'

==================================================

Running tests for API 'openfoodfacts'...
.Tests completed for API 'openfoodfacts'

==================================================

.
----------------------------------------------------------------------
Ran 2 tests in 2.030s

OK
