Running tests for API 'adviceslip'...
Tests completed for API 'adviceslip'

==================================================

python3: can't open file '/home/trevea/Projects/ToolsForTheJobBenchmark/generation/Inspiration/adviceslip/api_test.py': [Errno 2] No such file or directory
Running tests for API 'kanye'...
.
----------------------------------------------------------------------
Ran 1 test in 0.280s

OK
Tests completed for API 'kanye'

==================================================

Running tests for API 'breakingbad'...
..
----------------------------------------------------------------------
Ran 2 tests in 1.034s

OK
Tests completed for API 'breakingbad'

==================================================

Running tests for API 'quotesondesign'...
.
----------------------------------------------------------------------
Ran 1 test in 0.303s

OK
Tests completed for API 'quotesondesign'

==================================================

Running tests for API 'ronswanson'...
...
----------------------------------------------------------------------
Ran 3 tests in 1.040s

OK
Tests completed for API 'ronswanson'

==================================================

Running tests for API 'quotable'...
FF....F..
======================================================================
FAIL: test_get_author_by_slug (__main__.TestQuotableAPI.test_get_author_by_slug)
----------------------------------------------------------------------
Traceback (most recent call last):
  File "/home/trevea/Projects/ToolsForTheJobBenchmark/generation/Inspiration/quotable/api_test.py", line 45, in test_get_author_by_slug
    self.assertIn('name', response)
AssertionError: 'name' not found in {'statusCode': 404, 'statusMessage': 'The requested resource could not be found'}

======================================================================
FAIL: test_get_quote_by_id (__main__.TestQuotableAPI.test_get_quote_by_id)
----------------------------------------------------------------------
Traceback (most recent call last):
  File "/home/trevea/Projects/ToolsForTheJobBenchmark/generation/Inspiration/quotable/api_test.py", line 26, in test_get_quote_by_id
    self.assertIn('content', response)
AssertionError: 'content' not found in {'statusCode': 404, 'statusMessage': 'The requested resource could not be found'}

======================================================================
FAIL: test_list_tags (__main__.TestQuotableAPI.test_list_tags)
----------------------------------------------------------------------
Traceback (most recent call last):
  File "/home/trevea/Projects/ToolsForTheJobBenchmark/generation/Inspiration/quotable/api_test.py", line 49, in test_list_tags
    self.assertIn('results', response)
AssertionError: 'results' not found in [{'_id': 'PIyOMHYqPd', 'name': 'Age', 'slug': 'age', 'quoteCount': 1, 'dateAdded': '2023-04-14', 'dateModified': '2023-04-14'}, {'_id': 'qTFouZDPBZz', 'name': 'Athletics', 'slug': 'athletics', 'quoteCount': 0, 'dateAdded': '2022-07-06', 'dateModified': '2023-04-14'}, {'_id': 'M83oc3scg', 'name': 'Business', 'slug': 'business', 'quoteCount': 31, 'dateAdded': '2019-08-03', 'dateModified': '2023-04-14'}, {'_id': 'QmvdN2qkQCC', 'name': 'Change', 'slug': 'change', 'quoteCount': 34, 'dateAdded': '2022-03-12', 'dateModified': '2023-04-14'}, {'_id': 'vWfmIQt6k8c', 'name': 'Character', 'slug': 'character', 'quoteCount': 17, 'dateAdded': '2022-03-12', 'dateModified': '2023-04-14'}, {'_id': 'JaQwywHSk59', 'name': 'Competition', 'slug': 'competition', 'quoteCount': 38, 'dateAdded': '2022-07-06', 'dateModified': '2023-04-14'}, {'_id': 'AjxQFSPEylb', 'name': 'Conservative', 'slug': 'conservative', 'quoteCount': 1, 'dateAdded': '2022-03-12', 'dateModified': '2023-04-14'}, {'_id': 'Ipw2-EcInZg', 'name': 'Courage', 'slug': 'courage', 'quoteCount': 2, 'dateAdded': '2022-03-12', 'dateModified': '2023-04-14'}, {'_id': 'aLWQOIYpeMz', 'name': 'Creativity', 'slug': 'creativity', 'quoteCount': 1, 'dateAdded': '2023-04-14', 'dateModified': '2023-04-14'}, {'_id': 'kqzFRe-4V4', 'name': 'Education', 'slug': 'education', 'quoteCount': 7, 'dateAdded': '2019-03-17', 'dateModified': '2023-04-14'}, {'_id': 'jl_H9UVXhGb', 'name': 'Ethics', 'slug': 'ethics', 'quoteCount': 1, 'dateAdded': '2023-04-06', 'dateModified': '2023-04-14'}, {'_id': 'gElqvJIRz0h', 'name': 'Failure', 'slug': 'failure', 'quoteCount': 1, 'dateAdded': '2023-04-14', 'dateModified': '2023-04-14'}, {'_id': '-7GEUrC5r', 'name': 'Faith', 'slug': 'faith', 'quoteCount': 4, 'dateAdded': '2019-09-13', 'dateModified': '2023-04-14'}, {'_id': 'r437PEqVZx5', 'name': 'Family', 'slug': 'family', 'quoteCount': 2, 'dateAdded': '2022-03-12', 'dateModified': '2023-04-14'}, {'_id': 'fvpORe-t', 'name': 'Famous Quotes', 'slug': 'famous-quotes', 'quoteCount': 1090, 'dateAdded': '2019-07-23', 'dateModified': '2023-04-14'}, {'_id': 'HJ05xaA6gN', 'name': 'Film', 'slug': 'film', 'quoteCount': 13, 'dateAdded': '2022-07-04', 'dateModified': '2023-04-14'}, {'_id': 'QuBdKRcjNsO', 'name': 'Freedom', 'slug': 'freedom', 'quoteCount': 9, 'dateAdded': '2022-03-12', 'dateModified': '2023-04-14'}, {'_id': 'krXU-q4FE', 'name': 'Friendship', 'slug': 'friendship', 'quoteCount': 189, 'dateAdded': '2019-03-15', 'dateModified': '2023-04-14'}, {'_id': 'OMnUd1CUg', 'name': 'Future', 'slug': 'future', 'quoteCount': 21, 'dateAdded': '2019-02-17', 'dateModified': '2023-04-14'}, {'_id': 'i_OFrgCiQ4', 'name': 'Generosity', 'slug': 'generosity', 'quoteCount': 1, 'dateAdded': '2023-04-14', 'dateModified': '2023-04-14'}, {'_id': 'L09SJrfjY8s', 'name': 'Genius', 'slug': 'genius', 'quoteCount': 1, 'dateAdded': '2023-04-14', 'dateModified': '2023-04-14'}, {'_id': 'S9OYJZlyu5', 'name': 'Gratitude', 'slug': 'gratitude', 'quoteCount': 1, 'dateAdded': '2023-04-14', 'dateModified': '2023-04-14'}, {'_id': 'k97A51Uf5', 'name': 'Happiness', 'slug': 'happiness', 'quoteCount': 18, 'dateAdded': '2019-06-27', 'dateModified': '2023-04-14'}, {'_id': 'kv9zk8WIqaq', 'name': 'Health', 'slug': 'health', 'quoteCount': 1, 'dateAdded': '2023-04-14', 'dateModified': '2023-04-14'}, {'_id': 'KBWnDu4rH', 'name': 'History', 'slug': 'history', 'quoteCount': 18, 'dateAdded': '2021-01-30', 'dateModified': '2023-04-14'}, {'_id': 'uCLiEwnwh', 'name': 'Honor', 'slug': 'honor', 'quoteCount': 6, 'dateAdded': '2022-07-04', 'dateModified': '2023-04-14'}, {'_id': 'uki-krBKTB_', 'name': 'Humor', 'slug': 'humor', 'quoteCount': 0, 'dateAdded': '2022-03-12', 'dateModified': '2023-04-14'}, {'_id': 'HJp_e1usX', 'name': 'Humorous', 'slug': 'humorous', 'quoteCount': 17, 'dateAdded': '2022-07-08', 'dateModified': '2023-04-14'}, {'_id': 'eghR-r-OzL9', 'name': 'Imagination', 'slug': 'imagination', 'quoteCount': 2, 'dateAdded': '2023-04-06', 'dateModified': '2023-04-14'}, {'_id': 'JCMoLDds9', 'name': 'Inspirational', 'slug': 'inspirational', 'quoteCount': 89, 'dateAdded': '2020-01-27', 'dateModified': '2023-04-14'}, {'_id': 'v9QUFHDZPT3', 'name': 'Knowledge', 'slug': 'knowledge', 'quoteCount': 3, 'dateAdded': '2023-04-06', 'dateModified': '2023-04-14'}, {'_id': 'V60a195td', 'name': 'Leadership', 'slug': 'leadership', 'quoteCount': 1, 'dateAdded': '2022-07-04', 'dateModified': '2023-04-14'}, {'_id': 'poT-7QEBm', 'name': 'Life', 'slug': 'life', 'quoteCount': 42, 'dateAdded': '2020-09-09', 'dateModified': '2023-04-14'}, {'_id': '3n-gucf_OB', 'name': 'Literature', 'slug': 'literature', 'quoteCount': 1, 'dateAdded': '2020-03-01', 'dateModified': '2023-04-14'}, {'_id': 'rnrd8q9X1', 'name': 'Love', 'slug': 'love', 'quoteCount': 20, 'dateAdded': '2020-02-27', 'dateModified': '2023-04-14'}, {'_id': 's19tg5r8EM-', 'name': 'Mathematics', 'slug': 'mathematics', 'quoteCount': 1, 'dateAdded': '2023-04-06', 'dateModified': '2023-04-14'}, {'_id': 'CaE-vzeOZb', 'name': 'Motivational', 'slug': 'motivational', 'quoteCount': 32, 'dateAdded': '2022-07-04', 'dateModified': '2023-04-14'}, {'_id': 'vmVZQ72P_', 'name': 'Nature', 'slug': 'nature', 'quoteCount': 2, 'dateAdded': '2020-12-10', 'dateModified': '2023-04-14'}, {'_id': 'pnLPcXTs_S', 'name': 'Opportunity', 'slug': 'opportunity', 'quoteCount': 1, 'dateAdded': '2023-04-14', 'dateModified': '2023-04-14'}, {'_id': 'q8kOLaefsZM', 'name': 'Pain', 'slug': 'pain', 'quoteCount': 1, 'dateAdded': '2022-03-12', 'dateModified': '2023-04-14'}, {'_id': 'GaQEsvfbYYd', 'name': 'Perseverance', 'slug': 'perseverance', 'quoteCount': 2, 'dateAdded': '2023-04-14', 'dateModified': '2023-04-14'}, {'_id': 'mh6HEhK_T_a', 'name': 'Philosophy', 'slug': 'philosophy', 'quoteCount': 16, 'dateAdded': '2022-03-12', 'dateModified': '2023-04-14'}, {'_id': '96NNdxeI_', 'name': 'Politics', 'slug': 'politics', 'quoteCount': 15, 'dateAdded': '2020-04-02', 'dateModified': '2023-04-14'}, {'_id': 'MbsuUl67N3', 'name': 'Power Quotes', 'slug': 'power-quotes', 'quoteCount': 2, 'dateAdded': '2022-07-04', 'dateModified': '2023-04-14'}, {'_id': 'p5xRCWCdU', 'name': 'Proverb', 'slug': 'proverb', 'quoteCount': 0, 'dateAdded': '2021-02-12', 'dateModified': '2023-04-14'}, {'_id': 'tWLCsyf_K', 'name': 'Religion', 'slug': 'religion', 'quoteCount': 6, 'dateAdded': '2020-01-12', 'dateModified': '2023-04-14'}, {'_id': 'dm15bka7Qc', 'name': 'Sadness', 'slug': 'sadness', 'quoteCount': 1, 'dateAdded': '2023-04-14', 'dateModified': '2023-04-14'}, {'_id': 'qO4zwIUdFW', 'name': 'Science', 'slug': 'science', 'quoteCount': 14, 'dateAdded': '2020-01-26', 'dateModified': '2023-04-14'}, {'_id': '5wvH2mbETdq', 'name': 'Self', 'slug': 'self', 'quoteCount': 6, 'dateAdded': '2022-03-12', 'dateModified': '2023-04-14'}, {'_id': 'IJsMcEupo4', 'name': 'Self Help', 'slug': 'self-help', 'quoteCount': 6, 'dateAdded': '2022-07-04', 'dateModified': '2023-04-14'}, {'_id': '-WCNo8uFORU', 'name': 'Social Justice', 'slug': 'social-justice', 'quoteCount': 3, 'dateAdded': '2022-03-12', 'dateModified': '2023-04-14'}, {'_id': 'eD6qAIcDR8s', 'name': 'Society', 'slug': 'society', 'quoteCount': 1, 'dateAdded': '2023-04-06', 'dateModified': '2023-04-14'}, {'_id': 'DNZ4IdtHiFG', 'name': 'Spirituality', 'slug': 'spirituality', 'quoteCount': 4, 'dateAdded': '2022-03-12', 'dateModified': '2023-04-14'}, {'_id': 'EKV8W1TN-wb', 'name': 'Sports', 'slug': 'sports', 'quoteCount': 43, 'dateAdded': '2022-07-06', 'dateModified': '2023-04-14'}, {'_id': 'kZei477Cojv', 'name': 'Stupidity', 'slug': 'stupidity', 'quoteCount': 1, 'dateAdded': '2023-04-06', 'dateModified': '2023-04-14'}, {'_id': 'wm1HFcO8vf', 'name': 'Success', 'slug': 'success', 'quoteCount': 82, 'dateAdded': '2020-10-14', 'dateModified': '2023-04-14'}, {'_id': 'Gq75KBrfb', 'name': 'Technology', 'slug': 'technology', 'quoteCount': 50, 'dateAdded': '2020-01-27', 'dateModified': '2023-04-14'}, {'_id': 'LzQ9iXOoZw_', 'name': 'Time', 'slug': 'time', 'quoteCount': 1, 'dateAdded': '2022-03-12', 'dateModified': '2023-04-14'}, {'_id': 'o7BP9_4e2lL', 'name': 'Tolerance', 'slug': 'tolerance', 'quoteCount': 1, 'dateAdded': '2023-04-06', 'dateModified': '2023-04-14'}, {'_id': 'B1O_IThWjSP', 'name': 'Truth', 'slug': 'truth', 'quoteCount': 7, 'dateAdded': '2022-03-12', 'dateModified': '2023-04-14'}, {'_id': 'bsT8Bb9sxB', 'name': 'Virtue', 'slug': 'virtue', 'quoteCount': 10, 'dateAdded': '2022-07-04', 'dateModified': '2023-04-14'}, {'_id': 'olEL606Ju49', 'name': 'War', 'slug': 'war', 'quoteCount': 3, 'dateAdded': '2022-03-12', 'dateModified': '2023-04-14'}, {'_id': 'AN2qILFNzW', 'name': 'Weakness', 'slug': 'weakness', 'quoteCount': 1, 'dateAdded': '2023-04-14', 'dateModified': '2023-04-14'}, {'_id': '5j5s-YkHAr_', 'name': 'Wellness', 'slug': 'wellness', 'quoteCount': 1, 'dateAdded': '2023-04-14', 'dateModified': '2023-04-14'}, {'_id': '6J1qxxuj3', 'name': 'Wisdom', 'slug': 'wisdom', 'quoteCount': 550, 'dateAdded': '2019-10-18', 'dateModified': '2023-04-14'}, {'_id': 'Y3mg6WH7Qv1', 'name': 'Work', 'slug': 'work', 'quoteCount': 3, 'dateAdded': '2023-04-14', 'dateModified': '2023-04-14'}, {'_id': 'NLC25zc7-m5', 'name': 'Work', 'slug': 'work', 'quoteCount': 3, 'dateAdded': '2023-04-14', 'dateModified': '2023-04-14'}]

----------------------------------------------------------------------
Ran 9 tests in 2.421s

FAILED (failures=3)
Tests completed for API 'quotable'

==================================================

Running tests for API 'gameofthrones'...
.......
----------------------------------------------------------------------
Ran 7 tests in 1.945s

OK
Tests completed for API 'gameofthrones'

==================================================

Running tests for API 'quotegarden'...
EEEE
======================================================================
ERROR: test_get_all_authors (__main__.TestQuoteGardenAPI.test_get_all_authors)
----------------------------------------------------------------------
Traceback (most recent call last):
  File "/home/trevea/Projects/ToolsForTheJobBenchmark/generation/Inspiration/quotegarden/api_test.py", line 23, in test_get_all_authors
    self.assertEqual(response['statusCode'], 200)
                     ~~~~~~~~^^^^^^^^^^^^^^
KeyError: 'statusCode'

======================================================================
ERROR: test_get_all_genres (__main__.TestQuoteGardenAPI.test_get_all_genres)
----------------------------------------------------------------------
Traceback (most recent call last):
  File "/home/trevea/Projects/ToolsForTheJobBenchmark/generation/Inspiration/quotegarden/api_test.py", line 18, in test_get_all_genres
    self.assertEqual(response['statusCode'], 200)
                     ~~~~~~~~^^^^^^^^^^^^^^
KeyError: 'statusCode'

======================================================================
ERROR: test_get_quotes (__main__.TestQuoteGardenAPI.test_get_quotes)
----------------------------------------------------------------------
Traceback (most recent call last):
  File "/home/trevea/Projects/ToolsForTheJobBenchmark/generation/Inspiration/quotegarden/api_test.py", line 13, in test_get_quotes
    self.assertEqual(response['statusCode'], 200)
                     ~~~~~~~~^^^^^^^^^^^^^^
KeyError: 'statusCode'

======================================================================
ERROR: test_get_random_quote (__main__.TestQuoteGardenAPI.test_get_random_quote)
----------------------------------------------------------------------
Traceback (most recent call last):
  File "/home/trevea/Projects/ToolsForTheJobBenchmark/generation/Inspiration/quotegarden/api_test.py", line 8, in test_get_random_quote
    self.assertEqual(response['statusCode'], 200)
                     ~~~~~~~~^^^^^^^^^^^^^^
KeyError: 'statusCode'

----------------------------------------------------------------------
Ran 4 tests in 1.546s

FAILED (errors=4)
Tests completed for API 'quotegarden'

==================================================

Running tests for API 'affirmations'...
.
----------------------------------------------------------------------
Ran 1 test in 0.587s

OK
Tests completed for API 'affirmations'

==================================================

Running tests for API 'dictum'...
Tests completed for API 'dictum'

==================================================

EEEEEEEEEE
======================================================================
ERROR: test_create_quote (__main__.TestDictumAPI.test_create_quote)
----------------------------------------------------------------------
Traceback (most recent call last):
  File "/home/trevea/miniconda3/envs/nlp-rag/lib/python3.12/site-packages/urllib3/connection.py", line 203, in _new_conn
    sock = connection.create_connection(
           ^^^^^^^^^^^^^^^^^^^^^^^^^^^^^
  File "/home/trevea/miniconda3/envs/nlp-rag/lib/python3.12/site-packages/urllib3/util/connection.py", line 60, in create_connection
    for res in socket.getaddrinfo(host, port, family, socket.SOCK_STREAM):
               ^^^^^^^^^^^^^^^^^^^^^^^^^^^^^^^^^^^^^^^^^^^^^^^^^^^^^^^^^^
  File "/home/trevea/miniconda3/envs/nlp-rag/lib/python3.12/socket.py", line 963, in getaddrinfo
    for res in _socket.getaddrinfo(host, port, family, type, proto, flags):
               ^^^^^^^^^^^^^^^^^^^^^^^^^^^^^^^^^^^^^^^^^^^^^^^^^^^^^^^^^^^
socket.gaierror: [Errno -2] Name or service not known

The above exception was the direct cause of the following exception:

Traceback (most recent call last):
  File "/home/trevea/miniconda3/envs/nlp-rag/lib/python3.12/site-packages/urllib3/connectionpool.py", line 790, in urlopen
    response = self._make_request(
               ^^^^^^^^^^^^^^^^^^^
  File "/home/trevea/miniconda3/envs/nlp-rag/lib/python3.12/site-packages/urllib3/connectionpool.py", line 491, in _make_request
    raise new_e
  File "/home/trevea/miniconda3/envs/nlp-rag/lib/python3.12/site-packages/urllib3/connectionpool.py", line 467, in _make_request
    self._validate_conn(conn)
  File "/home/trevea/miniconda3/envs/nlp-rag/lib/python3.12/site-packages/urllib3/connectionpool.py", line 1096, in _validate_conn
    conn.connect()
  File "/home/trevea/miniconda3/envs/nlp-rag/lib/python3.12/site-packages/urllib3/connection.py", line 611, in connect
    self.sock = sock = self._new_conn()
                       ^^^^^^^^^^^^^^^^
  File "/home/trevea/miniconda3/envs/nlp-rag/lib/python3.12/site-packages/urllib3/connection.py", line 210, in _new_conn
    raise NameResolutionError(self.host, self, e) from e
urllib3.exceptions.NameResolutionError: <urllib3.connection.HTTPSConnection object at 0x7f96a4251730>: Failed to resolve 'api.dictum.com' ([Errno -2] Name or service not known)

The above exception was the direct cause of the following exception:

Traceback (most recent call last):
  File "/home/trevea/miniconda3/envs/nlp-rag/lib/python3.12/site-packages/requests/adapters.py", line 486, in send
    resp = conn.urlopen(
           ^^^^^^^^^^^^^
  File "/home/trevea/miniconda3/envs/nlp-rag/lib/python3.12/site-packages/urllib3/connectionpool.py", line 844, in urlopen
    retries = retries.increment(
              ^^^^^^^^^^^^^^^^^^
  File "/home/trevea/miniconda3/envs/nlp-rag/lib/python3.12/site-packages/urllib3/util/retry.py", line 515, in increment
    raise MaxRetryError(_pool, url, reason) from reason  # type: ignore[arg-type]
    ^^^^^^^^^^^^^^^^^^^^^^^^^^^^^^^^^^^^^^^^^^^^^^^^^^^
urllib3.exceptions.MaxRetryError: HTTPSConnectionPool(host='api.dictum.com', port=443): Max retries exceeded with url: /v1/quotes/en (Caused by NameResolutionError("<urllib3.connection.HTTPSConnection object at 0x7f96a4251730>: Failed to resolve 'api.dictum.com' ([Errno -2] Name or service not known)"))

During handling of the above exception, another exception occurred:

Traceback (most recent call last):
  File "/home/trevea/Projects/ToolsForTheJobBenchmark/generation/Inspiration/dictum/api_test.py", line 49, in test_create_quote
    response = create_quote(self.language, self.author_id, self.text)
               ^^^^^^^^^^^^^^^^^^^^^^^^^^^^^^^^^^^^^^^^^^^^^^^^^^^^^^
  File "/home/trevea/Projects/ToolsForTheJobBenchmark/generation/Inspiration/dictum/api.py", line 53, in create_quote
    response = requests.post(url, json=data)
               ^^^^^^^^^^^^^^^^^^^^^^^^^^^^^
  File "/home/trevea/miniconda3/envs/nlp-rag/lib/python3.12/site-packages/requests/api.py", line 115, in post
    return request("post", url, data=data, json=json, **kwargs)
           ^^^^^^^^^^^^^^^^^^^^^^^^^^^^^^^^^^^^^^^^^^^^^^^^^^^^
  File "/home/trevea/miniconda3/envs/nlp-rag/lib/python3.12/site-packages/requests/api.py", line 59, in request
    return session.request(method=method, url=url, **kwargs)
           ^^^^^^^^^^^^^^^^^^^^^^^^^^^^^^^^^^^^^^^^^^^^^^^^^
  File "/home/trevea/miniconda3/envs/nlp-rag/lib/python3.12/site-packages/requests/sessions.py", line 589, in request
    resp = self.send(prep, **send_kwargs)
           ^^^^^^^^^^^^^^^^^^^^^^^^^^^^^^
  File "/home/trevea/miniconda3/envs/nlp-rag/lib/python3.12/site-packages/requests/sessions.py", line 703, in send
    r = adapter.send(request, **kwargs)
        ^^^^^^^^^^^^^^^^^^^^^^^^^^^^^^^
  File "/home/trevea/miniconda3/envs/nlp-rag/lib/python3.12/site-packages/requests/adapters.py", line 519, in send
    raise ConnectionError(e, request=request)
requests.exceptions.ConnectionError: HTTPSConnectionPool(host='api.dictum.com', port=443): Max retries exceeded with url: /v1/quotes/en (Caused by NameResolutionError("<urllib3.connection.HTTPSConnection object at 0x7f96a4251730>: Failed to resolve 'api.dictum.com' ([Errno -2] Name or service not known)"))

======================================================================
ERROR: test_get_author (__main__.TestDictumAPI.test_get_author)
----------------------------------------------------------------------
Traceback (most recent call last):
  File "/home/trevea/miniconda3/envs/nlp-rag/lib/python3.12/site-packages/urllib3/connection.py", line 203, in _new_conn
    sock = connection.create_connection(
           ^^^^^^^^^^^^^^^^^^^^^^^^^^^^^
  File "/home/trevea/miniconda3/envs/nlp-rag/lib/python3.12/site-packages/urllib3/util/connection.py", line 60, in create_connection
    for res in socket.getaddrinfo(host, port, family, socket.SOCK_STREAM):
               ^^^^^^^^^^^^^^^^^^^^^^^^^^^^^^^^^^^^^^^^^^^^^^^^^^^^^^^^^^
  File "/home/trevea/miniconda3/envs/nlp-rag/lib/python3.12/socket.py", line 963, in getaddrinfo
    for res in _socket.getaddrinfo(host, port, family, type, proto, flags):
               ^^^^^^^^^^^^^^^^^^^^^^^^^^^^^^^^^^^^^^^^^^^^^^^^^^^^^^^^^^^
socket.gaierror: [Errno -2] Name or service not known

The above exception was the direct cause of the following exception:

Traceback (most recent call last):
  File "/home/trevea/miniconda3/envs/nlp-rag/lib/python3.12/site-packages/urllib3/connectionpool.py", line 790, in urlopen
    response = self._make_request(
               ^^^^^^^^^^^^^^^^^^^
  File "/home/trevea/miniconda3/envs/nlp-rag/lib/python3.12/site-packages/urllib3/connectionpool.py", line 491, in _make_request
    raise new_e
  File "/home/trevea/miniconda3/envs/nlp-rag/lib/python3.12/site-packages/urllib3/connectionpool.py", line 467, in _make_request
    self._validate_conn(conn)
  File "/home/trevea/miniconda3/envs/nlp-rag/lib/python3.12/site-packages/urllib3/connectionpool.py", line 1096, in _validate_conn
    conn.connect()
  File "/home/trevea/miniconda3/envs/nlp-rag/lib/python3.12/site-packages/urllib3/connection.py", line 611, in connect
    self.sock = sock = self._new_conn()
                       ^^^^^^^^^^^^^^^^
  File "/home/trevea/miniconda3/envs/nlp-rag/lib/python3.12/site-packages/urllib3/connection.py", line 210, in _new_conn
    raise NameResolutionError(self.host, self, e) from e
urllib3.exceptions.NameResolutionError: <urllib3.connection.HTTPSConnection object at 0x7f96a3336570>: Failed to resolve 'api.dictum.com' ([Errno -2] Name or service not known)

The above exception was the direct cause of the following exception:

Traceback (most recent call last):
  File "/home/trevea/miniconda3/envs/nlp-rag/lib/python3.12/site-packages/requests/adapters.py", line 486, in send
    resp = conn.urlopen(
           ^^^^^^^^^^^^^
  File "/home/trevea/miniconda3/envs/nlp-rag/lib/python3.12/site-packages/urllib3/connectionpool.py", line 844, in urlopen
    retries = retries.increment(
              ^^^^^^^^^^^^^^^^^^
  File "/home/trevea/miniconda3/envs/nlp-rag/lib/python3.12/site-packages/urllib3/util/retry.py", line 515, in increment
    raise MaxRetryError(_pool, url, reason) from reason  # type: ignore[arg-type]
    ^^^^^^^^^^^^^^^^^^^^^^^^^^^^^^^^^^^^^^^^^^^^^^^^^^^
urllib3.exceptions.MaxRetryError: HTTPSConnectionPool(host='api.dictum.com', port=443): Max retries exceeded with url: /v1/authors/en/some-author-id (Caused by NameResolutionError("<urllib3.connection.HTTPSConnection object at 0x7f96a3336570>: Failed to resolve 'api.dictum.com' ([Errno -2] Name or service not known)"))

During handling of the above exception, another exception occurred:

Traceback (most recent call last):
  File "/home/trevea/Projects/ToolsForTheJobBenchmark/generation/Inspiration/dictum/api_test.py", line 29, in test_get_author
    response = get_author(self.language, self.author_id)
               ^^^^^^^^^^^^^^^^^^^^^^^^^^^^^^^^^^^^^^^^^
  File "/home/trevea/Projects/ToolsForTheJobBenchmark/generation/Inspiration/dictum/api.py", line 16, in get_author
    response = requests.get(url)
               ^^^^^^^^^^^^^^^^^
  File "/home/trevea/miniconda3/envs/nlp-rag/lib/python3.12/site-packages/requests/api.py", line 73, in get
    return request("get", url, params=params, **kwargs)
           ^^^^^^^^^^^^^^^^^^^^^^^^^^^^^^^^^^^^^^^^^^^^
  File "/home/trevea/miniconda3/envs/nlp-rag/lib/python3.12/site-packages/requests/api.py", line 59, in request
    return session.request(method=method, url=url, **kwargs)
           ^^^^^^^^^^^^^^^^^^^^^^^^^^^^^^^^^^^^^^^^^^^^^^^^^
  File "/home/trevea/miniconda3/envs/nlp-rag/lib/python3.12/site-packages/requests/sessions.py", line 589, in request
    resp = self.send(prep, **send_kwargs)
           ^^^^^^^^^^^^^^^^^^^^^^^^^^^^^^
  File "/home/trevea/miniconda3/envs/nlp-rag/lib/python3.12/site-packages/requests/sessions.py", line 703, in send
    r = adapter.send(request, **kwargs)
        ^^^^^^^^^^^^^^^^^^^^^^^^^^^^^^^
  File "/home/trevea/miniconda3/envs/nlp-rag/lib/python3.12/site-packages/requests/adapters.py", line 519, in send
    raise ConnectionError(e, request=request)
requests.exceptions.ConnectionError: HTTPSConnectionPool(host='api.dictum.com', port=443): Max retries exceeded with url: /v1/authors/en/some-author-id (Caused by NameResolutionError("<urllib3.connection.HTTPSConnection object at 0x7f96a3336570>: Failed to resolve 'api.dictum.com' ([Errno -2] Name or service not known)"))

======================================================================
ERROR: test_get_authors (__main__.TestDictumAPI.test_get_authors)
----------------------------------------------------------------------
Traceback (most recent call last):
  File "/home/trevea/miniconda3/envs/nlp-rag/lib/python3.12/site-packages/urllib3/connection.py", line 203, in _new_conn
    sock = connection.create_connection(
           ^^^^^^^^^^^^^^^^^^^^^^^^^^^^^
  File "/home/trevea/miniconda3/envs/nlp-rag/lib/python3.12/site-packages/urllib3/util/connection.py", line 60, in create_connection
    for res in socket.getaddrinfo(host, port, family, socket.SOCK_STREAM):
               ^^^^^^^^^^^^^^^^^^^^^^^^^^^^^^^^^^^^^^^^^^^^^^^^^^^^^^^^^^
  File "/home/trevea/miniconda3/envs/nlp-rag/lib/python3.12/socket.py", line 963, in getaddrinfo
    for res in _socket.getaddrinfo(host, port, family, type, proto, flags):
               ^^^^^^^^^^^^^^^^^^^^^^^^^^^^^^^^^^^^^^^^^^^^^^^^^^^^^^^^^^^
socket.gaierror: [Errno -2] Name or service not known

The above exception was the direct cause of the following exception:

Traceback (most recent call last):
  File "/home/trevea/miniconda3/envs/nlp-rag/lib/python3.12/site-packages/urllib3/connectionpool.py", line 790, in urlopen
    response = self._make_request(
               ^^^^^^^^^^^^^^^^^^^
  File "/home/trevea/miniconda3/envs/nlp-rag/lib/python3.12/site-packages/urllib3/connectionpool.py", line 491, in _make_request
    raise new_e
  File "/home/trevea/miniconda3/envs/nlp-rag/lib/python3.12/site-packages/urllib3/connectionpool.py", line 467, in _make_request
    self._validate_conn(conn)
  File "/home/trevea/miniconda3/envs/nlp-rag/lib/python3.12/site-packages/urllib3/connectionpool.py", line 1096, in _validate_conn
    conn.connect()
  File "/home/trevea/miniconda3/envs/nlp-rag/lib/python3.12/site-packages/urllib3/connection.py", line 611, in connect
    self.sock = sock = self._new_conn()
                       ^^^^^^^^^^^^^^^^
  File "/home/trevea/miniconda3/envs/nlp-rag/lib/python3.12/site-packages/urllib3/connection.py", line 210, in _new_conn
    raise NameResolutionError(self.host, self, e) from e
urllib3.exceptions.NameResolutionError: <urllib3.connection.HTTPSConnection object at 0x7f96a3336cf0>: Failed to resolve 'api.dictum.com' ([Errno -2] Name or service not known)

The above exception was the direct cause of the following exception:

Traceback (most recent call last):
  File "/home/trevea/miniconda3/envs/nlp-rag/lib/python3.12/site-packages/requests/adapters.py", line 486, in send
    resp = conn.urlopen(
           ^^^^^^^^^^^^^
  File "/home/trevea/miniconda3/envs/nlp-rag/lib/python3.12/site-packages/urllib3/connectionpool.py", line 844, in urlopen
    retries = retries.increment(
              ^^^^^^^^^^^^^^^^^^
  File "/home/trevea/miniconda3/envs/nlp-rag/lib/python3.12/site-packages/urllib3/util/retry.py", line 515, in increment
    raise MaxRetryError(_pool, url, reason) from reason  # type: ignore[arg-type]
    ^^^^^^^^^^^^^^^^^^^^^^^^^^^^^^^^^^^^^^^^^^^^^^^^^^^
urllib3.exceptions.MaxRetryError: HTTPSConnectionPool(host='api.dictum.com', port=443): Max retries exceeded with url: /v1/authors/en?offset=0&limit=10 (Caused by NameResolutionError("<urllib3.connection.HTTPSConnection object at 0x7f96a3336cf0>: Failed to resolve 'api.dictum.com' ([Errno -2] Name or service not known)"))

During handling of the above exception, another exception occurred:

Traceback (most recent call last):
  File "/home/trevea/Projects/ToolsForTheJobBenchmark/generation/Inspiration/dictum/api_test.py", line 25, in test_get_authors
    response = get_authors(self.language)
               ^^^^^^^^^^^^^^^^^^^^^^^^^^
  File "/home/trevea/Projects/ToolsForTheJobBenchmark/generation/Inspiration/dictum/api.py", line 11, in get_authors
    response = requests.get(url, params=params)
               ^^^^^^^^^^^^^^^^^^^^^^^^^^^^^^^^
  File "/home/trevea/miniconda3/envs/nlp-rag/lib/python3.12/site-packages/requests/api.py", line 73, in get
    return request("get", url, params=params, **kwargs)
           ^^^^^^^^^^^^^^^^^^^^^^^^^^^^^^^^^^^^^^^^^^^^
  File "/home/trevea/miniconda3/envs/nlp-rag/lib/python3.12/site-packages/requests/api.py", line 59, in request
    return session.request(method=method, url=url, **kwargs)
           ^^^^^^^^^^^^^^^^^^^^^^^^^^^^^^^^^^^^^^^^^^^^^^^^^
  File "/home/trevea/miniconda3/envs/nlp-rag/lib/python3.12/site-packages/requests/sessions.py", line 589, in request
    resp = self.send(prep, **send_kwargs)
           ^^^^^^^^^^^^^^^^^^^^^^^^^^^^^^
  File "/home/trevea/miniconda3/envs/nlp-rag/lib/python3.12/site-packages/requests/sessions.py", line 703, in send
    r = adapter.send(request, **kwargs)
        ^^^^^^^^^^^^^^^^^^^^^^^^^^^^^^^
  File "/home/trevea/miniconda3/envs/nlp-rag/lib/python3.12/site-packages/requests/adapters.py", line 519, in send
    raise ConnectionError(e, request=request)
requests.exceptions.ConnectionError: HTTPSConnectionPool(host='api.dictum.com', port=443): Max retries exceeded with url: /v1/authors/en?offset=0&limit=10 (Caused by NameResolutionError("<urllib3.connection.HTTPSConnection object at 0x7f96a3336cf0>: Failed to resolve 'api.dictum.com' ([Errno -2] Name or service not known)"))

======================================================================
ERROR: test_get_languages (__main__.TestDictumAPI.test_get_languages)
----------------------------------------------------------------------
Traceback (most recent call last):
  File "/home/trevea/miniconda3/envs/nlp-rag/lib/python3.12/site-packages/urllib3/connection.py", line 203, in _new_conn
    sock = connection.create_connection(
           ^^^^^^^^^^^^^^^^^^^^^^^^^^^^^
  File "/home/trevea/miniconda3/envs/nlp-rag/lib/python3.12/site-packages/urllib3/util/connection.py", line 60, in create_connection
    for res in socket.getaddrinfo(host, port, family, socket.SOCK_STREAM):
               ^^^^^^^^^^^^^^^^^^^^^^^^^^^^^^^^^^^^^^^^^^^^^^^^^^^^^^^^^^
  File "/home/trevea/miniconda3/envs/nlp-rag/lib/python3.12/socket.py", line 963, in getaddrinfo
    for res in _socket.getaddrinfo(host, port, family, type, proto, flags):
               ^^^^^^^^^^^^^^^^^^^^^^^^^^^^^^^^^^^^^^^^^^^^^^^^^^^^^^^^^^^
socket.gaierror: [Errno -2] Name or service not known

The above exception was the direct cause of the following exception:

Traceback (most recent call last):
  File "/home/trevea/miniconda3/envs/nlp-rag/lib/python3.12/site-packages/urllib3/connectionpool.py", line 790, in urlopen
    response = self._make_request(
               ^^^^^^^^^^^^^^^^^^^
  File "/home/trevea/miniconda3/envs/nlp-rag/lib/python3.12/site-packages/urllib3/connectionpool.py", line 491, in _make_request
    raise new_e
  File "/home/trevea/miniconda3/envs/nlp-rag/lib/python3.12/site-packages/urllib3/connectionpool.py", line 467, in _make_request
    self._validate_conn(conn)
  File "/home/trevea/miniconda3/envs/nlp-rag/lib/python3.12/site-packages/urllib3/connectionpool.py", line 1096, in _validate_conn
    conn.connect()
  File "/home/trevea/miniconda3/envs/nlp-rag/lib/python3.12/site-packages/urllib3/connection.py", line 611, in connect
    self.sock = sock = self._new_conn()
                       ^^^^^^^^^^^^^^^^
  File "/home/trevea/miniconda3/envs/nlp-rag/lib/python3.12/site-packages/urllib3/connection.py", line 210, in _new_conn
    raise NameResolutionError(self.host, self, e) from e
urllib3.exceptions.NameResolutionError: <urllib3.connection.HTTPSConnection object at 0x7f96a3337500>: Failed to resolve 'api.dictum.com' ([Errno -2] Name or service not known)

The above exception was the direct cause of the following exception:

Traceback (most recent call last):
  File "/home/trevea/miniconda3/envs/nlp-rag/lib/python3.12/site-packages/requests/adapters.py", line 486, in send
    resp = conn.urlopen(
           ^^^^^^^^^^^^^
  File "/home/trevea/miniconda3/envs/nlp-rag/lib/python3.12/site-packages/urllib3/connectionpool.py", line 844, in urlopen
    retries = retries.increment(
              ^^^^^^^^^^^^^^^^^^
  File "/home/trevea/miniconda3/envs/nlp-rag/lib/python3.12/site-packages/urllib3/util/retry.py", line 515, in increment
    raise MaxRetryError(_pool, url, reason) from reason  # type: ignore[arg-type]
    ^^^^^^^^^^^^^^^^^^^^^^^^^^^^^^^^^^^^^^^^^^^^^^^^^^^
urllib3.exceptions.MaxRetryError: HTTPSConnectionPool(host='api.dictum.com', port=443): Max retries exceeded with url: /v1/languages (Caused by NameResolutionError("<urllib3.connection.HTTPSConnection object at 0x7f96a3337500>: Failed to resolve 'api.dictum.com' ([Errno -2] Name or service not known)"))

During handling of the above exception, another exception occurred:

Traceback (most recent call last):
  File "/home/trevea/Projects/ToolsForTheJobBenchmark/generation/Inspiration/dictum/api_test.py", line 37, in test_get_languages
    response = get_languages()
               ^^^^^^^^^^^^^^^
  File "/home/trevea/Projects/ToolsForTheJobBenchmark/generation/Inspiration/dictum/api.py", line 31, in get_languages
    response = requests.get(url)
               ^^^^^^^^^^^^^^^^^
  File "/home/trevea/miniconda3/envs/nlp-rag/lib/python3.12/site-packages/requests/api.py", line 73, in get
    return request("get", url, params=params, **kwargs)
           ^^^^^^^^^^^^^^^^^^^^^^^^^^^^^^^^^^^^^^^^^^^^
  File "/home/trevea/miniconda3/envs/nlp-rag/lib/python3.12/site-packages/requests/api.py", line 59, in request
    return session.request(method=method, url=url, **kwargs)
           ^^^^^^^^^^^^^^^^^^^^^^^^^^^^^^^^^^^^^^^^^^^^^^^^^
  File "/home/trevea/miniconda3/envs/nlp-rag/lib/python3.12/site-packages/requests/sessions.py", line 589, in request
    resp = self.send(prep, **send_kwargs)
           ^^^^^^^^^^^^^^^^^^^^^^^^^^^^^^
  File "/home/trevea/miniconda3/envs/nlp-rag/lib/python3.12/site-packages/requests/sessions.py", line 703, in send
    r = adapter.send(request, **kwargs)
        ^^^^^^^^^^^^^^^^^^^^^^^^^^^^^^^
  File "/home/trevea/miniconda3/envs/nlp-rag/lib/python3.12/site-packages/requests/adapters.py", line 519, in send
    raise ConnectionError(e, request=request)
requests.exceptions.ConnectionError: HTTPSConnectionPool(host='api.dictum.com', port=443): Max retries exceeded with url: /v1/languages (Caused by NameResolutionError("<urllib3.connection.HTTPSConnection object at 0x7f96a3337500>: Failed to resolve 'api.dictum.com' ([Errno -2] Name or service not known)"))

======================================================================
ERROR: test_get_quote (__main__.TestDictumAPI.test_get_quote)
----------------------------------------------------------------------
Traceback (most recent call last):
  File "/home/trevea/miniconda3/envs/nlp-rag/lib/python3.12/site-packages/urllib3/connection.py", line 203, in _new_conn
    sock = connection.create_connection(
           ^^^^^^^^^^^^^^^^^^^^^^^^^^^^^
  File "/home/trevea/miniconda3/envs/nlp-rag/lib/python3.12/site-packages/urllib3/util/connection.py", line 60, in create_connection
    for res in socket.getaddrinfo(host, port, family, socket.SOCK_STREAM):
               ^^^^^^^^^^^^^^^^^^^^^^^^^^^^^^^^^^^^^^^^^^^^^^^^^^^^^^^^^^
  File "/home/trevea/miniconda3/envs/nlp-rag/lib/python3.12/socket.py", line 963, in getaddrinfo
    for res in _socket.getaddrinfo(host, port, family, type, proto, flags):
               ^^^^^^^^^^^^^^^^^^^^^^^^^^^^^^^^^^^^^^^^^^^^^^^^^^^^^^^^^^^
socket.gaierror: [Errno -2] Name or service not known

The above exception was the direct cause of the following exception:

Traceback (most recent call last):
  File "/home/trevea/miniconda3/envs/nlp-rag/lib/python3.12/site-packages/urllib3/connectionpool.py", line 790, in urlopen
    response = self._make_request(
               ^^^^^^^^^^^^^^^^^^^
  File "/home/trevea/miniconda3/envs/nlp-rag/lib/python3.12/site-packages/urllib3/connectionpool.py", line 491, in _make_request
    raise new_e
  File "/home/trevea/miniconda3/envs/nlp-rag/lib/python3.12/site-packages/urllib3/connectionpool.py", line 467, in _make_request
    self._validate_conn(conn)
  File "/home/trevea/miniconda3/envs/nlp-rag/lib/python3.12/site-packages/urllib3/connectionpool.py", line 1096, in _validate_conn
    conn.connect()
  File "/home/trevea/miniconda3/envs/nlp-rag/lib/python3.12/site-packages/urllib3/connection.py", line 611, in connect
    self.sock = sock = self._new_conn()
                       ^^^^^^^^^^^^^^^^
  File "/home/trevea/miniconda3/envs/nlp-rag/lib/python3.12/site-packages/urllib3/connection.py", line 210, in _new_conn
    raise NameResolutionError(self.host, self, e) from e
urllib3.exceptions.NameResolutionError: <urllib3.connection.HTTPSConnection object at 0x7f96a3337da0>: Failed to resolve 'api.dictum.com' ([Errno -2] Name or service not known)

The above exception was the direct cause of the following exception:

Traceback (most recent call last):
  File "/home/trevea/miniconda3/envs/nlp-rag/lib/python3.12/site-packages/requests/adapters.py", line 486, in send
    resp = conn.urlopen(
           ^^^^^^^^^^^^^
  File "/home/trevea/miniconda3/envs/nlp-rag/lib/python3.12/site-packages/urllib3/connectionpool.py", line 844, in urlopen
    retries = retries.increment(
              ^^^^^^^^^^^^^^^^^^
  File "/home/trevea/miniconda3/envs/nlp-rag/lib/python3.12/site-packages/urllib3/util/retry.py", line 515, in increment
    raise MaxRetryError(_pool, url, reason) from reason  # type: ignore[arg-type]
    ^^^^^^^^^^^^^^^^^^^^^^^^^^^^^^^^^^^^^^^^^^^^^^^^^^^
urllib3.exceptions.MaxRetryError: HTTPSConnectionPool(host='api.dictum.com', port=443): Max retries exceeded with url: /v1/quotes/en/some-quote-id (Caused by NameResolutionError("<urllib3.connection.HTTPSConnection object at 0x7f96a3337da0>: Failed to resolve 'api.dictum.com' ([Errno -2] Name or service not known)"))

During handling of the above exception, another exception occurred:

Traceback (most recent call last):
  File "/home/trevea/Projects/ToolsForTheJobBenchmark/generation/Inspiration/dictum/api_test.py", line 57, in test_get_quote
    response = get_quote(self.language, self.quote_id)
               ^^^^^^^^^^^^^^^^^^^^^^^^^^^^^^^^^^^^^^^
  File "/home/trevea/Projects/ToolsForTheJobBenchmark/generation/Inspiration/dictum/api.py", line 63, in get_quote
    response = requests.get(url)
               ^^^^^^^^^^^^^^^^^
  File "/home/trevea/miniconda3/envs/nlp-rag/lib/python3.12/site-packages/requests/api.py", line 73, in get
    return request("get", url, params=params, **kwargs)
           ^^^^^^^^^^^^^^^^^^^^^^^^^^^^^^^^^^^^^^^^^^^^
  File "/home/trevea/miniconda3/envs/nlp-rag/lib/python3.12/site-packages/requests/api.py", line 59, in request
    return session.request(method=method, url=url, **kwargs)
           ^^^^^^^^^^^^^^^^^^^^^^^^^^^^^^^^^^^^^^^^^^^^^^^^^
  File "/home/trevea/miniconda3/envs/nlp-rag/lib/python3.12/site-packages/requests/sessions.py", line 589, in request
    resp = self.send(prep, **send_kwargs)
           ^^^^^^^^^^^^^^^^^^^^^^^^^^^^^^
  File "/home/trevea/miniconda3/envs/nlp-rag/lib/python3.12/site-packages/requests/sessions.py", line 703, in send
    r = adapter.send(request, **kwargs)
        ^^^^^^^^^^^^^^^^^^^^^^^^^^^^^^^
  File "/home/trevea/miniconda3/envs/nlp-rag/lib/python3.12/site-packages/requests/adapters.py", line 519, in send
    raise ConnectionError(e, request=request)
requests.exceptions.ConnectionError: HTTPSConnectionPool(host='api.dictum.com', port=443): Max retries exceeded with url: /v1/quotes/en/some-quote-id (Caused by NameResolutionError("<urllib3.connection.HTTPSConnection object at 0x7f96a3337da0>: Failed to resolve 'api.dictum.com' ([Errno -2] Name or service not known)"))

======================================================================
ERROR: test_get_random_quote (__main__.TestDictumAPI.test_get_random_quote)
----------------------------------------------------------------------
Traceback (most recent call last):
  File "/home/trevea/miniconda3/envs/nlp-rag/lib/python3.12/site-packages/urllib3/connection.py", line 203, in _new_conn
    sock = connection.create_connection(
           ^^^^^^^^^^^^^^^^^^^^^^^^^^^^^
  File "/home/trevea/miniconda3/envs/nlp-rag/lib/python3.12/site-packages/urllib3/util/connection.py", line 60, in create_connection
    for res in socket.getaddrinfo(host, port, family, socket.SOCK_STREAM):
               ^^^^^^^^^^^^^^^^^^^^^^^^^^^^^^^^^^^^^^^^^^^^^^^^^^^^^^^^^^
  File "/home/trevea/miniconda3/envs/nlp-rag/lib/python3.12/socket.py", line 963, in getaddrinfo
    for res in _socket.getaddrinfo(host, port, family, type, proto, flags):
               ^^^^^^^^^^^^^^^^^^^^^^^^^^^^^^^^^^^^^^^^^^^^^^^^^^^^^^^^^^^
socket.gaierror: [Errno -2] Name or service not known

The above exception was the direct cause of the following exception:

Traceback (most recent call last):
  File "/home/trevea/miniconda3/envs/nlp-rag/lib/python3.12/site-packages/urllib3/connectionpool.py", line 790, in urlopen
    response = self._make_request(
               ^^^^^^^^^^^^^^^^^^^
  File "/home/trevea/miniconda3/envs/nlp-rag/lib/python3.12/site-packages/urllib3/connectionpool.py", line 491, in _make_request
    raise new_e
  File "/home/trevea/miniconda3/envs/nlp-rag/lib/python3.12/site-packages/urllib3/connectionpool.py", line 467, in _make_request
    self._validate_conn(conn)
  File "/home/trevea/miniconda3/envs/nlp-rag/lib/python3.12/site-packages/urllib3/connectionpool.py", line 1096, in _validate_conn
    conn.connect()
  File "/home/trevea/miniconda3/envs/nlp-rag/lib/python3.12/site-packages/urllib3/connection.py", line 611, in connect
    self.sock = sock = self._new_conn()
                       ^^^^^^^^^^^^^^^^
  File "/home/trevea/miniconda3/envs/nlp-rag/lib/python3.12/site-packages/urllib3/connection.py", line 210, in _new_conn
    raise NameResolutionError(self.host, self, e) from e
urllib3.exceptions.NameResolutionError: <urllib3.connection.HTTPSConnection object at 0x7f96a3337500>: Failed to resolve 'api.dictum.com' ([Errno -2] Name or service not known)

The above exception was the direct cause of the following exception:

Traceback (most recent call last):
  File "/home/trevea/miniconda3/envs/nlp-rag/lib/python3.12/site-packages/requests/adapters.py", line 486, in send
    resp = conn.urlopen(
           ^^^^^^^^^^^^^
  File "/home/trevea/miniconda3/envs/nlp-rag/lib/python3.12/site-packages/urllib3/connectionpool.py", line 844, in urlopen
    retries = retries.increment(
              ^^^^^^^^^^^^^^^^^^
  File "/home/trevea/miniconda3/envs/nlp-rag/lib/python3.12/site-packages/urllib3/util/retry.py", line 515, in increment
    raise MaxRetryError(_pool, url, reason) from reason  # type: ignore[arg-type]
    ^^^^^^^^^^^^^^^^^^^^^^^^^^^^^^^^^^^^^^^^^^^^^^^^^^^
urllib3.exceptions.MaxRetryError: HTTPSConnectionPool(host='api.dictum.com', port=443): Max retries exceeded with url: /v1/quotes/en/random (Caused by NameResolutionError("<urllib3.connection.HTTPSConnection object at 0x7f96a3337500>: Failed to resolve 'api.dictum.com' ([Errno -2] Name or service not known)"))

During handling of the above exception, another exception occurred:

Traceback (most recent call last):
  File "/home/trevea/Projects/ToolsForTheJobBenchmark/generation/Inspiration/dictum/api_test.py", line 53, in test_get_random_quote
    response = get_random_quote(self.language)
               ^^^^^^^^^^^^^^^^^^^^^^^^^^^^^^^
  File "/home/trevea/Projects/ToolsForTheJobBenchmark/generation/Inspiration/dictum/api.py", line 58, in get_random_quote
    response = requests.get(url)
               ^^^^^^^^^^^^^^^^^
  File "/home/trevea/miniconda3/envs/nlp-rag/lib/python3.12/site-packages/requests/api.py", line 73, in get
    return request("get", url, params=params, **kwargs)
           ^^^^^^^^^^^^^^^^^^^^^^^^^^^^^^^^^^^^^^^^^^^^
  File "/home/trevea/miniconda3/envs/nlp-rag/lib/python3.12/site-packages/requests/api.py", line 59, in request
    return session.request(method=method, url=url, **kwargs)
           ^^^^^^^^^^^^^^^^^^^^^^^^^^^^^^^^^^^^^^^^^^^^^^^^^
  File "/home/trevea/miniconda3/envs/nlp-rag/lib/python3.12/site-packages/requests/sessions.py", line 589, in request
    resp = self.send(prep, **send_kwargs)
           ^^^^^^^^^^^^^^^^^^^^^^^^^^^^^^
  File "/home/trevea/miniconda3/envs/nlp-rag/lib/python3.12/site-packages/requests/sessions.py", line 703, in send
    r = adapter.send(request, **kwargs)
        ^^^^^^^^^^^^^^^^^^^^^^^^^^^^^^^
  File "/home/trevea/miniconda3/envs/nlp-rag/lib/python3.12/site-packages/requests/adapters.py", line 519, in send
    raise ConnectionError(e, request=request)
requests.exceptions.ConnectionError: HTTPSConnectionPool(host='api.dictum.com', port=443): Max retries exceeded with url: /v1/quotes/en/random (Caused by NameResolutionError("<urllib3.connection.HTTPSConnection object at 0x7f96a3337500>: Failed to resolve 'api.dictum.com' ([Errno -2] Name or service not known)"))

======================================================================
ERROR: test_get_statistics (__main__.TestDictumAPI.test_get_statistics)
----------------------------------------------------------------------
Traceback (most recent call last):
  File "/home/trevea/miniconda3/envs/nlp-rag/lib/python3.12/site-packages/urllib3/connection.py", line 203, in _new_conn
    sock = connection.create_connection(
           ^^^^^^^^^^^^^^^^^^^^^^^^^^^^^
  File "/home/trevea/miniconda3/envs/nlp-rag/lib/python3.12/site-packages/urllib3/util/connection.py", line 60, in create_connection
    for res in socket.getaddrinfo(host, port, family, socket.SOCK_STREAM):
               ^^^^^^^^^^^^^^^^^^^^^^^^^^^^^^^^^^^^^^^^^^^^^^^^^^^^^^^^^^
  File "/home/trevea/miniconda3/envs/nlp-rag/lib/python3.12/socket.py", line 963, in getaddrinfo
    for res in _socket.getaddrinfo(host, port, family, type, proto, flags):
               ^^^^^^^^^^^^^^^^^^^^^^^^^^^^^^^^^^^^^^^^^^^^^^^^^^^^^^^^^^^
socket.gaierror: [Errno -2] Name or service not known

The above exception was the direct cause of the following exception:

Traceback (most recent call last):
  File "/home/trevea/miniconda3/envs/nlp-rag/lib/python3.12/site-packages/urllib3/connectionpool.py", line 790, in urlopen
    response = self._make_request(
               ^^^^^^^^^^^^^^^^^^^
  File "/home/trevea/miniconda3/envs/nlp-rag/lib/python3.12/site-packages/urllib3/connectionpool.py", line 491, in _make_request
    raise new_e
  File "/home/trevea/miniconda3/envs/nlp-rag/lib/python3.12/site-packages/urllib3/connectionpool.py", line 467, in _make_request
    self._validate_conn(conn)
  File "/home/trevea/miniconda3/envs/nlp-rag/lib/python3.12/site-packages/urllib3/connectionpool.py", line 1096, in _validate_conn
    conn.connect()
  File "/home/trevea/miniconda3/envs/nlp-rag/lib/python3.12/site-packages/urllib3/connection.py", line 611, in connect
    self.sock = sock = self._new_conn()
                       ^^^^^^^^^^^^^^^^
  File "/home/trevea/miniconda3/envs/nlp-rag/lib/python3.12/site-packages/urllib3/connection.py", line 210, in _new_conn
    raise NameResolutionError(self.host, self, e) from e
urllib3.exceptions.NameResolutionError: <urllib3.connection.HTTPSConnection object at 0x7f96a3336840>: Failed to resolve 'api.dictum.com' ([Errno -2] Name or service not known)

The above exception was the direct cause of the following exception:

Traceback (most recent call last):
  File "/home/trevea/miniconda3/envs/nlp-rag/lib/python3.12/site-packages/requests/adapters.py", line 486, in send
    resp = conn.urlopen(
           ^^^^^^^^^^^^^
  File "/home/trevea/miniconda3/envs/nlp-rag/lib/python3.12/site-packages/urllib3/connectionpool.py", line 844, in urlopen
    retries = retries.increment(
              ^^^^^^^^^^^^^^^^^^
  File "/home/trevea/miniconda3/envs/nlp-rag/lib/python3.12/site-packages/urllib3/util/retry.py", line 515, in increment
    raise MaxRetryError(_pool, url, reason) from reason  # type: ignore[arg-type]
    ^^^^^^^^^^^^^^^^^^^^^^^^^^^^^^^^^^^^^^^^^^^^^^^^^^^
urllib3.exceptions.MaxRetryError: HTTPSConnectionPool(host='api.dictum.com', port=443): Max retries exceeded with url: /v1/statistics/en (Caused by NameResolutionError("<urllib3.connection.HTTPSConnection object at 0x7f96a3336840>: Failed to resolve 'api.dictum.com' ([Errno -2] Name or service not known)"))

During handling of the above exception, another exception occurred:

Traceback (most recent call last):
  File "/home/trevea/Projects/ToolsForTheJobBenchmark/generation/Inspiration/dictum/api_test.py", line 61, in test_get_statistics
    response = get_statistics(self.language)
               ^^^^^^^^^^^^^^^^^^^^^^^^^^^^^
  File "/home/trevea/Projects/ToolsForTheJobBenchmark/generation/Inspiration/dictum/api.py", line 68, in get_statistics
    response = requests.get(url)
               ^^^^^^^^^^^^^^^^^
  File "/home/trevea/miniconda3/envs/nlp-rag/lib/python3.12/site-packages/requests/api.py", line 73, in get
    return request("get", url, params=params, **kwargs)
           ^^^^^^^^^^^^^^^^^^^^^^^^^^^^^^^^^^^^^^^^^^^^
  File "/home/trevea/miniconda3/envs/nlp-rag/lib/python3.12/site-packages/requests/api.py", line 59, in request
    return session.request(method=method, url=url, **kwargs)
           ^^^^^^^^^^^^^^^^^^^^^^^^^^^^^^^^^^^^^^^^^^^^^^^^^
  File "/home/trevea/miniconda3/envs/nlp-rag/lib/python3.12/site-packages/requests/sessions.py", line 589, in request
    resp = self.send(prep, **send_kwargs)
           ^^^^^^^^^^^^^^^^^^^^^^^^^^^^^^
  File "/home/trevea/miniconda3/envs/nlp-rag/lib/python3.12/site-packages/requests/sessions.py", line 703, in send
    r = adapter.send(request, **kwargs)
        ^^^^^^^^^^^^^^^^^^^^^^^^^^^^^^^
  File "/home/trevea/miniconda3/envs/nlp-rag/lib/python3.12/site-packages/requests/adapters.py", line 519, in send
    raise ConnectionError(e, request=request)
requests.exceptions.ConnectionError: HTTPSConnectionPool(host='api.dictum.com', port=443): Max retries exceeded with url: /v1/statistics/en (Caused by NameResolutionError("<urllib3.connection.HTTPSConnection object at 0x7f96a3336840>: Failed to resolve 'api.dictum.com' ([Errno -2] Name or service not known)"))

======================================================================
ERROR: test_like_quote (__main__.TestDictumAPI.test_like_quote)
----------------------------------------------------------------------
Traceback (most recent call last):
  File "/home/trevea/miniconda3/envs/nlp-rag/lib/python3.12/site-packages/urllib3/connection.py", line 203, in _new_conn
    sock = connection.create_connection(
           ^^^^^^^^^^^^^^^^^^^^^^^^^^^^^
  File "/home/trevea/miniconda3/envs/nlp-rag/lib/python3.12/site-packages/urllib3/util/connection.py", line 60, in create_connection
    for res in socket.getaddrinfo(host, port, family, socket.SOCK_STREAM):
               ^^^^^^^^^^^^^^^^^^^^^^^^^^^^^^^^^^^^^^^^^^^^^^^^^^^^^^^^^^
  File "/home/trevea/miniconda3/envs/nlp-rag/lib/python3.12/socket.py", line 963, in getaddrinfo
    for res in _socket.getaddrinfo(host, port, family, type, proto, flags):
               ^^^^^^^^^^^^^^^^^^^^^^^^^^^^^^^^^^^^^^^^^^^^^^^^^^^^^^^^^^^
socket.gaierror: [Errno -2] Name or service not known

The above exception was the direct cause of the following exception:

Traceback (most recent call last):
  File "/home/trevea/miniconda3/envs/nlp-rag/lib/python3.12/site-packages/urllib3/connectionpool.py", line 790, in urlopen
    response = self._make_request(
               ^^^^^^^^^^^^^^^^^^^
  File "/home/trevea/miniconda3/envs/nlp-rag/lib/python3.12/site-packages/urllib3/connectionpool.py", line 491, in _make_request
    raise new_e
  File "/home/trevea/miniconda3/envs/nlp-rag/lib/python3.12/site-packages/urllib3/connectionpool.py", line 467, in _make_request
    self._validate_conn(conn)
  File "/home/trevea/miniconda3/envs/nlp-rag/lib/python3.12/site-packages/urllib3/connectionpool.py", line 1096, in _validate_conn
    conn.connect()
  File "/home/trevea/miniconda3/envs/nlp-rag/lib/python3.12/site-packages/urllib3/connection.py", line 611, in connect
    self.sock = sock = self._new_conn()
                       ^^^^^^^^^^^^^^^^
  File "/home/trevea/miniconda3/envs/nlp-rag/lib/python3.12/site-packages/urllib3/connection.py", line 210, in _new_conn
    raise NameResolutionError(self.host, self, e) from e
urllib3.exceptions.NameResolutionError: <urllib3.connection.HTTPSConnection object at 0x7f96a1d84080>: Failed to resolve 'api.dictum.com' ([Errno -2] Name or service not known)

The above exception was the direct cause of the following exception:

Traceback (most recent call last):
  File "/home/trevea/miniconda3/envs/nlp-rag/lib/python3.12/site-packages/requests/adapters.py", line 486, in send
    resp = conn.urlopen(
           ^^^^^^^^^^^^^
  File "/home/trevea/miniconda3/envs/nlp-rag/lib/python3.12/site-packages/urllib3/connectionpool.py", line 844, in urlopen
    retries = retries.increment(
              ^^^^^^^^^^^^^^^^^^
  File "/home/trevea/miniconda3/envs/nlp-rag/lib/python3.12/site-packages/urllib3/util/retry.py", line 515, in increment
    raise MaxRetryError(_pool, url, reason) from reason  # type: ignore[arg-type]
    ^^^^^^^^^^^^^^^^^^^^^^^^^^^^^^^^^^^^^^^^^^^^^^^^^^^
urllib3.exceptions.MaxRetryError: HTTPSConnectionPool(host='api.dictum.com', port=443): Max retries exceeded with url: /v1/likes/en (Caused by NameResolutionError("<urllib3.connection.HTTPSConnection object at 0x7f96a1d84080>: Failed to resolve 'api.dictum.com' ([Errno -2] Name or service not known)"))

During handling of the above exception, another exception occurred:

Traceback (most recent call last):
  File "/home/trevea/Projects/ToolsForTheJobBenchmark/generation/Inspiration/dictum/api_test.py", line 41, in test_like_quote
    response = like_quote(self.language, self.quote_id)
               ^^^^^^^^^^^^^^^^^^^^^^^^^^^^^^^^^^^^^^^^
  File "/home/trevea/Projects/ToolsForTheJobBenchmark/generation/Inspiration/dictum/api.py", line 37, in like_quote
    response = requests.post(url, json=data)
               ^^^^^^^^^^^^^^^^^^^^^^^^^^^^^
  File "/home/trevea/miniconda3/envs/nlp-rag/lib/python3.12/site-packages/requests/api.py", line 115, in post
    return request("post", url, data=data, json=json, **kwargs)
           ^^^^^^^^^^^^^^^^^^^^^^^^^^^^^^^^^^^^^^^^^^^^^^^^^^^^
  File "/home/trevea/miniconda3/envs/nlp-rag/lib/python3.12/site-packages/requests/api.py", line 59, in request
    return session.request(method=method, url=url, **kwargs)
           ^^^^^^^^^^^^^^^^^^^^^^^^^^^^^^^^^^^^^^^^^^^^^^^^^
  File "/home/trevea/miniconda3/envs/nlp-rag/lib/python3.12/site-packages/requests/sessions.py", line 589, in request
    resp = self.send(prep, **send_kwargs)
           ^^^^^^^^^^^^^^^^^^^^^^^^^^^^^^
  File "/home/trevea/miniconda3/envs/nlp-rag/lib/python3.12/site-packages/requests/sessions.py", line 703, in send
    r = adapter.send(request, **kwargs)
        ^^^^^^^^^^^^^^^^^^^^^^^^^^^^^^^
  File "/home/trevea/miniconda3/envs/nlp-rag/lib/python3.12/site-packages/requests/adapters.py", line 519, in send
    raise ConnectionError(e, request=request)
requests.exceptions.ConnectionError: HTTPSConnectionPool(host='api.dictum.com', port=443): Max retries exceeded with url: /v1/likes/en (Caused by NameResolutionError("<urllib3.connection.HTTPSConnection object at 0x7f96a1d84080>: Failed to resolve 'api.dictum.com' ([Errno -2] Name or service not known)"))

======================================================================
ERROR: test_search_author_quotes (__main__.TestDictumAPI.test_search_author_quotes)
----------------------------------------------------------------------
Traceback (most recent call last):
  File "/home/trevea/miniconda3/envs/nlp-rag/lib/python3.12/site-packages/urllib3/connection.py", line 203, in _new_conn
    sock = connection.create_connection(
           ^^^^^^^^^^^^^^^^^^^^^^^^^^^^^
  File "/home/trevea/miniconda3/envs/nlp-rag/lib/python3.12/site-packages/urllib3/util/connection.py", line 60, in create_connection
    for res in socket.getaddrinfo(host, port, family, socket.SOCK_STREAM):
               ^^^^^^^^^^^^^^^^^^^^^^^^^^^^^^^^^^^^^^^^^^^^^^^^^^^^^^^^^^
  File "/home/trevea/miniconda3/envs/nlp-rag/lib/python3.12/socket.py", line 963, in getaddrinfo
    for res in _socket.getaddrinfo(host, port, family, type, proto, flags):
               ^^^^^^^^^^^^^^^^^^^^^^^^^^^^^^^^^^^^^^^^^^^^^^^^^^^^^^^^^^^
socket.gaierror: [Errno -2] Name or service not known

The above exception was the direct cause of the following exception:

Traceback (most recent call last):
  File "/home/trevea/miniconda3/envs/nlp-rag/lib/python3.12/site-packages/urllib3/connectionpool.py", line 790, in urlopen
    response = self._make_request(
               ^^^^^^^^^^^^^^^^^^^
  File "/home/trevea/miniconda3/envs/nlp-rag/lib/python3.12/site-packages/urllib3/connectionpool.py", line 491, in _make_request
    raise new_e
  File "/home/trevea/miniconda3/envs/nlp-rag/lib/python3.12/site-packages/urllib3/connectionpool.py", line 467, in _make_request
    self._validate_conn(conn)
  File "/home/trevea/miniconda3/envs/nlp-rag/lib/python3.12/site-packages/urllib3/connectionpool.py", line 1096, in _validate_conn
    conn.connect()
  File "/home/trevea/miniconda3/envs/nlp-rag/lib/python3.12/site-packages/urllib3/connection.py", line 611, in connect
    self.sock = sock = self._new_conn()
                       ^^^^^^^^^^^^^^^^
  File "/home/trevea/miniconda3/envs/nlp-rag/lib/python3.12/site-packages/urllib3/connection.py", line 210, in _new_conn
    raise NameResolutionError(self.host, self, e) from e
urllib3.exceptions.NameResolutionError: <urllib3.connection.HTTPSConnection object at 0x7f96a1d84aa0>: Failed to resolve 'api.dictum.com' ([Errno -2] Name or service not known)

The above exception was the direct cause of the following exception:

Traceback (most recent call last):
  File "/home/trevea/miniconda3/envs/nlp-rag/lib/python3.12/site-packages/requests/adapters.py", line 486, in send
    resp = conn.urlopen(
           ^^^^^^^^^^^^^
  File "/home/trevea/miniconda3/envs/nlp-rag/lib/python3.12/site-packages/urllib3/connectionpool.py", line 844, in urlopen
    retries = retries.increment(
              ^^^^^^^^^^^^^^^^^^
  File "/home/trevea/miniconda3/envs/nlp-rag/lib/python3.12/site-packages/urllib3/util/retry.py", line 515, in increment
    raise MaxRetryError(_pool, url, reason) from reason  # type: ignore[arg-type]
    ^^^^^^^^^^^^^^^^^^^^^^^^^^^^^^^^^^^^^^^^^^^^^^^^^^^
urllib3.exceptions.MaxRetryError: HTTPSConnectionPool(host='api.dictum.com', port=443): Max retries exceeded with url: /v1/authors/en/some-author-id/quotes?offset=0&limit=10 (Caused by NameResolutionError("<urllib3.connection.HTTPSConnection object at 0x7f96a1d84aa0>: Failed to resolve 'api.dictum.com' ([Errno -2] Name or service not known)"))

During handling of the above exception, another exception occurred:

Traceback (most recent call last):
  File "/home/trevea/Projects/ToolsForTheJobBenchmark/generation/Inspiration/dictum/api_test.py", line 33, in test_search_author_quotes
    response = search_author_quotes(self.language, self.author_id)
               ^^^^^^^^^^^^^^^^^^^^^^^^^^^^^^^^^^^^^^^^^^^^^^^^^^^
  File "/home/trevea/Projects/ToolsForTheJobBenchmark/generation/Inspiration/dictum/api.py", line 26, in search_author_quotes
    response = requests.get(url, params=params)
               ^^^^^^^^^^^^^^^^^^^^^^^^^^^^^^^^
  File "/home/trevea/miniconda3/envs/nlp-rag/lib/python3.12/site-packages/requests/api.py", line 73, in get
    return request("get", url, params=params, **kwargs)
           ^^^^^^^^^^^^^^^^^^^^^^^^^^^^^^^^^^^^^^^^^^^^
  File "/home/trevea/miniconda3/envs/nlp-rag/lib/python3.12/site-packages/requests/api.py", line 59, in request
    return session.request(method=method, url=url, **kwargs)
           ^^^^^^^^^^^^^^^^^^^^^^^^^^^^^^^^^^^^^^^^^^^^^^^^^
  File "/home/trevea/miniconda3/envs/nlp-rag/lib/python3.12/site-packages/requests/sessions.py", line 589, in request
    resp = self.send(prep, **send_kwargs)
           ^^^^^^^^^^^^^^^^^^^^^^^^^^^^^^
  File "/home/trevea/miniconda3/envs/nlp-rag/lib/python3.12/site-packages/requests/sessions.py", line 703, in send
    r = adapter.send(request, **kwargs)
        ^^^^^^^^^^^^^^^^^^^^^^^^^^^^^^^
  File "/home/trevea/miniconda3/envs/nlp-rag/lib/python3.12/site-packages/requests/adapters.py", line 519, in send
    raise ConnectionError(e, request=request)
requests.exceptions.ConnectionError: HTTPSConnectionPool(host='api.dictum.com', port=443): Max retries exceeded with url: /v1/authors/en/some-author-id/quotes?offset=0&limit=10 (Caused by NameResolutionError("<urllib3.connection.HTTPSConnection object at 0x7f96a1d84aa0>: Failed to resolve 'api.dictum.com' ([Errno -2] Name or service not known)"))

======================================================================
ERROR: test_search_quotes (__main__.TestDictumAPI.test_search_quotes)
----------------------------------------------------------------------
Traceback (most recent call last):
  File "/home/trevea/miniconda3/envs/nlp-rag/lib/python3.12/site-packages/urllib3/connection.py", line 203, in _new_conn
    sock = connection.create_connection(
           ^^^^^^^^^^^^^^^^^^^^^^^^^^^^^
  File "/home/trevea/miniconda3/envs/nlp-rag/lib/python3.12/site-packages/urllib3/util/connection.py", line 60, in create_connection
    for res in socket.getaddrinfo(host, port, family, socket.SOCK_STREAM):
               ^^^^^^^^^^^^^^^^^^^^^^^^^^^^^^^^^^^^^^^^^^^^^^^^^^^^^^^^^^
  File "/home/trevea/miniconda3/envs/nlp-rag/lib/python3.12/socket.py", line 963, in getaddrinfo
    for res in _socket.getaddrinfo(host, port, family, type, proto, flags):
               ^^^^^^^^^^^^^^^^^^^^^^^^^^^^^^^^^^^^^^^^^^^^^^^^^^^^^^^^^^^
socket.gaierror: [Errno -2] Name or service not known

The above exception was the direct cause of the following exception:

Traceback (most recent call last):
  File "/home/trevea/miniconda3/envs/nlp-rag/lib/python3.12/site-packages/urllib3/connectionpool.py", line 790, in urlopen
    response = self._make_request(
               ^^^^^^^^^^^^^^^^^^^
  File "/home/trevea/miniconda3/envs/nlp-rag/lib/python3.12/site-packages/urllib3/connectionpool.py", line 491, in _make_request
    raise new_e
  File "/home/trevea/miniconda3/envs/nlp-rag/lib/python3.12/site-packages/urllib3/connectionpool.py", line 467, in _make_request
    self._validate_conn(conn)
  File "/home/trevea/miniconda3/envs/nlp-rag/lib/python3.12/site-packages/urllib3/connectionpool.py", line 1096, in _validate_conn
    conn.connect()
  File "/home/trevea/miniconda3/envs/nlp-rag/lib/python3.12/site-packages/urllib3/connection.py", line 611, in connect
    self.sock = sock = self._new_conn()
                       ^^^^^^^^^^^^^^^^
  File "/home/trevea/miniconda3/envs/nlp-rag/lib/python3.12/site-packages/urllib3/connection.py", line 210, in _new_conn
    raise NameResolutionError(self.host, self, e) from e
urllib3.exceptions.NameResolutionError: <urllib3.connection.HTTPSConnection object at 0x7f96a3335e80>: Failed to resolve 'api.dictum.com' ([Errno -2] Name or service not known)

The above exception was the direct cause of the following exception:

Traceback (most recent call last):
  File "/home/trevea/miniconda3/envs/nlp-rag/lib/python3.12/site-packages/requests/adapters.py", line 486, in send
    resp = conn.urlopen(
           ^^^^^^^^^^^^^
  File "/home/trevea/miniconda3/envs/nlp-rag/lib/python3.12/site-packages/urllib3/connectionpool.py", line 844, in urlopen
    retries = retries.increment(
              ^^^^^^^^^^^^^^^^^^
  File "/home/trevea/miniconda3/envs/nlp-rag/lib/python3.12/site-packages/urllib3/util/retry.py", line 515, in increment
    raise MaxRetryError(_pool, url, reason) from reason  # type: ignore[arg-type]
    ^^^^^^^^^^^^^^^^^^^^^^^^^^^^^^^^^^^^^^^^^^^^^^^^^^^
urllib3.exceptions.MaxRetryError: HTTPSConnectionPool(host='api.dictum.com', port=443): Max retries exceeded with url: /v1/quotes/en?offset=0&limit=10 (Caused by NameResolutionError("<urllib3.connection.HTTPSConnection object at 0x7f96a3335e80>: Failed to resolve 'api.dictum.com' ([Errno -2] Name or service not known)"))

During handling of the above exception, another exception occurred:

Traceback (most recent call last):
  File "/home/trevea/Projects/ToolsForTheJobBenchmark/generation/Inspiration/dictum/api_test.py", line 45, in test_search_quotes
    response = search_quotes(self.language)
               ^^^^^^^^^^^^^^^^^^^^^^^^^^^^
  File "/home/trevea/Projects/ToolsForTheJobBenchmark/generation/Inspiration/dictum/api.py", line 47, in search_quotes
    response = requests.get(url, params=params)
               ^^^^^^^^^^^^^^^^^^^^^^^^^^^^^^^^
  File "/home/trevea/miniconda3/envs/nlp-rag/lib/python3.12/site-packages/requests/api.py", line 73, in get
    return request("get", url, params=params, **kwargs)
           ^^^^^^^^^^^^^^^^^^^^^^^^^^^^^^^^^^^^^^^^^^^^
  File "/home/trevea/miniconda3/envs/nlp-rag/lib/python3.12/site-packages/requests/api.py", line 59, in request
    return session.request(method=method, url=url, **kwargs)
           ^^^^^^^^^^^^^^^^^^^^^^^^^^^^^^^^^^^^^^^^^^^^^^^^^
  File "/home/trevea/miniconda3/envs/nlp-rag/lib/python3.12/site-packages/requests/sessions.py", line 589, in request
    resp = self.send(prep, **send_kwargs)
           ^^^^^^^^^^^^^^^^^^^^^^^^^^^^^^
  File "/home/trevea/miniconda3/envs/nlp-rag/lib/python3.12/site-packages/requests/sessions.py", line 703, in send
    r = adapter.send(request, **kwargs)
        ^^^^^^^^^^^^^^^^^^^^^^^^^^^^^^^
  File "/home/trevea/miniconda3/envs/nlp-rag/lib/python3.12/site-packages/requests/adapters.py", line 519, in send
    raise ConnectionError(e, request=request)
requests.exceptions.ConnectionError: HTTPSConnectionPool(host='api.dictum.com', port=443): Max retries exceeded with url: /v1/quotes/en?offset=0&limit=10 (Caused by NameResolutionError("<urllib3.connection.HTTPSConnection object at 0x7f96a3335e80>: Failed to resolve 'api.dictum.com' ([Errno -2] Name or service not known)"))

----------------------------------------------------------------------
Ran 10 tests in 0.224s

FAILED (errors=10)
