Running tests for API 'carbonintensity'...
......
----------------------------------------------------------------------
Ran 6 tests in 4.532s

OK
Tests completed for API 'carbonintensity'

==================================================

Running tests for API 'universitysearch'...
....
----------------------------------------------------------------------
Ran 4 tests in 1.004s

OK
Tests completed for API 'universitysearch'

==================================================

Running tests for API 'pmtwentyfive'...
...........F..
======================================================================
FAIL: test_get_devices_nearest (__main__.TestPMTwentyFiveAPI.test_get_devices_nearest)
----------------------------------------------------------------------
Traceback (most recent call last):
  File "/home/trevea/Projects/ToolsForTheJobBenchmark/generation/OpenData/pmtwentyfive/api_test.py", line 35, in test_get_devices_nearest
    self.assertIn("feeds", response)
AssertionError: 'feeds' not found in {'error': 'Expecting value: line 1 column 1 (char 0)', 'response': ''}

----------------------------------------------------------------------
Ran 14 tests in 11.089s

FAILED (failures=1)
Tests completed for API 'pmtwentyfive'

==================================================

Running tests for API 'fipe'...
....
----------------------------------------------------------------------
Ran 4 tests in 3.488s

OK
Tests completed for API 'fipe'

==================================================

Running tests for API 'wikipedia'...
EEEEEEEEE
======================================================================
ERROR: test_get_category_metrics (__main__.TestWikipediaAPI.test_get_category_metrics)
----------------------------------------------------------------------
Traceback (most recent call last):
  File "/home/trevea/miniconda3/envs/nlp-rag/lib/python3.12/site-packages/requests/models.py", line 971, in json
    return complexjson.loads(self.text, **kwargs)
           ^^^^^^^^^^^^^^^^^^^^^^^^^^^^^^^^^^^^^^
  File "/home/trevea/miniconda3/envs/nlp-rag/lib/python3.12/json/__init__.py", line 346, in loads
    return _default_decoder.decode(s)
           ^^^^^^^^^^^^^^^^^^^^^^^^^^
  File "/home/trevea/miniconda3/envs/nlp-rag/lib/python3.12/json/decoder.py", line 337, in decode
    obj, end = self.raw_decode(s, idx=_w(s, 0).end())
               ^^^^^^^^^^^^^^^^^^^^^^^^^^^^^^^^^^^^^^
  File "/home/trevea/miniconda3/envs/nlp-rag/lib/python3.12/json/decoder.py", line 355, in raw_decode
    raise JSONDecodeError("Expecting value", s, err.value) from None
json.decoder.JSONDecodeError: Expecting value: line 1 column 1 (char 0)

During handling of the above exception, another exception occurred:

Traceback (most recent call last):
  File "/home/trevea/Projects/ToolsForTheJobBenchmark/generation/OpenData/wikipedia/api_test.py", line 7, in test_get_category_metrics
    response = get_category_metrics('example-category', '2022-01-01', '2022-02-01')
               ^^^^^^^^^^^^^^^^^^^^^^^^^^^^^^^^^^^^^^^^^^^^^^^^^^^^^^^^^^^^^^^^^^^^
  File "/home/trevea/Projects/ToolsForTheJobBenchmark/generation/OpenData/wikipedia/api.py", line 10, in get_category_metrics
    return response.json()
           ^^^^^^^^^^^^^^^
  File "/home/trevea/miniconda3/envs/nlp-rag/lib/python3.12/site-packages/requests/models.py", line 975, in json
    raise RequestsJSONDecodeError(e.msg, e.doc, e.pos)
requests.exceptions.JSONDecodeError: Expecting value: line 1 column 1 (char 0)

======================================================================
ERROR: test_get_edits_aggregate (__main__.TestWikipediaAPI.test_get_edits_aggregate)
----------------------------------------------------------------------
Traceback (most recent call last):
  File "/home/trevea/miniconda3/envs/nlp-rag/lib/python3.12/site-packages/requests/models.py", line 971, in json
    return complexjson.loads(self.text, **kwargs)
           ^^^^^^^^^^^^^^^^^^^^^^^^^^^^^^^^^^^^^^
  File "/home/trevea/miniconda3/envs/nlp-rag/lib/python3.12/json/__init__.py", line 346, in loads
    return _default_decoder.decode(s)
           ^^^^^^^^^^^^^^^^^^^^^^^^^^
  File "/home/trevea/miniconda3/envs/nlp-rag/lib/python3.12/json/decoder.py", line 337, in decode
    obj, end = self.raw_decode(s, idx=_w(s, 0).end())
               ^^^^^^^^^^^^^^^^^^^^^^^^^^^^^^^^^^^^^^
  File "/home/trevea/miniconda3/envs/nlp-rag/lib/python3.12/json/decoder.py", line 355, in raw_decode
    raise JSONDecodeError("Expecting value", s, err.value) from None
json.decoder.JSONDecodeError: Expecting value: line 1 column 1 (char 0)

During handling of the above exception, another exception occurred:

Traceback (most recent call last):
  File "/home/trevea/Projects/ToolsForTheJobBenchmark/generation/OpenData/wikipedia/api_test.py", line 35, in test_get_edits_aggregate
    response = get_edits_aggregate('en.wikipedia', 'anonymous', 'all-page-types', 'daily', '2023-01-01', '2023-01-31')
               ^^^^^^^^^^^^^^^^^^^^^^^^^^^^^^^^^^^^^^^^^^^^^^^^^^^^^^^^^^^^^^^^^^^^^^^^^^^^^^^^^^^^^^^^^^^^^^^^^^^^^^^
  File "/home/trevea/Projects/ToolsForTheJobBenchmark/generation/OpenData/wikipedia/api.py", line 45, in get_edits_aggregate
    return response.json()
           ^^^^^^^^^^^^^^^
  File "/home/trevea/miniconda3/envs/nlp-rag/lib/python3.12/site-packages/requests/models.py", line 975, in json
    raise RequestsJSONDecodeError(e.msg, e.doc, e.pos)
requests.exceptions.JSONDecodeError: Expecting value: line 1 column 1 (char 0)

======================================================================
ERROR: test_get_edits_per_category (__main__.TestWikipediaAPI.test_get_edits_per_category)
----------------------------------------------------------------------
Traceback (most recent call last):
  File "/home/trevea/miniconda3/envs/nlp-rag/lib/python3.12/site-packages/requests/models.py", line 971, in json
    return complexjson.loads(self.text, **kwargs)
           ^^^^^^^^^^^^^^^^^^^^^^^^^^^^^^^^^^^^^^
  File "/home/trevea/miniconda3/envs/nlp-rag/lib/python3.12/json/__init__.py", line 346, in loads
    return _default_decoder.decode(s)
           ^^^^^^^^^^^^^^^^^^^^^^^^^^
  File "/home/trevea/miniconda3/envs/nlp-rag/lib/python3.12/json/decoder.py", line 337, in decode
    obj, end = self.raw_decode(s, idx=_w(s, 0).end())
               ^^^^^^^^^^^^^^^^^^^^^^^^^^^^^^^^^^^^^^
  File "/home/trevea/miniconda3/envs/nlp-rag/lib/python3.12/json/decoder.py", line 355, in raw_decode
    raise JSONDecodeError("Expecting value", s, err.value) from None
json.decoder.JSONDecodeError: Expecting value: line 1 column 1 (char 0)

During handling of the above exception, another exception occurred:

Traceback (most recent call last):
  File "/home/trevea/Projects/ToolsForTheJobBenchmark/generation/OpenData/wikipedia/api_test.py", line 11, in test_get_edits_per_category
    response = get_edits_per_category('example-category', 'inclusive', 'all-editor-types', '2022-01-01', '2022-02-01')
               ^^^^^^^^^^^^^^^^^^^^^^^^^^^^^^^^^^^^^^^^^^^^^^^^^^^^^^^^^^^^^^^^^^^^^^^^^^^^^^^^^^^^^^^^^^^^^^^^^^^^^^^
  File "/home/trevea/Projects/ToolsForTheJobBenchmark/generation/OpenData/wikipedia/api.py", line 15, in get_edits_per_category
    return response.json()
           ^^^^^^^^^^^^^^^
  File "/home/trevea/miniconda3/envs/nlp-rag/lib/python3.12/site-packages/requests/models.py", line 975, in json
    raise RequestsJSONDecodeError(e.msg, e.doc, e.pos)
requests.exceptions.JSONDecodeError: Expecting value: line 1 column 1 (char 0)

======================================================================
ERROR: test_get_pageviews_aggregate (__main__.TestWikipediaAPI.test_get_pageviews_aggregate)
----------------------------------------------------------------------
Traceback (most recent call last):
  File "/home/trevea/miniconda3/envs/nlp-rag/lib/python3.12/site-packages/requests/models.py", line 971, in json
    return complexjson.loads(self.text, **kwargs)
           ^^^^^^^^^^^^^^^^^^^^^^^^^^^^^^^^^^^^^^
  File "/home/trevea/miniconda3/envs/nlp-rag/lib/python3.12/json/__init__.py", line 346, in loads
    return _default_decoder.decode(s)
           ^^^^^^^^^^^^^^^^^^^^^^^^^^
  File "/home/trevea/miniconda3/envs/nlp-rag/lib/python3.12/json/decoder.py", line 337, in decode
    obj, end = self.raw_decode(s, idx=_w(s, 0).end())
               ^^^^^^^^^^^^^^^^^^^^^^^^^^^^^^^^^^^^^^
  File "/home/trevea/miniconda3/envs/nlp-rag/lib/python3.12/json/decoder.py", line 355, in raw_decode
    raise JSONDecodeError("Expecting value", s, err.value) from None
json.decoder.JSONDecodeError: Expecting value: line 1 column 1 (char 0)

During handling of the above exception, another exception occurred:

Traceback (most recent call last):
  File "/home/trevea/Projects/ToolsForTheJobBenchmark/generation/OpenData/wikipedia/api_test.py", line 39, in test_get_pageviews_aggregate
    response = get_pageviews_aggregate('en.wikipedia', 'all-access', 'all-agents', 'daily', '2023-01-01', '2023-01-31')
               ^^^^^^^^^^^^^^^^^^^^^^^^^^^^^^^^^^^^^^^^^^^^^^^^^^^^^^^^^^^^^^^^^^^^^^^^^^^^^^^^^^^^^^^^^^^^^^^^^^^^^^^^
  File "/home/trevea/Projects/ToolsForTheJobBenchmark/generation/OpenData/wikipedia/api.py", line 50, in get_pageviews_aggregate
    return response.json()
           ^^^^^^^^^^^^^^^
  File "/home/trevea/miniconda3/envs/nlp-rag/lib/python3.12/site-packages/requests/models.py", line 975, in json
    raise RequestsJSONDecodeError(e.msg, e.doc, e.pos)
requests.exceptions.JSONDecodeError: Expecting value: line 1 column 1 (char 0)

======================================================================
ERROR: test_get_pageviews_per_category (__main__.TestWikipediaAPI.test_get_pageviews_per_category)
----------------------------------------------------------------------
Traceback (most recent call last):
  File "/home/trevea/miniconda3/envs/nlp-rag/lib/python3.12/site-packages/requests/models.py", line 971, in json
    return complexjson.loads(self.text, **kwargs)
           ^^^^^^^^^^^^^^^^^^^^^^^^^^^^^^^^^^^^^^
  File "/home/trevea/miniconda3/envs/nlp-rag/lib/python3.12/json/__init__.py", line 346, in loads
    return _default_decoder.decode(s)
           ^^^^^^^^^^^^^^^^^^^^^^^^^^
  File "/home/trevea/miniconda3/envs/nlp-rag/lib/python3.12/json/decoder.py", line 337, in decode
    obj, end = self.raw_decode(s, idx=_w(s, 0).end())
               ^^^^^^^^^^^^^^^^^^^^^^^^^^^^^^^^^^^^^^
  File "/home/trevea/miniconda3/envs/nlp-rag/lib/python3.12/json/decoder.py", line 355, in raw_decode
    raise JSONDecodeError("Expecting value", s, err.value) from None
json.decoder.JSONDecodeError: Expecting value: line 1 column 1 (char 0)

During handling of the above exception, another exception occurred:

Traceback (most recent call last):
  File "/home/trevea/Projects/ToolsForTheJobBenchmark/generation/OpenData/wikipedia/api_test.py", line 15, in test_get_pageviews_per_category
    response = get_pageviews_per_category('example-category', 'inclusive', 'en.wikipedia', '2022-01-01', '2022-02-01')
               ^^^^^^^^^^^^^^^^^^^^^^^^^^^^^^^^^^^^^^^^^^^^^^^^^^^^^^^^^^^^^^^^^^^^^^^^^^^^^^^^^^^^^^^^^^^^^^^^^^^^^^^
  File "/home/trevea/Projects/ToolsForTheJobBenchmark/generation/OpenData/wikipedia/api.py", line 20, in get_pageviews_per_category
    return response.json()
           ^^^^^^^^^^^^^^^
  File "/home/trevea/miniconda3/envs/nlp-rag/lib/python3.12/site-packages/requests/models.py", line 975, in json
    raise RequestsJSONDecodeError(e.msg, e.doc, e.pos)
requests.exceptions.JSONDecodeError: Expecting value: line 1 column 1 (char 0)

======================================================================
ERROR: test_get_top_edited_categories (__main__.TestWikipediaAPI.test_get_top_edited_categories)
----------------------------------------------------------------------
Traceback (most recent call last):
  File "/home/trevea/miniconda3/envs/nlp-rag/lib/python3.12/site-packages/requests/models.py", line 971, in json
    return complexjson.loads(self.text, **kwargs)
           ^^^^^^^^^^^^^^^^^^^^^^^^^^^^^^^^^^^^^^
  File "/home/trevea/miniconda3/envs/nlp-rag/lib/python3.12/json/__init__.py", line 346, in loads
    return _default_decoder.decode(s)
           ^^^^^^^^^^^^^^^^^^^^^^^^^^
  File "/home/trevea/miniconda3/envs/nlp-rag/lib/python3.12/json/decoder.py", line 337, in decode
    obj, end = self.raw_decode(s, idx=_w(s, 0).end())
               ^^^^^^^^^^^^^^^^^^^^^^^^^^^^^^^^^^^^^^
  File "/home/trevea/miniconda3/envs/nlp-rag/lib/python3.12/json/decoder.py", line 355, in raw_decode
    raise JSONDecodeError("Expecting value", s, err.value) from None
json.decoder.JSONDecodeError: Expecting value: line 1 column 1 (char 0)

During handling of the above exception, another exception occurred:

Traceback (most recent call last):
  File "/home/trevea/Projects/ToolsForTheJobBenchmark/generation/OpenData/wikipedia/api_test.py", line 19, in test_get_top_edited_categories
    response = get_top_edited_categories('inclusive', 'all-editor-types', 2023, 1)
               ^^^^^^^^^^^^^^^^^^^^^^^^^^^^^^^^^^^^^^^^^^^^^^^^^^^^^^^^^^^^^^^^^^^
  File "/home/trevea/Projects/ToolsForTheJobBenchmark/generation/OpenData/wikipedia/api.py", line 25, in get_top_edited_categories
    return response.json()
           ^^^^^^^^^^^^^^^
  File "/home/trevea/miniconda3/envs/nlp-rag/lib/python3.12/site-packages/requests/models.py", line 975, in json
    raise RequestsJSONDecodeError(e.msg, e.doc, e.pos)
requests.exceptions.JSONDecodeError: Expecting value: line 1 column 1 (char 0)

======================================================================
ERROR: test_get_top_pages_per_category (__main__.TestWikipediaAPI.test_get_top_pages_per_category)
----------------------------------------------------------------------
Traceback (most recent call last):
  File "/home/trevea/miniconda3/envs/nlp-rag/lib/python3.12/site-packages/requests/models.py", line 971, in json
    return complexjson.loads(self.text, **kwargs)
           ^^^^^^^^^^^^^^^^^^^^^^^^^^^^^^^^^^^^^^
  File "/home/trevea/miniconda3/envs/nlp-rag/lib/python3.12/json/__init__.py", line 346, in loads
    return _default_decoder.decode(s)
           ^^^^^^^^^^^^^^^^^^^^^^^^^^
  File "/home/trevea/miniconda3/envs/nlp-rag/lib/python3.12/json/decoder.py", line 337, in decode
    obj, end = self.raw_decode(s, idx=_w(s, 0).end())
               ^^^^^^^^^^^^^^^^^^^^^^^^^^^^^^^^^^^^^^
  File "/home/trevea/miniconda3/envs/nlp-rag/lib/python3.12/json/decoder.py", line 355, in raw_decode
    raise JSONDecodeError("Expecting value", s, err.value) from None
json.decoder.JSONDecodeError: Expecting value: line 1 column 1 (char 0)

During handling of the above exception, another exception occurred:

Traceback (most recent call last):
  File "/home/trevea/Projects/ToolsForTheJobBenchmark/generation/OpenData/wikipedia/api_test.py", line 27, in test_get_top_pages_per_category
    response = get_top_pages_per_category('example-category', 'inclusive', 'en.wikipedia', 2023, 1)
               ^^^^^^^^^^^^^^^^^^^^^^^^^^^^^^^^^^^^^^^^^^^^^^^^^^^^^^^^^^^^^^^^^^^^^^^^^^^^^^^^^^^^
  File "/home/trevea/Projects/ToolsForTheJobBenchmark/generation/OpenData/wikipedia/api.py", line 35, in get_top_pages_per_category
    return response.json()
           ^^^^^^^^^^^^^^^
  File "/home/trevea/miniconda3/envs/nlp-rag/lib/python3.12/site-packages/requests/models.py", line 975, in json
    raise RequestsJSONDecodeError(e.msg, e.doc, e.pos)
requests.exceptions.JSONDecodeError: Expecting value: line 1 column 1 (char 0)

======================================================================
ERROR: test_get_top_viewed_categories (__main__.TestWikipediaAPI.test_get_top_viewed_categories)
----------------------------------------------------------------------
Traceback (most recent call last):
  File "/home/trevea/miniconda3/envs/nlp-rag/lib/python3.12/site-packages/requests/models.py", line 971, in json
    return complexjson.loads(self.text, **kwargs)
           ^^^^^^^^^^^^^^^^^^^^^^^^^^^^^^^^^^^^^^
  File "/home/trevea/miniconda3/envs/nlp-rag/lib/python3.12/json/__init__.py", line 346, in loads
    return _default_decoder.decode(s)
           ^^^^^^^^^^^^^^^^^^^^^^^^^^
  File "/home/trevea/miniconda3/envs/nlp-rag/lib/python3.12/json/decoder.py", line 337, in decode
    obj, end = self.raw_decode(s, idx=_w(s, 0).end())
               ^^^^^^^^^^^^^^^^^^^^^^^^^^^^^^^^^^^^^^
  File "/home/trevea/miniconda3/envs/nlp-rag/lib/python3.12/json/decoder.py", line 355, in raw_decode
    raise JSONDecodeError("Expecting value", s, err.value) from None
json.decoder.JSONDecodeError: Expecting value: line 1 column 1 (char 0)

During handling of the above exception, another exception occurred:

Traceback (most recent call last):
  File "/home/trevea/Projects/ToolsForTheJobBenchmark/generation/OpenData/wikipedia/api_test.py", line 23, in test_get_top_viewed_categories
    response = get_top_viewed_categories('inclusive', 'en.wikipedia', 2023, 1)
               ^^^^^^^^^^^^^^^^^^^^^^^^^^^^^^^^^^^^^^^^^^^^^^^^^^^^^^^^^^^^^^^
  File "/home/trevea/Projects/ToolsForTheJobBenchmark/generation/OpenData/wikipedia/api.py", line 30, in get_top_viewed_categories
    return response.json()
           ^^^^^^^^^^^^^^^
  File "/home/trevea/miniconda3/envs/nlp-rag/lib/python3.12/site-packages/requests/models.py", line 975, in json
    raise RequestsJSONDecodeError(e.msg, e.doc, e.pos)
requests.exceptions.JSONDecodeError: Expecting value: line 1 column 1 (char 0)

======================================================================
ERROR: test_get_unique_devices (__main__.TestWikipediaAPI.test_get_unique_devices)
----------------------------------------------------------------------
Traceback (most recent call last):
  File "/home/trevea/miniconda3/envs/nlp-rag/lib/python3.12/site-packages/requests/models.py", line 971, in json
    return complexjson.loads(self.text, **kwargs)
           ^^^^^^^^^^^^^^^^^^^^^^^^^^^^^^^^^^^^^^
  File "/home/trevea/miniconda3/envs/nlp-rag/lib/python3.12/json/__init__.py", line 346, in loads
    return _default_decoder.decode(s)
           ^^^^^^^^^^^^^^^^^^^^^^^^^^
  File "/home/trevea/miniconda3/envs/nlp-rag/lib/python3.12/json/decoder.py", line 337, in decode
    obj, end = self.raw_decode(s, idx=_w(s, 0).end())
               ^^^^^^^^^^^^^^^^^^^^^^^^^^^^^^^^^^^^^^
  File "/home/trevea/miniconda3/envs/nlp-rag/lib/python3.12/json/decoder.py", line 355, in raw_decode
    raise JSONDecodeError("Expecting value", s, err.value) from None
json.decoder.JSONDecodeError: Expecting value: line 1 column 1 (char 0)

During handling of the above exception, another exception occurred:

Traceback (most recent call last):
  File "/home/trevea/Projects/ToolsForTheJobBenchmark/generation/OpenData/wikipedia/api_test.py", line 31, in test_get_unique_devices
    response = get_unique_devices('en.wikipedia', 'desktop', 'daily', '2023-01-01', '2023-01-31')
               ^^^^^^^^^^^^^^^^^^^^^^^^^^^^^^^^^^^^^^^^^^^^^^^^^^^^^^^^^^^^^^^^^^^^^^^^^^^^^^^^^^
  File "/home/trevea/Projects/ToolsForTheJobBenchmark/generation/OpenData/wikipedia/api.py", line 40, in get_unique_devices
    return response.json()
           ^^^^^^^^^^^^^^^
  File "/home/trevea/miniconda3/envs/nlp-rag/lib/python3.12/site-packages/requests/models.py", line 975, in json
    raise RequestsJSONDecodeError(e.msg, e.doc, e.pos)
requests.exceptions.JSONDecodeError: Expecting value: line 1 column 1 (char 0)

----------------------------------------------------------------------
Ran 9 tests in 3.402s

FAILED (errors=9)
Tests completed for API 'wikipedia'

==================================================

Running tests for API 'openlibrary'...
Tests completed for API 'openlibrary'

==================================================

python3: can't open file '/home/trevea/Projects/ToolsForTheJobBenchmark/generation/OpenData/openlibrary/api_test.py': [Errno 2] No such file or directory
Running tests for API 'vehicles'...
...E.....F.............
======================================================================
ERROR: test_decode_vin_values_batch (__main__.TestVehiclesAPI.test_decode_vin_values_batch)
----------------------------------------------------------------------
Traceback (most recent call last):
  File "/home/trevea/miniconda3/envs/nlp-rag/lib/python3.12/site-packages/requests/models.py", line 971, in json
    return complexjson.loads(self.text, **kwargs)
           ^^^^^^^^^^^^^^^^^^^^^^^^^^^^^^^^^^^^^^
  File "/home/trevea/miniconda3/envs/nlp-rag/lib/python3.12/json/__init__.py", line 346, in loads
    return _default_decoder.decode(s)
           ^^^^^^^^^^^^^^^^^^^^^^^^^^
  File "/home/trevea/miniconda3/envs/nlp-rag/lib/python3.12/json/decoder.py", line 337, in decode
    obj, end = self.raw_decode(s, idx=_w(s, 0).end())
               ^^^^^^^^^^^^^^^^^^^^^^^^^^^^^^^^^^^^^^
  File "/home/trevea/miniconda3/envs/nlp-rag/lib/python3.12/json/decoder.py", line 355, in raw_decode
    raise JSONDecodeError("Expecting value", s, err.value) from None
json.decoder.JSONDecodeError: Expecting value: line 1 column 1 (char 0)

During handling of the above exception, another exception occurred:

Traceback (most recent call last):
  File "/home/trevea/Projects/ToolsForTheJobBenchmark/generation/OpenData/vehicles/api_test.py", line 92, in test_decode_vin_values_batch
    response = decode_vin_values_batch(vins)
               ^^^^^^^^^^^^^^^^^^^^^^^^^^^^^
  File "/home/trevea/Projects/ToolsForTheJobBenchmark/generation/OpenData/vehicles/api.py", line 235, in decode_vin_values_batch
    return response.json()
           ^^^^^^^^^^^^^^^
  File "/home/trevea/miniconda3/envs/nlp-rag/lib/python3.12/site-packages/requests/models.py", line 975, in json
    raise RequestsJSONDecodeError(e.msg, e.doc, e.pos)
requests.exceptions.JSONDecodeError: Expecting value: line 1 column 1 (char 0)

======================================================================
FAIL: test_get_equipment_plant_codes (__main__.TestVehiclesAPI.test_get_equipment_plant_codes)
----------------------------------------------------------------------
Traceback (most recent call last):
  File "/home/trevea/Projects/ToolsForTheJobBenchmark/generation/OpenData/vehicles/api_test.py", line 68, in test_get_equipment_plant_codes
    self.assertIn('Results', response)
AssertionError: 'Results' not found in {'message': "No HTTP resource was found that matches the request URI 'https://backend-vpic-api.nhtsa.dot.gov/api/vehicles/GetEquipmentPlantCodes/2015?format=json'.", 'messageDetail': "No action was found on the controller 'Vehicles' that matches the request."}

----------------------------------------------------------------------
Ran 23 tests in 9.899s

FAILED (failures=1, errors=1)
Tests completed for API 'vehicles'

==================================================

Running tests for API 'datapoliceuk'...
.............E.......
======================================================================
ERROR: test_outcomes_for_specific_crime (__main__.TestPoliceAPI.test_outcomes_for_specific_crime)
----------------------------------------------------------------------
Traceback (most recent call last):
  File "/home/trevea/miniconda3/envs/nlp-rag/lib/python3.12/site-packages/requests/models.py", line 971, in json
    return complexjson.loads(self.text, **kwargs)
           ^^^^^^^^^^^^^^^^^^^^^^^^^^^^^^^^^^^^^^
  File "/home/trevea/miniconda3/envs/nlp-rag/lib/python3.12/json/__init__.py", line 346, in loads
    return _default_decoder.decode(s)
           ^^^^^^^^^^^^^^^^^^^^^^^^^^
  File "/home/trevea/miniconda3/envs/nlp-rag/lib/python3.12/json/decoder.py", line 337, in decode
    obj, end = self.raw_decode(s, idx=_w(s, 0).end())
               ^^^^^^^^^^^^^^^^^^^^^^^^^^^^^^^^^^^^^^
  File "/home/trevea/miniconda3/envs/nlp-rag/lib/python3.12/json/decoder.py", line 355, in raw_decode
    raise JSONDecodeError("Expecting value", s, err.value) from None
json.decoder.JSONDecodeError: Expecting value: line 1 column 1 (char 0)

During handling of the above exception, another exception occurred:

Traceback (most recent call last):
  File "/home/trevea/Projects/ToolsForTheJobBenchmark/generation/OpenData/datapoliceuk/api_test.py", line 50, in test_outcomes_for_specific_crime
    response = outcomes_for_specific_crime(crime_id)
               ^^^^^^^^^^^^^^^^^^^^^^^^^^^^^^^^^^^^^
  File "/home/trevea/Projects/ToolsForTheJobBenchmark/generation/OpenData/datapoliceuk/api.py", line 106, in outcomes_for_specific_crime
    return response.json()
           ^^^^^^^^^^^^^^^
  File "/home/trevea/miniconda3/envs/nlp-rag/lib/python3.12/site-packages/requests/models.py", line 975, in json
    raise RequestsJSONDecodeError(e.msg, e.doc, e.pos)
requests.exceptions.JSONDecodeError: Expecting value: line 1 column 1 (char 0)

----------------------------------------------------------------------
Ran 21 tests in 18.516s

FAILED (errors=1)
Tests completed for API 'datapoliceuk'

==================================================

Running tests for API 'archiveorg'...
...
----------------------------------------------------------------------
Ran 3 tests in 1.066s

OK
Tests completed for API 'archiveorg'

==================================================

Running tests for API 'waybackmachine'...
.
----------------------------------------------------------------------
Ran 1 test in 10.498s

OK
Tests completed for API 'waybackmachine'

==================================================

Running tests for API 'housestockwatcher'...
..Tests completed for API 'housestockwatcher'

==================================================

.
----------------------------------------------------------------------
Ran 3 tests in 1.209s

OK
