F.FF.F..F.
======================================================================
FAIL: test_get_all_boxes (__main__.TestOpenSenseMapAPI.test_get_all_boxes)
----------------------------------------------------------------------
Traceback (most recent call last):
  File "/home/trevea/Projects/ToolsForTheJobBenchmark/generation/Weather/opensensemap/api_test.py", line 13, in test_get_all_boxes
    self.assertIsInstance(response, list)
AssertionError: {'code': 'UnprocessableEntity', 'message': 'Illegal value for parameter classify. allowed values: true, false'} is not an instance of <class 'list'>

======================================================================
FAIL: test_get_idw_statistics (__main__.TestOpenSenseMapAPI.test_get_idw_statistics)
----------------------------------------------------------------------
Traceback (most recent call last):
  File "/home/trevea/Projects/ToolsForTheJobBenchmark/generation/Weather/opensensemap/api_test.py", line 22, in test_get_idw_statistics
    self.assertIn("featureCollection", response)
AssertionError: 'featureCollection' not found in {'code': 'Ok', 'data': {'breaks': [14.37, 18.756, 23.142, 27.528, 31.914, 36.3], 'featureCollection': {'type': 'FeatureCollection', 'features': []}, 'timesteps': ['2024-08-23T07:32:15.061Z', '2024-08-23T15:32:15.061Z', '2024-08-23T23:32:15.061Z', '2024-08-24T07:32:15.061Z', '2024-08-24T15:32:15.061Z', '2024-08-24T23:32:15.061Z']}}

======================================================================
FAIL: test_get_latest_measurements_for_sensor (__main__.TestOpenSenseMapAPI.test_get_latest_measurements_for_sensor)
----------------------------------------------------------------------
Traceback (most recent call last):
  File "/home/trevea/Projects/ToolsForTheJobBenchmark/generation/Weather/opensensemap/api_test.py", line 30, in test_get_latest_measurements_for_sensor
    self.assertIsInstance(response, list)
AssertionError: {'code': 'UnprocessableEntity', 'message': 'Illegal value for parameter download. allowed values: true, false'} is not an instance of <class 'list'>

======================================================================
FAIL: test_get_latest_measurements_of_sensor (__main__.TestOpenSenseMapAPI.test_get_latest_measurements_of_sensor)
----------------------------------------------------------------------
Traceback (most recent call last):
  File "/home/trevea/Projects/ToolsForTheJobBenchmark/generation/Weather/opensensemap/api_test.py", line 38, in test_get_latest_measurements_of_sensor
    self.assertIn("_id", response)
AssertionError: '_id' not found in {'error': 'Expecting value: line 1 column 1 (char 0)', 'response': ''}

======================================================================
FAIL: test_get_stats (__main__.TestOpenSenseMapAPI.test_get_stats)
----------------------------------------------------------------------
Traceback (most recent call last):
  File "/home/trevea/Projects/ToolsForTheJobBenchmark/generation/Weather/opensensemap/api_test.py", line 42, in test_get_stats
    self.assertIsInstance(response, list)
AssertionError: {'code': 'UnprocessableEntity', 'message': 'Illegal value for parameter human. allowed values: true, false'} is not an instance of <class 'list'>

----------------------------------------------------------------------
Ran 10 tests in 102.471s

FAILED (failures=5)
Tests completed for API 'opensensemap'

==================================================

Running tests for API 'awc'...
FF...F.FF.F....
======================================================================
FAIL: test_get_airport (__main__.TestAWCAPI.test_get_airport)
----------------------------------------------------------------------
Traceback (most recent call last):
  File "/home/trevea/Projects/ToolsForTheJobBenchmark/generation/Weather/awc/api_test.py", line 64, in test_get_airport
    self.assertTrue(isinstance(response, dict))
AssertionError: False is not true

======================================================================
FAIL: test_get_airsigmet (__main__.TestAWCAPI.test_get_airsigmet)
----------------------------------------------------------------------
Traceback (most recent call last):
  File "/home/trevea/Projects/ToolsForTheJobBenchmark/generation/Weather/awc/api_test.py", line 28, in test_get_airsigmet
    self.assertTrue(isinstance(response, dict))
AssertionError: False is not true

======================================================================
FAIL: test_get_feature (__main__.TestAWCAPI.test_get_feature)
----------------------------------------------------------------------
Traceback (most recent call last):
  File "/home/trevea/Projects/ToolsForTheJobBenchmark/generation/Weather/awc/api_test.py", line 68, in test_get_feature
    self.assertTrue(isinstance(response, dict))
AssertionError: False is not true

======================================================================
FAIL: test_get_isigmet (__main__.TestAWCAPI.test_get_isigmet)
----------------------------------------------------------------------
Traceback (most recent call last):
  File "/home/trevea/Projects/ToolsForTheJobBenchmark/generation/Weather/awc/api_test.py", line 32, in test_get_isigmet
    self.assertTrue(isinstance(response, dict))
AssertionError: False is not true

======================================================================
FAIL: test_get_metar (__main__.TestAWCAPI.test_get_metar)
----------------------------------------------------------------------
Traceback (most recent call last):
  File "/home/trevea/Projects/ToolsForTheJobBenchmark/generation/Weather/awc/api_test.py", line 16, in test_get_metar
    self.assertTrue(isinstance(response, dict))
AssertionError: False is not true

======================================================================
FAIL: test_get_obstacle (__main__.TestAWCAPI.test_get_obstacle)
----------------------------------------------------------------------
Traceback (most recent call last):
  File "/home/trevea/Projects/ToolsForTheJobBenchmark/generation/Weather/awc/api_test.py", line 72, in test_get_obstacle
    self.assertTrue(isinstance(response, dict))
AssertionError: False is not true

----------------------------------------------------------------------
Ran 15 tests in 11.426s

FAILED (failures=6)
Tests completed for API 'awc'

==================================================

Running tests for API 'openmeteo'...
Tests completed for API 'openmeteo'

==================================================

python3: can't open file '/home/trevea/Projects/ToolsForTheJobBenchmark/generation/Weather/openmeteo/api_test.py': [Errno 2] No such file or directory
